Workbook

Sheet BANK
A1: This is a list of active account/product types currently available on T24.
A2: BRANCH_CO_MNE | B2: @ID | C2: DESCRIPTION | D2: PRODUCT_GROUP | E2: PARENT.PRODUCT | F2: CATEGORY CODE | G2: ONLINE ACCESS | H2: View Only | I2: Transfer to Internal Accounts (A2A) | J2: Transfer from Internal Accounts (A2A) | K2: Transfer To External Accounts | L2: Transfer From External Accounts | M2: Loan Payment (From) | N2: CC Payment (From) | O2: Bill Pay (From) | P2: RDC (Deposit to) | Q2: P2P (From) | R2: Comments
A3: BNK | B3: AD.BRO.BB.FR.NONP | C3: Book-Based GIC - Non Personal | D3: BROKER.TERM.DEPOSITS | E3: =VLOOKUP(B3,'PARENT PRODUCT'!$A:$B,2,FALSE) -> AD.BRO.PARENT.FR | F3: 6611 | G3: =VLOOKUP(B3,'ONLINE ACCESS'!$A:$B,2,FALSE) -> #N/A
A4: BNK | B4: AD.BRO.BB.FR.NONP.WHS | C4: Book-Based GIC - Non Personal WHS | D4: BROKER.TERM.DEPOSITS | E4: =VLOOKUP(B4,'PARENT PRODUCT'!$A:$B,2,FALSE) -> AD.BRO.PARENT.FR | F4: 6617 | G4: =VLOOKUP(B4,'ONLINE ACCESS'!$A:$B,2,FALSE) -> #N/A
A5: BNK | B5: AD.BRO.BB.FR.PERS | C5: Book-Based GIC - Personal | D5: BROKER.TERM.DEPOSITS | E5: =VLOOKUP(B5,'PARENT PRODUCT'!$A:$B,2,FALSE) -> AD.BRO.PARENT.FR | F5: =VLOOKUP(B5,'CATEGORY CODE'!$A:$B,2,FALSE) -> 6712 | G5: =VLOOKUP(B5,'ONLINE ACCESS'!$A:$B,2,FALSE) -> #N/A
A6: BNK | B6: AD.BRO.BB.FR.PERS.WHS | C6: Book-Based GIC - Personal WHS | D6: BROKER.TERM.DEPOSITS | E6: =VLOOKUP(B6,'PARENT PRODUCT'!$A:$B,2,FALSE) -> AD.BRO.PARENT.FR | F6: =VLOOKUP(B6,'CATEGORY CODE'!$A:$B,2,FALSE) -> 6717 | G6: =VLOOKUP(B6,'ONLINE ACCESS'!$A:$B,2,FALSE) -> #N/A
A7: BNK | B7: AD.BRO.CSC.NONPER | C7: CSC - Non-Personal | D7: BROKER.TERM.DEPOSITS | E7: =VLOOKUP(B7,'PARENT PRODUCT'!$A:$B,2,FALSE) -> AD.BRO.PARENT.FR | F7: 6651 | G7: =VLOOKUP(B7,'ONLINE ACCESS'!$A:$B,2,FALSE) -> #N/A
A8: BNK | B8: AD.BRO.CSC.NONPER.WH | C8: CSC - Non Personal Wholesale | D8: BROKER.TERM.DEPOSITS | E8: =VLOOKUP(B8,'PARENT PRODUCT'!$A:$B,2,FALSE) -> AD.BRO.PARENT.FR | F8: 6656 | G8: =VLOOKUP(B8,'ONLINE ACCESS'!$A:$B,2,FALSE) -> #N/A
A9: BNK | B9: AD.BRO.CSC.PER | C9: CSC - Personal | D9: BROKER.TERM.DEPOSITS | E9: =VLOOKUP(B9,'PARENT PRODUCT'!$A:$B,2,FALSE) -> AD.BRO.PARENT.FR | F9: 6751 | G9: =VLOOKUP(B9,'ONLINE ACCESS'!$A:$B,2,FALSE) -> #N/A
A10: BNK | B10: AD.BRO.CSC.PER.WH | C10: CSC - Personal Wholesale | D10: BROKER.TERM.DEPOSITS | E10: =VLOOKUP(B10,'PARENT PRODUCT'!$A:$B,2,FALSE) -> AD.BRO.PARENT.FR | F10: 6756 | G10: =VLOOKUP(B10,'ONLINE ACCESS'!$A:$B,2,FALSE) -> #N/A
A11: BNK | B11: AD.BRO.FLR.NONPERS | C11: FLR - Non Personal | D11: BROKER.TERM.DEPOSITS | E11: =VLOOKUP(B11,'PARENT PRODUCT'!$A:$B,2,FALSE) -> AD.BRO.PARENT.FR | F11: =VLOOKUP(B11,'CATEGORY CODE'!$A:$B,2,FALSE) -> 6602 | G11: =VLOOKUP(B11,'ONLINE ACCESS'!$A:$B,2,FALSE) -> #N/A
A12: BNK | B12: AD.BRO.FLR.NONPERS.WH | C12: FLR - Non Personal Wholesale | D12: BROKER.TERM.DEPOSITS | E12: =VLOOKUP(B12,'PARENT PRODUCT'!$A:$B,2,FALSE) -> AD.BRO.PARENT.FR | F12: 6607 | G12: =VLOOKUP(B12,'ONLINE ACCESS'!$A:$B,2,FALSE) -> #N/A
A13: BNK | B13: AD.BRO.FLR.PERS | C13: FLR - Personal | D13: BROKER.TERM.DEPOSITS | E13: =VLOOKUP(B13,'PARENT PRODUCT'!$A:$B,2,FALSE) -> AD.BRO.PARENT.FR | F13: =VLOOKUP(B13,'CATEGORY CODE'!$A:$B,2,FALSE) -> 6702 | G13: =VLOOKUP(B13,'ONLINE ACCESS'!$A:$B,2,FALSE) -> #N/A
A14: BNK | B14: AD.BRO.FLR.PERS.WH | C14: FLR - Personal Wholesale | D14: BROKER.TERM.DEPOSITS | E14: =VLOOKUP(B14,'PARENT PRODUCT'!$A:$B,2,FALSE) -> AD.BRO.PARENT.FR | F14: 6706 | G14: =VLOOKUP(B14,'ONLINE ACCESS'!$A:$B,2,FALSE) -> #N/A
A15: BNK | B15: AD.BRO.FR.NONPERS | C15: GIC - Non Personal | D15: BROKER.TERM.DEPOSITS | E15: =VLOOKUP(B15,'PARENT PRODUCT'!$A:$B,2,FALSE) -> AD.BRO.PARENT.FR | F15: =VLOOKUP(B15,'CATEGORY CODE'!$A:$B,2,FALSE) -> 6611 | G15: =VLOOKUP(B15,'ONLINE ACCESS'!$A:$B,2,FALSE) -> #N/A
A16: BNK | B16: AD.BRO.FR.NONPERS.WHS | C16: GIC - Non Personal Wholesale | D16: BROKER.TERM.DEPOSITS | E16: =VLOOKUP(B16,'PARENT PRODUCT'!$A:$B,2,FALSE) -> AD.BRO.PARENT.FR | F16: =VLOOKUP(B16,'CATEGORY CODE'!$A:$B,2,FALSE) -> 6617 | G16: =VLOOKUP(B16,'ONLINE ACCESS'!$A:$B,2,FALSE) -> #N/A
A17: BNK | B17: AD.BRO.FR.PERS | C17: GIC - Personal | D17: BROKER.TERM.DEPOSITS | E17: =VLOOKUP(B17,'PARENT PRODUCT'!$A:$B,2,FALSE) -> AD.BRO.PARENT.FR | F17: =VLOOKUP(B17,'CATEGORY CODE'!$A:$B,2,FALSE) -> 6712 | G17: =VLOOKUP(B17,'ONLINE ACCESS'!$A:$B,2,FALSE) -> #N/A
A18: BNK | B18: AD.BRO.FR.PERS.WHS | C18: GIC - Personal Wholesale | D18: BROKER.TERM.DEPOSITS | E18: =VLOOKUP(B18,'PARENT PRODUCT'!$A:$B,2,FALSE) -> AD.BRO.PARENT.FR | F18: =VLOOKUP(B18,'CATEGORY CODE'!$A:$B,2,FALSE) -> 6717 | G18: =VLOOKUP(B18,'ONLINE ACCESS'!$A:$B,2,FALSE) -> #N/A
A19: BNK | B19: AD.BRO.RIF.CON.PER | C19: RRIF Convertible GIC | D19: BROKER.REG.TERM.DEPOSITS | E19: =VLOOKUP(B19,'PARENT PRODUCT'!$A:$B,2,FALSE) -> AD.BRO.RIF.PARENT.FR | F19: 6911 | G19: =VLOOKUP(B19,'ONLINE ACCESS'!$A:$B,2,FALSE) -> #N/A
A20: BNK | B20: AD.BRO.RIF.CON.PER.WH | C20: Broker RRIF Conv-Personal Wholesale | D20: BROKER.TERM.DEPOSITS | E20: =VLOOKUP(B20,'PARENT PRODUCT'!$A:$B,2,FALSE) -> #N/A | F20: 6915 | G20: =VLOOKUP(B20,'ONLINE ACCESS'!$A:$B,2,FALSE) -> #N/A
A21: BNK | B21: AD.BRO.RIF.FR.PERS | C21: RRIF Premium GIC | D21: BROKER.REG.TERM.DEPOSITS | E21: =VLOOKUP(B21,'PARENT PRODUCT'!$A:$B,2,FALSE) -> AD.BRO.RIF.PARENT.FR | F21: =VLOOKUP(B21,'CATEGORY CODE'!$A:$B,2,FALSE) -> 6921 | G21: =VLOOKUP(B21,'ONLINE ACCESS'!$A:$B,2,FALSE) -> #N/A
A22: BNK | B22: AD.BRO.RIF.FR.PERS.WH | C22: Broker RRIF FR - Personal Wholesale | D22: BROKER.TERM.DEPOSITS | E22: =VLOOKUP(B22,'PARENT PRODUCT'!$A:$B,2,FALSE) -> #N/A | F22: 6925 | G22: =VLOOKUP(B22,'ONLINE ACCESS'!$A:$B,2,FALSE) -> #N/A
A23: BNK | B23: AD.BRO.RIF.FRE.PER | C23: RRIF Fully Redeemable GIC | D23: BROKER.REG.TERM.DEPOSITS | E23: =VLOOKUP(B23,'PARENT PRODUCT'!$A:$B,2,FALSE) -> AD.BRO.RIF.PARENT.FR | F23: 6941 | G23: =VLOOKUP(B23,'ONLINE ACCESS'!$A:$B,2,FALSE) -> #N/A
A24: BNK | B24: AD.BRO.RIF.FRE.PER.WH | C24: Broker RRIF Fully Redeem Pers WHS | D24: BROKER.TERM.DEPOSITS | E24: =VLOOKUP(B24,'PARENT PRODUCT'!$A:$B,2,FALSE) -> #N/A | F24: 6945 | G24: =VLOOKUP(B24,'ONLINE ACCESS'!$A:$B,2,FALSE) -> #N/A
A25: BNK | B25: AD.BRO.RSP.CON.PER | C25: RRSP Convertible GIC | D25: BROKER.REG.TERM.DEPOSITS | E25: =VLOOKUP(B25,'PARENT PRODUCT'!$A:$B,2,FALSE) -> AD.BRO.RSP.PARENT.FR | F25: 6821 | G25: =VLOOKUP(B25,'ONLINE ACCESS'!$A:$B,2,FALSE) -> #N/A
A26: BNK | B26: AD.BRO.RSP.CON.PER.WH | C26: Broker RRSP Conv-Pers Wholesale | D26: BROKER.TERM.DEPOSITS | E26: =VLOOKUP(B26,'PARENT PRODUCT'!$A:$B,2,FALSE) -> #N/A | F26: 6815 | G26: =VLOOKUP(B26,'ONLINE ACCESS'!$A:$B,2,FALSE) -> #N/A
A27: BNK | B27: AD.BRO.RSP.FR.PERS | C27: RRSP Premium GIC | D27: BROKER.REG.TERM.DEPOSITS | E27: =VLOOKUP(B27,'PARENT PRODUCT'!$A:$B,2,FALSE) -> AD.BRO.RSP.PARENT.FR | F27: =VLOOKUP(B27,'CATEGORY CODE'!$A:$B,2,FALSE) -> 6821 | G27: =VLOOKUP(B27,'ONLINE ACCESS'!$A:$B,2,FALSE) -> #N/A
A28: BNK | B28: AD.BRO.RSP.FR.PERS.WH | C28: Broker RRSP FR - Personal Wholesale | D28: BROKER.TERM.DEPOSITS | E28: =VLOOKUP(B28,'PARENT PRODUCT'!$A:$B,2,FALSE) -> #N/A | F28: 6825 | G28: =VLOOKUP(B28,'ONLINE ACCESS'!$A:$B,2,FALSE) -> #N/A
A29: BNK | B29: AD.BRO.TFSA.FR.PER | C29: TFSA Premium GIC | D29: BROKER.REG.TERM.DEPOSITS | E29: =VLOOKUP(B29,'PARENT PRODUCT'!$A:$B,2,FALSE) -> AD.BRO.TFSA.PARENT.FR | F29: 6761 | G29: =VLOOKUP(B29,'ONLINE ACCESS'!$A:$B,2,FALSE) -> #N/A
A30: BNK | B30: AD.BRO.TFSA.FR.PER.WH | C30: Broker TFSA FR - Personal Wholesale | D30: BROKER.TERM.DEPOSITS | E30: =VLOOKUP(B30,'PARENT PRODUCT'!$A:$B,2,FALSE) -> #N/A | F30: 6717 | G30: =VLOOKUP(B30,'ONLINE ACCESS'!$A:$B,2,FALSE) -> #N/A
A31: BNK | B31: AD.CDF.FR.PERS | C31: Motive GIC - Personal | D31: CDF.TERM.DEPOSITS | E31: =VLOOKUP(B31,'PARENT PRODUCT'!$A:$B,2,FALSE) -> AD.CDF.PARENT.FR | F31: =VLOOKUP(B31,'CATEGORY CODE'!$A:$B,2,FALSE) -> 6710 | G31: =VLOOKUP(B31,'ONLINE ACCESS'!$A:$B,2,FALSE) -> CDF
A32: BNK | B32: AD.CDF.FR.PERS.WHS | C32: Motive GIC - Personal Wholesale | D32: CDF.TERM.DEPOSITS | E32: =VLOOKUP(B32,'PARENT PRODUCT'!$A:$B,2,FALSE) -> AD.CDF.PARENT.FR | F32: =VLOOKUP(B32,'CATEGORY CODE'!$A:$B,2,FALSE) -> 6715 | G32: =VLOOKUP(B32,'ONLINE ACCESS'!$A:$B,2,FALSE) -> CDF
A33: BNK | B33: AD.CDF.RIF.FR.PERS | C33: Motive RRIF GIC | D33: CDF.REG.TERM.DEPOSITS | E33: =VLOOKUP(B33,'PARENT PRODUCT'!$A:$B,2,FALSE) -> AD.CDF.RIF.PARENT.FR | F33: =VLOOKUP(B33,'CATEGORY CODE'!$A:$B,2,FALSE) -> 6920 | G33: =VLOOKUP(B33,'ONLINE ACCESS'!$A:$B,2,FALSE) -> CDF
A34: BNK | B34: AD.CDF.RSP.FR.PERS | C34: Motive RRSP GIC | D34: CDF.REG.TERM.DEPOSITS | E34: =VLOOKUP(B34,'PARENT PRODUCT'!$A:$B,2,FALSE) -> AD.CDF.RSP.PARENT.FR | F34: =VLOOKUP(B34,'CATEGORY CODE'!$A:$B,2,FALSE) -> 6820 | G34: =VLOOKUP(B34,'ONLINE ACCESS'!$A:$B,2,FALSE) -> CDF
A35: BNK | B35: AD.CDF.RSP.FR.PERS.WH | C35: CDF RRSP FR - Personal Wholesale | D35: CDF.TERM.DEPOSITS | E35: =VLOOKUP(B35,'PARENT PRODUCT'!$A:$B,2,FALSE) -> #N/A | F35: 6715 | G35: =VLOOKUP(B35,'ONLINE ACCESS'!$A:$B,2,FALSE) -> CDF
A36: BNK | B36: AD.CDF.TFSA.FR.PER | C36: Motive TFSA GIC | D36: CDF.REG.TERM.DEPOSITS | E36: =VLOOKUP(B36,'PARENT PRODUCT'!$A:$B,2,FALSE) -> AD.CDF.TFSA.PARENT.FR | F36: 6760 | G36: =VLOOKUP(B36,'ONLINE ACCESS'!$A:$B,2,FALSE) -> CDF
A37: BNK | B37: AD.CDF.TFSA.FR.PER.WH | C37: CDF TFSA FR - Personal Wholesale | D37: CDF.TERM.DEPOSITS | E37: =VLOOKUP(B37,'PARENT PRODUCT'!$A:$B,2,FALSE) -> #N/A | F37: 6715 | G37: =VLOOKUP(B37,'ONLINE ACCESS'!$A:$B,2,FALSE) -> CDF
A38: BNK | B38: AD.FLR.NONPER.WHS.USD | C38: USD FLR - Non Personal Wholesale | D38: NONREG.TERM.DEPOSITS | E38: =VLOOKUP(B38,'PARENT PRODUCT'!$A:$B,2,FALSE) -> AD.PARENT.FR | F38: 6606 | G38: =VLOOKUP(B38,'ONLINE ACCESS'!$A:$B,2,FALSE) -> CWB
A39: BNK | B39: AD.FLR.NONPERS | C39: FLR - Non Personal | D39: NONREG.TERM.DEPOSITS | E39: =VLOOKUP(B39,'PARENT PRODUCT'!$A:$B,2,FALSE) -> AD.PARENT.FR | F39: =VLOOKUP(B39,'CATEGORY CODE'!$A:$B,2,FALSE) -> 6601 | G39: =VLOOKUP(B39,'ONLINE ACCESS'!$A:$B,2,FALSE) -> CWB
A40: BNK | B40: AD.FLR.NONPERS.USD | C40: USD FLR - Non Personal | D40: NONREG.TERM.DEPOSITS | E40: =VLOOKUP(B40,'PARENT PRODUCT'!$A:$B,2,FALSE) -> AD.PARENT.FR | F40: =VLOOKUP(B40,'CATEGORY CODE'!$A:$B,2,FALSE) -> 6601 | G40: =VLOOKUP(B40,'ONLINE ACCESS'!$A:$B,2,FALSE) -> CWB
...

Sheet PARENT PRODUCT
A1: @ID | B1: PARENT_PRODUCT | C1: PRODUCT_GROUP
A2: AD.BRO.BB.FR.NONP | B2: AD.BRO.PARENT.FR | C2: BROKER.TERM.DEPOSITS
A3: AD.BRO.BB.FR.NONP.WHS | B3: AD.BRO.PARENT.FR | C3: BROKER.TERM.DEPOSITS
A4: AD.BRO.BB.FR.PERS | B4: AD.BRO.PARENT.FR | C4: BROKER.TERM.DEPOSITS
A5: AD.BRO.BB.FR.PERS.WHS | B5: AD.BRO.PARENT.FR | C5: BROKER.TERM.DEPOSITS
A6: AD.BRO.CSC.NONPER | B6: AD.BRO.PARENT.FR | C6: BROKER.TERM.DEPOSITS
A7: AD.BRO.CSC.NONPER.WH | B7: AD.BRO.PARENT.FR | C7: BROKER.TERM.DEPOSITS
A8: AD.BRO.CSC.PER | B8: AD.BRO.PARENT.FR | C8: BROKER.TERM.DEPOSITS
A9: AD.BRO.CSC.PER.WH | B9: AD.BRO.PARENT.FR | C9: BROKER.TERM.DEPOSITS
A10: AD.BRO.FLR.NONPERS | B10: AD.BRO.PARENT.FR | C10: BROKER.TERM.DEPOSITS
A11: AD.BRO.FLR.NONPERS.WH | B11: AD.BRO.PARENT.FR | C11: BROKER.TERM.DEPOSITS
A12: AD.BRO.FLR.PERS | B12: AD.BRO.PARENT.FR | C12: BROKER.TERM.DEPOSITS
... A255: NHA.MBS.FLOATING | B255: AD.PARENT.NHA | C255: NHA.MBS

Sheet CATEGORY CODE
A1: @ID | B1: CATEGORY
A2: AD.BRO.BB.FR.NONPERS | B2: 6611
A3: AD.BRO.BB.FR.NONPERS.WHS | B3: 6617
A4: AD.BRO.BB.FR.PERS | B4: 6712
A5: AD.BRO.BB.FR.PERS.WHS | B5: 6717
A6: AD.BRO.CSC.NONPERS | B6: 6651
A7: AD.BRO.CSC.NONPERS.WHS | B7: 6656
A8: AD.BRO.CSC.PERS | B8: 6751
A9: AD.BRO.CSC.PERS.WHS | B9: 6756
A10: AD.BRO.FLR.NONPERS | B10: 6602
A11: AD.BRO.FLR.NONPERS.WHS | B11: 6607
A12: AD.BRO.FLR.PERS | B12: 6702
A13: AD.BRO.FLR.PERS.WHS | B13: 6706
... A260: LENDING | B260: 3001

Sheet ONLINE ACCESS
A1: PRODUCT ID | B1: Card Type
A2: AD.CDF.FR.PERS | B2: CDF
A3: AD.CDF.FR.PERS | B3: MOT
A4: AD.CDF.FR.PERS.WHS | B4: CDF
A5: AD.CDF.FR.PERS.WHS | B5: MOT
A6: AD.CDF.RIF.FR.PERS | B6: CDF
A7: AD.CDF.RIF.FR.PERS | B7: MOT
A8: AD.CDF.RSP.FR.PERS | B8: CDF
A9: AD.CDF.RSP.FR.PERS | B9: MOT
A10: AD.CDF.RSP.FR.PERS.WH | B10: CDF
A11: AD.CDF.RSP.FR.PERS.WH | B11: MOT
A12: AD.CDF.TFSA.FR.PER | B12: CDF
... A409: AR.YOUTH.ACCOUNT.STF | B409: FLS
