Workbook

Sheet Sprint Status Dashboard
A1: Sprint# | B1: 14
A3: Count of User Story #
A4: Status | B4: Total
A5: Decision Updated | B5: 3
A6: In Review | B6: 3
A7: Approved | B7: 26
A8: UI Pending | B8: 2
A9: Grand Total | B9: 34

Sheet DBX Sprint
A1: SOW291, | B1: Sprint# | C1: Sprint Start Date | D1: Sprint End Date | E1: User Story Approval Due Date | F1: Module | G1: Feature | H1: Functionality | I1: SOW Description | J1: User Story # | K1: Status | L1: Decision Date if the Status is "Decision Updated" | M1: Decision Details if the Status is "Decision Updated" | N1: Decision Made by if the Status is "Decision Updated" | O1: Additonal Notes | P1: Story Approval Date
A2: SOW170 | B2: TBD | F2: Transfers | G2: Fund Transfers | H2: Transfer to own account in other financial institutions (Me2Me) | I2: Add a new account in another domestic bank/CU as an external account (recipient) to the profile, by providing account information. Users can transfer funds to the external account once it has been verified and activated. | K2: Decision Updated | L2: 44183 | M2: 12/18/2020 CM: Defer Me2Me from R1 to a post R1 release. This needs to be there with Motive as it is a retail function. Temenos and CWB agreed both recommended deferring M2M, and collectively indicated it would put R1 at risk in the workshop this morning. | N2: Christina Mullin | O2: This needs to be there with Motive as it is a retail function.
A3: SOW190 | B3: TBD | F3: Cheque Management | G3: Stop Cheque Payment | H3: Stop Cheque payment | I3: The Infinity Stop Cheque and Stop Payment function includes a field for the Date of Request Field. The intent of this field is to display the date the stop request was made. This date is captured and sent to T24. However when a user is review the request history, the Date Requested field is not returned from T24. CWB does require this field (should) and a decision is required on how to solution this field. The four options discussed are as follows: • Change the API to return the Date of Request • Suppress the field • Display the date based on what Infinity captures when (needs to be validated if this is technically possible). This would be a temporary solution. • Leave it blank | K3: Decision Updated | M3: The request create date is required. Suppresssing and leaving it blank are not options as date is on the screen and part of the user story. Next step is to ask Temenos what would suffice as a solution. | O3: Neil (1/15/20) set email to Grant to request solution scope)
A4: SOW283 | B4: 11 | F4: Payments & Withdrawals | G4: Pay Business Taxes | H4: Remit Tax | I4: Ability to remit Provincial Business Tax (separate forms from CRA) | J4: 11.1.1 | K4: Approved
A5: SOW283 | B5: 11 | F5: Payments & Withdrawals | G5: Pay Business Taxes | H5: Remit Tax | I5: Ability to remit Provincial Business Tax (separate forms from CRA) | J5: 11.1.2 | K5: Approved | P5: Jan 18-22
A6: SOW283 | B6: 11 | F6: Payments & Withdrawals | G6: Pay Business Taxes | H6: Remit Tax | I6: Ability to remit Provincial Business Tax (separate forms from CRA) | J6: 11.1.3 | K6: Approved
A7: SOW283 | B7: 11 | F7: Payments & Withdrawals | G7: Pay Business Taxes | H7: Remit Tax | I7: Ability to remit Provincial Business Tax (separate forms from CRA) | J7: 11.1.4 | K7: Approved
A8: SOW283 | B8: 11 | F8: Payments & Withdrawals | G8: Pay Business Taxes | H8: Remit Tax | I8: Ability to remit Provincial Business Tax (separate forms from CRA) | J8: 11.1.5 | K8: Approved | P8: 44222
A9: SOW283 | B9: 11 | F9: Payments & Withdrawals | G9: Pay Business Taxes | H9: Remit Tax | I9: Ability to remit Provincial Business Tax (separate forms from CRA) | J9: 11.1.6 | K9: Approved | P9: 44222
A10: SOW70 | B10: 11 | F10: Payments & Withdrawals | G10: CRA Fund Transfer | H10: View CRA Payment History | I10: Ability to view payment history | J10: 11.2.1 | K10: Approved
A11: SOW70 | B11: 11 | F11: Payments & Withdrawals | G11: CRA Fund Transfer | H11: View CRA Payment History | I11: Ability to view payment history | J11: 11.2.2 | K11: Approved
A12: SOW70 | B12: 11 | F12: Payments & Withdrawals | G12: CRA Fund Transfer | H12: View CRA Payment History | I12: Ability to view payment history | J12: 11.2.3 | K12: Approved
A13: SOW71 | B13: 11 | F13: Payments & Withdrawals | G13: CRA Fund Transfer | H13: View CRA Payment History | I13: Ability to view payment history | J13: 11.2.4 | K13: Approved
A14: SOW72 | B14: 11 | F14: Payments & Withdrawals | G14: CRA Fund Transfer | H14: View CRA Payment History | I14: Ability to view payment history | J14: 11.2.5 | K14: Approved
A15: SOW73 | B15: 11 | F15: Payments & Withdrawals | G15: CRA Fund Transfer | H15: View CRA Payment History | I15: Ability to view payment history | J15: 11.2.6 | K15: Approved
A16: SOW83 | B16: 11 | F16: Accounts | G16: Transactions | H16: Pagination | I16: Increase pagination beyond 10 transactions at a time. The requirement is to allow User to see 50 per page. Parameter of the pagination has to be passed to MS, need a cursor value back for next and previous transaction pages. | J16: 11.3.1 | K16: In Review
A17: SOW282 | B17: 11 | F17: Transfers | G17: External Accounts | H17: Manage External Bank accounts | I17: Remove external accounts added for transfers | J17: 1 | K17: In Review
A18: SOW282 | B18: 11 | F18: Transfers | G18: External Accounts | H18: Manage External Bank accounts | I18: Remove external accounts added for transfers | J18: 2 | K18: Draft
A19: SOW60 | B19: 12 | F19: Bill Payment | G19: Bill Pay | H19: Transaction / Payment Receipts | I19: Ability to view list of bill payments, with the option to manage each transaction ( i.e. print and download each receipt). The list can contain the beneficiary name, transaction description, type, from account, transaction ID, date, status, amount | J19: 12.1.1 | K19: In Review
A20: SOW60 | B20: 12 | F20: Bill Payment | G20: Bill Pay | H20: Transaction / Payment Receipts | I20: Ability to view list of bill payments, with the option to manage each transaction ( i.e. print and download each receipt). The list can contain the beneficiary name, transaction description, type, from account, transaction ID, date, status, amount | J20: 12.1.2 | K20: Approved
A21: SOW1000 | B21: 12 | F21: Cheque Management | G21: Stop Payment | H21: Stop payment | I21: Stop Payment for Pre-Authorized Payment | J21: 12.3.1 | K21: Approved
A22: SOW1000 | B22: 12 | F22: Cheque Management | G22: Stop Payment | H22: Stop payment | I22: Stop Payment for Pre-Authorized Payment | J22: 12.3.2 | K22: Approved
A23: SOW1000 | B23: 12 | F23: Cheque Management | G23: Stop Payment | H23: Stop payment | I23: Stop Payment for Pre-Authorized Payment | J23: 12.3.3 | K23: Approved
A24: SOW1000 | B24: 12 | F24: Cheque Management | G24: Stop Payment | H24: Stop payment | I24: Stop Payment for Pre-Authorized Payment | J24: 12.3.4 | K24: Approved
A25: SOW1000 | B25: 12 | F25: Cheque Management | G25: Stop Payment | H25: Stop payment | I25: Stop Payment for Pre-Authorized Payment | J25: 12.3.5 | K25: Approved
A26: SOW1000 | B26: 12 | F26: Cheque Management | G26: Stop Payment | H26: Stop payment | I26: Stop Payment for Pre-Authorized Payment | J26: 12.3.6 | K26: Approved
A27: SOW1000 | B27: 12 | F27: Cheque Management | G27: Stop Payment | H27: Stop payment | I27: Stop Payment for Pre-Authorized Payment | J27: 12.3.7 | K27: UI Pending
A28: SOW1000 | B28: 12 | F28: Cheque Management | G28: Stop Payment | H28: Stop payment | I28: Stop Payment for Pre-Authorized Payment | J28: 12.3.8 | K28: Approved
A29: SOW1000 | B29: 12 | F29: Cheque Management | G29: Stop Payment | H29: Stop payment | I29: Stop Payment for Pre-Authorized Payment | J29: 12.3.9 | K29: Approved
A30: SOW1000 | B30: 12 | F30: Cheque Management | G30: Stop Payment | H30: Stop payment | I30: Stop Payment for Pre-Authorized Payment | J30: 12.3.10 | K30: Approved
A31: SOW1000 | B31: 12 | F31: Cheque Management | G31: Stop Payment | H31: Stop payment | I31: Stop Payment for Pre-Authorized Payment | J31: 12.3.11 | K31: Approved
A32: SOW1000 | B32: 12 | F32: Cheque Management | G32: Stop Payment | H32: Stop payment | I32: Stop Payment for Pre-Authorized Payment | J32: 12.3.12 | K32: Draft | L32: 44187 | M32: Revoke PAP will not be in R1 | N32: Include in Scope to manage multiple statuses for PAP. | O32: removed b/c Stop Cheque is not in r1 1/14/21- Notified Temenos, stories moved to In Draft Status in Confluence
A33: SOW1000 | B33: 12 | F33: Cheque Management | G33: Stop Payment | H33: Stop payment | I33: Stop Payment for Pre-Authorized Payment | J33: 12.3.13 | K33: Approved | L33: 44187 | M33: Revoke PAP will not be in R1 | N33: Include in Scope to manage multiple statuses for PAP. | O33: removed b/c Stop Cheque is not in r1 1/14/21- Notified Temenos, stories moved to In Draft Status in Confluence | P33: 44221
A34: SOW1000 | B34: 12 | F34: Cheque Management | G34: Stop Payment | H34: Stop payment | I34: Stop Payment for Pre-Authorized Payment | J34: 12.3.14 | K34: Approved
A35: SOW1000 | B35: 12 | F35: Cheque Management | G35: Stop Payment | H35: Stop payment | I35: Stop Payment for Pre-Authorized Payment | J35: 12.3.15 | K35: Approved
A36: SOW1000 | B36: 12 | F36: Cheque Management | G36: Stop Payment | H36: Stop payment | I36: Stop Payment for Pre-Authorized Payment | J36: 12.3.16 | K36: Approved
A37: SOW1000 | B37: 12 | F37: Cheque Management | G37: Stop Payment | H37: Stop payment | I37: Stop Payment for Pre-Authorized Payment | J37: 12.3.17 | K37: Approved
A38: SOW1000 | B38: 12 | F38: Cheque Management | G38: Stop Payment | H38: Stop payment | I38: Stop Payment for Pre-Authorized Payment | J38: 12.3.18 | K38: Approved | P38: 44221
A39: SOW97 | B39: 13 | F39: User Interface | G39: Menu | H39: Navigation and Configuration | I39: Deliver a configurable menu in Release 1 (not a customization that would impact future upgrades). They require two sections for money movement at the top hierarchy of the menu structure: Transfers – includes only internal A2A and external A2A transfers) Payments – includes all other payment type CRA (Tax Payments) Bill Pay EFT / ACH eTransfers (P2P) – This mean splitting the transfers module into two and adding restrictions Wires (Domestic and International) CWB requests Product team take this item Note - 9/18 - EFT is no longer in scope for Release 1 and is in the backlog | J39: 13.2.1 | K39: In Review
A40: SOW97 | B40: 13 | F40: User Interface | G40: Menu | H40: Navigation and Configuration | I40: Deliver a configurable menu in Release 1 (not a customization that would impact future upgrades). They require two sections for money movement at the top hierarchy of the menu structure: Transfers – includes only internal A2A and external A2A transfers) Payments – includes all other payment type CRA (Tax Payments) Bill Pay EFT / ACH eTransfers (P2P) – This mean splitting the transfers module into two and adding restrictions Wires (Domestic and International) CWB requests Product team take this item Note - 9/18 - EFT is no longer in scope for Release 1 and is in the backlog | J40: 13.2.2 | K40: Approved
...

Sheet PM Dashboard
C3: OOTB without customization | D3: =COUNTIF('DBX Sprint'!#REF!,"OOTB without Customization") -> #REF! | F3: Functionality items per sprint
C4: OOTB with customization | D4: =COUNTIF('DBX Sprint'!#REF!,"OOTB with Customization") -> #REF! | F4: Sprint 8 | G4: =COUNTIF('DBX Sprint'!$B$1:$B$62,"Sprint 08") -> 0
C5: New Feature | D5: =COUNTIF('DBX Sprint'!#REF!,"New Feature") -> #REF! | F5: Sprint 9 | G5: =COUNTIF('DBX Sprint'!$B$1:$B$62,"Sprint 09") -> 0
C6: Other | D6: =(COUNTA('DBX Sprint'!#REF!))-SUM(D3:D5) -> #REF! | F6: Sprint 10 | G6: =COUNTIF('DBX Sprint'!$B$1:$B$62,"Sprint 10") -> 0
C7: TOTAL | D7: =SUM(D3:D6) -> #REF! | F7: Sprint 11 | G7: =COUNTIF('DBX Sprint'!$B$1:$B$62,"Sprint 11") -> 0
F8: Sprint 12 | G8: =COUNTIF('DBX Sprint'!$B$1:$B$62,"Sprint 12") -> 0
F9: Sprint 13 | G9: =COUNTIF('DBX Sprint'!$B$1:$B$62,"Sprint 13") -> 0
F10: Sprint 14 | G10: =COUNTIF('DBX Sprint'!$B$1:$B$62,"Sprint 14") -> 0
F11: Sprint 15 | G11: =COUNTIF('DBX Sprint'!$B$1:$B$62,"Sprint 15") -> 0
F12: TOTAL | G12: =SUM(G4:G11) -> 0
D19: OOTB without customization | E19: OOTB with customization | F19: New Feature | G19: TOTAL
C20: Sprint 8 | D20: =COUNTIFS('DBX Sprint'!$B$1:$B$62,"Sprint 08",'DBX Sprint'!#REF!,"OOTB without Customization") -> #REF! | E20: =COUNTIFS('DBX Sprint'!$B$1:$B$62,"Sprint 08",'DBX Sprint'!#REF!,"OOTB with Customization") -> #REF! | F20: =COUNTIFS('DBX Sprint'!$B$1:$B$62,"Sprint 08",'DBX Sprint'!#REF!,"New Feature") -> #REF! | G20: =SUM(D20:F20) -> #REF!
C21: Sprint 9 | D21: =COUNTIFS('DBX Sprint'!$B$1:$B$62,"Sprint 09",'DBX Sprint'!#REF!,"OOTB without Customization") -> #REF! | E21: =COUNTIFS('DBX Sprint'!$B$1:$B$62,"Sprint 09",'DBX Sprint'!#REF!,"OOTB with Customization") -> #REF! | F21: =COUNTIFS('DBX Sprint'!$B$1:$B$62,"Sprint 09",'DBX Sprint'!#REF!,"New Feature") -> #REF! | G21: =SUM(D21:F21) -> #REF!
C22: Sprint 10 | D22: =COUNTIFS('DBX Sprint'!$B$1:$B$62,"Sprint 10",'DBX Sprint'!#REF!,"OOTB without Customization") -> #REF! | E22: =COUNTIFS('DBX Sprint'!$B$1:$B$62,"Sprint 10",'DBX Sprint'!#REF!,"OOTB with Customization") -> #REF! | F22: =COUNTIFS('DBX Sprint'!$B$1:$B$62,"Sprint 10",'DBX Sprint'!#REF!,"New Feature") -> #REF! | G22: =SUM(D22:F22) -> #REF!
C23: Sprint 11 | D23: =COUNTIFS('DBX Sprint'!$B$1:$B$62,"Sprint 11",'DBX Sprint'!#REF!,"OOTB without Customization") -> #REF! | E23: =COUNTIFS('DBX Sprint'!$B$1:$B$62,"Sprint 11",'DBX Sprint'!#REF!,"OOTB with Customization") -> #REF! | F23: =COUNTIFS('DBX Sprint'!$B$1:$B$62,"Sprint 11",'DBX Sprint'!#REF!,"New Feature") -> #REF! | G23: =SUM(D23:F23) -> #REF!
C24: Sprint 12 | D24: =COUNTIFS('DBX Sprint'!$B$1:$B$62,"Sprint 12",'DBX Sprint'!#REF!,"OOTB without Customization") -> #REF! | E24: =COUNTIFS('DBX Sprint'!$B$1:$B$62,"Sprint 12",'DBX Sprint'!#REF!,"OOTB with Customization") -> #REF! | F24: =COUNTIFS('DBX Sprint'!$B$1:$B$62,"Sprint 12",'DBX Sprint'!#REF!,"New Feature") -> #REF! | G24: =SUM(D24:F24) -> #REF!
C25: Sprint 13 | D25: =COUNTIFS('DBX Sprint'!$B$1:$B$62,"Sprint 13",'DBX Sprint'!#REF!,"OOTB without Customization") -> #REF! | E25: =COUNTIFS('DBX Sprint'!$B$1:$B$62,"Sprint 13",'DBX Sprint'!#REF!,"OOTB with Customization") -> #REF! | F25: =COUNTIFS('DBX Sprint'!$B$1:$B$62,"Sprint 13",'DBX Sprint'!#REF!,"New Feature") -> #REF! | G25: =SUM(D25:F25) -> #REF!
C26: Sprint 14 | D26: =COUNTIFS('DBX Sprint'!$B$1:$B$62,"Sprint 14",'DBX Sprint'!#REF!,"OOTB without Customization") -> #REF! | E26: =COUNTIFS('DBX Sprint'!$B$1:$B$62,"Sprint 14",'DBX Sprint'!#REF!,"OOTB with Customization") -> #REF! | F26: =COUNTIFS('DBX Sprint'!$B$1:$B$62,"Sprint 14",'DBX Sprint'!#REF!,"New Feature") -> #REF! | G26: =SUM(D26:F26) -> #REF!
C27: Sprint 15 | D27: =COUNTIFS('DBX Sprint'!$B$1:$B$62,"Sprint 15",'DBX Sprint'!#REF!,"OOTB without Customization") -> #REF! | E27: =COUNTIFS('DBX Sprint'!$B$1:$B$62,"Sprint 15",'DBX Sprint'!#REF!,"OOTB with Customization") -> #REF! | F27: =COUNTIFS('DBX Sprint'!$B$1:$B$62,"Sprint 15",'DBX Sprint'!#REF!,"New Feature") -> #REF! | G27: =SUM(D27:F27) -> #REF!
C28: TOTAL | D28: =SUM(D20:D27) -> #REF! | E28: =SUM(E20:E27) -> #REF! | F28: =SUM(F20:F27) -> #REF! | G28: =SUM(G20:G27) -> #REF!
C32: T24 Data mapping | I32: Technical Design | O32: Services/RAML Definition | U32: UI/UX | AA32: User Story | AG32: CWB Story Approval | AM32: Mulesoft and third-party
C33: Completed | D33: Overdue | E33: Due Tomorrow | F33: Due 2-5 days from today | G33: Due 6-10 days from today | I33: Completed | J33: Overdue | K33: Due Tomorrow | L33: Due 2-5 days from today | M33: Due 6-10 days from today | O33: Completed | P33: Overdue | Q33: Due Tomorrow | R33: Due 2-5 days from today | S33: Due 6-10 days from today | U33: Completed | V33: Overdue | W33: Due Tomorrow | X33: Due 2-5 days from today | Y33: Due 6-10 days from today | AA33: Completed | AB33: Overdue | AC33: Due Tomorrow | AD33: Due 2-5 days from today | AE33: Due 6-10 days from today | AG33: Completed | AH33: Overdue | AI33: Due Tomorrow | AJ33: Due 2-5 days from today | AK33: Due 6-10 days from today | AM33: Completed | AN33: Overdue | AO33: Due Tomorrow | AP33: Due 2-5 days from today | AQ33: Due 6-10 days from today
C34: {=IFERROR(INDEX('DBX Sprint'!$A$7:$K$62, SMALL(IF((INDEX('DBX Sprint'!$A$7:$K$62, ,13)=("Complete"))*(INDEX('DBX Sprint'!$A$7:$K$62, ,13)="Complete"),MATCH(ROW('DBX Sprint'!$A$7:$K$62),ROW('DBX Sprint'!$A$7:$K$62)),""),ROWS(C$34:$C34)),COLUMNS('DBX Sprint'!$A$1:A1)),"")} | D34: {=IFERROR(INDEX('DBX Sprint'!$A$7:$K$62, SMALL(IF((INDEX('DBX Sprint'!$A$7:$K$62, ,13)<(TODAY()))*(INDEX('DBX Sprint'!$A$7:$K$62, ,13)<>"Complete"),MATCH(ROW('DBX Sprint'!$A$7:$K$62),ROW('DBX Sprint'!$A$7:$K$62)),""),ROWS(D$34:$D34)),COLUMNS('DBX Sprint'!$A$1:A1)),"")} | E34: {=IFERROR(INDEX('DBX Sprint'!$A$7:$K$62, SMALL(IF((INDEX('DBX Sprint'!$A$7:$K$62, ,13)<=(TODAY()+1))*(INDEX('DBX Sprint'!$A$7:$K$62, ,13)>=TODAY()),MATCH(ROW('DBX Sprint'!$A$7:$K$62),ROW('DBX Sprint'!$A$7:$K$62)),""),ROWS(E$34:$E34)),COLUMNS('DBX Sprint'!$A$1:A1)),"")} | F34: {=IFERROR(INDEX('DBX Sprint'!$A$7:$K$62, SMALL(IF((INDEX('DBX Sprint'!$A$7:$K$62, ,13)<=(TODAY()+5))*(INDEX('DBX Sprint'!$A$7:$K$62, ,13)>(TODAY()+1)),MATCH(ROW('DBX Sprint'!$A$7:$K$62),ROW('DBX Sprint'!$A$7:$K$62)),""),ROWS($F$34:F34)),COLUMNS('DBX Sprint'!$A$1:A1)),"")} | G34: {=IFERROR(INDEX('DBX Sprint'!$A$7:$K$62, SMALL(IF((INDEX('DBX Sprint'!$A$7:$K$62, ,13)<=(TODAY()+10))*(INDEX('DBX Sprint'!$A$7:$K$62, ,13)>(TODAY()+5)),MATCH(ROW('DBX Sprint'!$A$7:$K$62),ROW('DBX Sprint'!$A$7:$K$62)),""),ROWS($G$34:G34)),COLUMNS('DBX Sprint'!$A$1:A1)),"")} | I34: {=IFERROR(INDEX('DBX Sprint'!$A$7:$K$62, SMALL(IF((INDEX('DBX Sprint'!$A$7:$K$62, ,16)=("Complete"))*(INDEX('DBX Sprint'!$A$7:$K$62, ,16)="Complete"),MATCH(ROW('DBX Sprint'!$A$7:$K$62),ROW('DBX Sprint'!$A$7:$K$62)),""),ROWS($I$34:I34)),COLUMNS('DBX Sprint'!$A$1:A1)),"")} | J34: {=IFERROR(INDEX('DBX Sprint'!$A$7:$K$62, SMALL(IF((INDEX('DBX Sprint'!$A$7:$K$62, ,16)<(TODAY()))*(INDEX('DBX Sprint'!$A$7:$K$62, ,16)<>"Complete"),MATCH(ROW('DBX Sprint'!$A$7:$K$62),ROW('DBX Sprint'!$A$7:$K$62)),""),ROWS($J$34:J34)),COLUMNS('DBX Sprint'!$A$1:A1)),"")} | K34: {=IFERROR(INDEX('DBX Sprint'!$A$7:$K$62, SMALL(IF((INDEX('DBX Sprint'!$A$7:$K$62, ,16)<=(TODAY()+1))*(INDEX('DBX Sprint'!$A$7:$K$62, ,16)>=TODAY()),MATCH(ROW('DBX Sprint'!$A$7:$K$62),ROW('DBX Sprint'!$A$7:$K$62)),""),ROWS($K$34:K34)),COLUMNS('DBX Sprint'!$A$1:A1)),"")} | L34: {=IFERROR(INDEX('DBX Sprint'!$A$7:$K$62, SMALL(IF((INDEX('DBX Sprint'!$A$7:$K$62, ,16)<=(TODAY()+5))*(INDEX('DBX Sprint'!$A$7:$K$62, ,16)>(TODAY()+1)),MATCH(ROW('DBX Sprint'!$A$7:$K$62),ROW('DBX Sprint'!$A$7:$K$62)),""),ROWS($L$34:L34)),COLUMNS('DBX Sprint'!$A$1:A1)),"")} | M34: {=IFERROR(INDEX('DBX Sprint'!$A$7:$K$62, SMALL(IF((INDEX('DBX Sprint'!$A$7:$K$62, ,16)<=(TODAY()+10))*(INDEX('DBX Sprint'!$A$7:$K$62, ,16)>(TODAY()+5)),MATCH(ROW('DBX Sprint'!$A$7:$K$62),ROW('DBX Sprint'!$A$7:$K$62)),""),ROWS($M$34:M34)),COLUMNS('DBX Sprint'!$A$1:A1)),"")} | O34: {=IFERROR(INDEX('DBX Sprint'!$A$7:$K$62, SMALL(IF((INDEX('DBX Sprint'!$A$7:$K$62, ,19)=("Complete"))*(INDEX('DBX Sprint'!$A$7:$K$62, ,19)="Complete"),MATCH(ROW('DBX Sprint'!$A$7:$K$62),ROW('DBX Sprint'!$A$7:$K$62)),""),ROWS($O$34:O34)),COLUMNS('DBX Sprint'!$A$1:A1)),"")} | P34: {=IFERROR(INDEX('DBX Sprint'!$A$7:$K$62, SMALL(IF((INDEX('DBX Sprint'!$A$7:$K$62, ,19)<(TODAY()))*(INDEX('DBX Sprint'!$A$7:$K$62, ,19)<>"Complete"),MATCH(ROW('DBX Sprint'!$A$7:$K$62),ROW('DBX Sprint'!$A$7:$K$62)),""),ROWS($P$34:P34)),COLUMNS('DBX Sprint'!$A$1:A1)),"")} | Q34: {=IFERROR(INDEX('DBX Sprint'!$A$7:$K$62, SMALL(IF((INDEX('DBX Sprint'!$A$7:$K$62, ,19)<=(TODAY()+1))*(INDEX('DBX Sprint'!$A$7:$K$62, ,19)>=TODAY()),MATCH(ROW('DBX Sprint'!$A$7:$K$62),ROW('DBX Sprint'!$A$7:$K$62)),""),ROWS($Q$34:Q34)),COLUMNS('DBX Sprint'!$A$1:A1)),"")} | R34: {=IFERROR(INDEX('DBX Sprint'!$A$7:$K$62, SMALL(IF((INDEX('DBX Sprint'!$A$7:$K$62, ,19)<=(TODAY()+5))*(INDEX('DBX Sprint'!$A$7:$K$62, ,19)>(TODAY()+1)),MATCH(ROW('DBX Sprint'!$A$7:$K$62),ROW('DBX Sprint'!$A$7:$K$62)),""),ROWS($R$34:R34)),COLUMNS('DBX Sprint'!$A$1:A1)),"")} | S34: {=IFERROR(INDEX('DBX Sprint'!$A$7:$K$62, SMALL(IF((INDEX('DBX Sprint'!$A$7:$K$62, ,19)<=(TODAY()+10))*(INDEX('DBX Sprint'!$A$7:$K$62, ,19)>(TODAY()+5)),MATCH(ROW('DBX Sprint'!$A$7:$K$62),ROW('DBX Sprint'!$A$7:$K$62)),""),ROWS($S$34:S34)),COLUMNS('DBX Sprint'!$A$1:A1)),"")} | U34: {=IFERROR(INDEX('DBX Sprint'!$A$7:$K$62, SMALL(IF((INDEX('DBX Sprint'!$A$7:$K$62, ,22)=("Complete"))*(INDEX('DBX Sprint'!$A$7:$K$62, ,22)="Complete"),MATCH(ROW('DBX Sprint'!$A$7:$K$62),ROW('DBX Sprint'!$A$7:$K$62)),""),ROWS($U$34:U34)),COLUMNS('DBX Sprint'!$A$1:A1)),"")} | V34: {=IFERROR(INDEX('DBX Sprint'!$A$7:$K$62, SMALL(IF((INDEX('DBX Sprint'!$A$7:$K$62, ,22)<(TODAY()))*(INDEX('DBX Sprint'!$A$7:$K$62, ,22)<>"Complete"),MATCH(ROW('DBX Sprint'!$A$7:$K$62),ROW('DBX Sprint'!$A$7:$K$62)),""),ROWS($V$34:V34)),COLUMNS('DBX Sprint'!$A$1:A1)),"")} | W34: {=IFERROR(INDEX('DBX Sprint'!$A$7:$K$62, SMALL(IF((INDEX('DBX Sprint'!$A$7:$K$62, ,22)<=(TODAY()+1))*(INDEX('DBX Sprint'!$A$7:$K$62, ,22)>=TODAY()),MATCH(ROW('DBX Sprint'!$A$7:$K$62),ROW('DBX Sprint'!$A$7:$K$62)),""),ROWS($W$34:W34)),COLUMNS('DBX Sprint'!$A$1:A1)),"")} | X34: {=IFERROR(INDEX('DBX Sprint'!$A$7:$K$62, SMALL(IF((INDEX('DBX Sprint'!$A$7:$K$62, ,22)<=(TODAY()+5))*(INDEX('DBX Sprint'!$A$7:$K$62, ,22)>(TODAY()+1)),MATCH(ROW('DBX Sprint'!$A$7:$K$62),ROW('DBX Sprint'!$A$7:$K$62)),""),ROWS($X$34:X34)),COLUMNS('DBX Sprint'!$A$1:A1)),"")} | Y34: {=IFERROR(INDEX('DBX Sprint'!$A$7:$K$62, SMALL(IF((INDEX('DBX Sprint'!$A$7:$K$62, ,22)<=(TODAY()+10))*(INDEX('DBX Sprint'!$A$7:$K$62, ,22)>(TODAY()+5)),MATCH(ROW('DBX Sprint'!$A$7:$K$62),ROW('DBX Sprint'!$A$7:$K$62)),""),ROWS($Y$34:Y34)),COLUMNS('DBX Sprint'!$A$1:A1)),"")} | AA34: {=IFERROR(INDEX('DBX Sprint'!$A$7:$K$62, SMALL(IF((INDEX('DBX Sprint'!$A$7:$K$62, ,25)=("Complete"))*(INDEX('DBX Sprint'!$A$7:$K$62, ,25)="Complete"),MATCH(ROW('DBX Sprint'!$A$7:$K$62),ROW('DBX Sprint'!$A$7:$K$62)),""),ROWS($AA$34:AA34)),COLUMNS('DBX Sprint'!$A$1:A1)),"")} | AB34: {=IFERROR(INDEX('DBX Sprint'!$A$7:$K$62, SMALL(IF((INDEX('DBX Sprint'!$A$7:$K$62, ,25)<(TODAY()))*(INDEX('DBX Sprint'!$A$7:$K$62, ,25)<>"Complete"),MATCH(ROW('DBX Sprint'!$A$7:$K$62),ROW('DBX Sprint'!$A$7:$K$62)),""),ROWS($AB$34:AB34)),COLUMNS('DBX Sprint'!$A$1:A1)),"")} | AC34: {=IFERROR(INDEX('DBX Sprint'!$A$7:$K$62, SMALL(IF((INDEX('DBX Sprint'!$A$7:$K$62, ,25)<=(TODAY()+1))*(INDEX('DBX Sprint'!$A$7:$K$62, ,25)>=TODAY()),MATCH(ROW('DBX Sprint'!$A$7:$K$62),ROW('DBX Sprint'!$A$7:$K$62)),""),ROWS($AC$34:AC34)),COLUMNS('DBX Sprint'!$A$1:A1)),"")} | AD34: {=IFERROR(INDEX('DBX Sprint'!$A$7:$K$62, SMALL(IF((INDEX('DBX Sprint'!$A$7:$K$62, ,25)<=(TODAY()+5))*(INDEX('DBX Sprint'!$A$7:$K$62, ,25)>(TODAY()+1)),MATCH(ROW('DBX Sprint'!$A$7:$K$62),ROW('DBX Sprint'!$A$7:$K$62)),""),ROWS($AD$34:AD34)),COLUMNS('DBX Sprint'!$A$1:A1)),"")} | AE34: {=IFERROR(INDEX('DBX Sprint'!$A$7:$K$62, SMALL(IF((INDEX('DBX Sprint'!$A$7:$K$62, ,25)<=(TODAY()+10))*(INDEX('DBX Sprint'!$A$7:$K$62, ,25)>(TODAY()+5)),MATCH(ROW('DBX Sprint'!$A$7:$K$62),ROW('DBX Sprint'!$A$7:$K$62)),""),ROWS($AE$34:AE34)),COLUMNS('DBX Sprint'!$A$1:A1)),"")} | AG34: {=IFERROR(INDEX('DBX Sprint'!$A$7:$K$62, SMALL(IF((INDEX('DBX Sprint'!$A$7:$K$62, ,29)=("Complete"))*(INDEX('DBX Sprint'!$A$7:$K$62, ,29)="Complete"),MATCH(ROW('DBX Sprint'!$A$7:$K$62),ROW('DBX Sprint'!$A$7:$K$62)),""),ROWS($AG$34:AG34)),COLUMNS('DBX Sprint'!$A$1:A1)),"")} | AH34: {=IFERROR(INDEX('DBX Sprint'!$A$7:$K$62, SMALL(IF((INDEX('DBX Sprint'!$A$7:$K$62, ,29)<(TODAY()))*(INDEX('DBX Sprint'!$A$7:$K$62, ,29)<>"Complete"),MATCH(ROW('DBX Sprint'!$A$7:$K$62),ROW('DBX Sprint'!$A$7:$K$62)),""),ROWS($AH$34:AH34)),COLUMNS('DBX Sprint'!$A$1:A1)),"")} | AI34: {=IFERROR(INDEX('DBX Sprint'!$A$7:$K$62, SMALL(IF((INDEX('DBX Sprint'!$A$7:$K$62, ,29)<=(TODAY()+1))*(INDEX('DBX Sprint'!$A$7:$K$62, ,29)>=TODAY()),MATCH(ROW('DBX Sprint'!$A$7:$K$62),ROW('DBX Sprint'!$A$7:$K$62)),""),ROWS($AI$34:AI34)),COLUMNS('DBX Sprint'!$A$1:A1)),"")} | AJ34: {=IFERROR(INDEX('DBX Sprint'!$A$7:$K$62, SMALL(IF((INDEX('DBX Sprint'!$A$7:$K$62, ,29)<=(TODAY()+5))*(INDEX('DBX Sprint'!$A$7:$K$62, ,29)>(TODAY()+1)),MATCH(ROW('DBX Sprint'!$A$7:$K$62),ROW('DBX Sprint'!$A$7:$K$62)),""),ROWS($AJ$34:AJ34)),COLUMNS('DBX Sprint'!$A$1:A1)),"")} | AK34: {=IFERROR(INDEX('DBX Sprint'!$A$7:$K$62, SMALL(IF((INDEX('DBX Sprint'!$A$7:$K$62, ,29)<=(TODAY()+10))*(INDEX('DBX Sprint'!$A$7:$K$62, ,29)>(TODAY()+5)),MATCH(ROW('DBX Sprint'!$A$7:$K$62),ROW('DBX Sprint'!$A$7:$K$62)),""),ROWS($AK$34:AK34)),COLUMNS('DBX Sprint'!$A$1:A1)),"")} | AM34: {=IFERROR(INDEX('DBX Sprint'!$A$7:$K$62, SMALL(IF((INDEX('DBX Sprint'!$A$7:$K$62, ,32)=("Complete"))*(INDEX('DBX Sprint'!$A$7:$K$62, ,32)="Complete"),MATCH(ROW('DBX Sprint'!$A$7:$K$62),ROW('DBX Sprint'!$A$7:$K$62)),""),ROWS($AM$34:AM34)),COLUMNS('DBX Sprint'!$A$1:A1)),"")} | AN34: {=IFERROR(INDEX('DBX Sprint'!$A$7:$K$62, SMALL(IF((INDEX('DBX Sprint'!$A$7:$K$62, ,32)<(TODAY()))*(INDEX('DBX Sprint'!$A$7:$K$62, ,32)<>"Complete"),MATCH(ROW('DBX Sprint'!$A$7:$K$62),ROW('DBX Sprint'!$A$7:$K$62)),""),ROWS($AN$34:AN34)),COLUMNS('DBX Sprint'!$A$1:A1)),"")} | AO34: {=IFERROR(INDEX('DBX Sprint'!$A$7:$K$62, SMALL(IF((INDEX('DBX Sprint'!$A$7:$K$62, ,32)<=(TODAY()+1))*(INDEX('DBX Sprint'!$A$7:$K$62, ,32)>=TODAY()),MATCH(ROW('DBX Sprint'!$A$7:$K$62),ROW('DBX Sprint'!$A$7:$K$62)),""),ROWS($AO$34:AO34)),COLUMNS('DBX Sprint'!$A$1:A1)),"")} | AP34: {=IFERROR(INDEX('DBX Sprint'!$A$7:$K$62, SMALL(IF((INDEX('DBX Sprint'!$A$7:$K$62, ,32)<=(TODAY()+5))*(INDEX('DBX Sprint'!$A$7:$K$62, ,32)>(TODAY()+1)),MATCH(ROW('DBX Sprint'!$A$7:$K$62),ROW('DBX Sprint'!$A$7:$K$62)),""),ROWS($AP$34:AP34)),COLUMNS('DBX Sprint'!$A$1:A1)),"")} | AQ34: {=IFERROR(INDEX('DBX Sprint'!$A$7:$K$62, SMALL(IF((INDEX('DBX Sprint'!$A$7:$K$62, ,32)<=(TODAY()+10))*(INDEX('DBX Sprint'!$A$7:$K$62, ,32)>(TODAY()+5)),MATCH(ROW('DBX Sprint'!$A$7:$K$62),ROW('DBX Sprint'!$A$7:$K$62)),""),ROWS($AQ$34:AQ34)),COLUMNS('DBX Sprint'!$A$1:A1)),"")}
C35: {=IFERROR(INDEX('DBX Sprint'!$A$7:$K$62, SMALL(IF((INDEX('DBX Sprint'!$A$7:$K$62, ,13)=("Complete"))*(INDEX('DBX Sprint'!$A$7:$K$62, ,13)="Complete"),MATCH(ROW('DBX Sprint'!$A$7:$K$62),ROW('DBX Sprint'!$A$7:$K$62)),""),ROWS(C$34:$C35)),COLUMNS('DBX Sprint'!$A$1:A7)),"")} | D35: {=IFERROR(INDEX('DBX Sprint'!$A$7:$K$62, SMALL(IF((INDEX('DBX Sprint'!$A$7:$K$62, ,13)<(TODAY()))*(INDEX('DBX Sprint'!$A$7:$K$62, ,13)<>"Complete"),MATCH(ROW('DBX Sprint'!$A$7:$K$62),ROW('DBX Sprint'!$A$7:$K$62)),""),ROWS(D$34:$D35)),COLUMNS('DBX Sprint'!$A$1:A7)),"")} | E35: {=IFERROR(INDEX('DBX Sprint'!$A$7:$K$62, SMALL(IF((INDEX('DBX Sprint'!$A$7:$K$62, ,13)<=(TODAY()+1))*(INDEX('DBX Sprint'!$A$7:$K$62, ,13)>=TODAY()),MATCH(ROW('DBX Sprint'!$A$7:$K$62),ROW('DBX Sprint'!$A$7:$K$62)),""),ROWS(E$34:$E35)),COLUMNS('DBX Sprint'!$A$1:A7)),"")} | F35: {=IFERROR(INDEX('DBX Sprint'!$A$7:$K$62, SMALL(IF((INDEX('DBX Sprint'!$A$7:$K$62, ,13)<=(TODAY()+5))*(INDEX('DBX Sprint'!$A$7:$K$62, ,13)>(TODAY()+1)),MATCH(ROW('DBX Sprint'!$A$7:$K$62),ROW('DBX Sprint'!$A$7:$K$62)),""),ROWS($F$34:F35)),COLUMNS('DBX Sprint'!$A$1:A7)),"")} | G35: {=IFERROR(INDEX('DBX Sprint'!$A$7:$K$62, SMALL(IF((INDEX('DBX Sprint'!$A$7:$K$62, ,13)<=(TODAY()+10))*(INDEX('DBX Sprint'!$A$7:$K$62, ,13)>(TODAY()+5)),MATCH(ROW('DBX Sprint'!$A$7:$K$62),ROW('DBX Sprint'!$A$7:$K$62)),""),ROWS($G$34:G35)),COLUMNS('DBX Sprint'!$A$1:A7)),"")} | I35: {=IFERROR(INDEX('DBX Sprint'!$A$7:$K$62, SMALL(IF((INDEX('DBX Sprint'!$A$7:$K$62, ,16)=("Complete"))*(INDEX('DBX Sprint'!$A$7:$K$62, ,16)="Complete"),MATCH(ROW('DBX Sprint'!$A$7:$K$62),ROW('DBX Sprint'!$A$7:$K$62)),""),ROWS($I$34:I35)),COLUMNS('DBX Sprint'!$A$1:A7)),"")} | J35: {=IFERROR(INDEX('DBX Sprint'!$A$7:$K$62, SMALL(IF((INDEX('DBX Sprint'!$A$7:$K$62, ,16)<(TODAY()))*(INDEX('DBX Sprint'!$A$7:$K$62, ,16)<>"Complete"),MATCH(ROW('DBX Sprint'!$A$7:$K$62),ROW('DBX Sprint'!$A$7:$K$62)),""),ROWS($J$34:J35)),COLUMNS('DBX Sprint'!$A$1:A7)),"")} | K35: {=IFERROR(INDEX('DBX Sprint'!$A$7:$K$62, SMALL(IF((INDEX('DBX Sprint'!$A$7:$K$62, ,16)<=(TODAY()+1))*(INDEX('DBX Sprint'!$A$7:$K$62, ,16)>=TODAY()),MATCH(ROW('DBX Sprint'!$A$7:$K$62),ROW('DBX Sprint'!$A$7:$K$62)),""),ROWS($K$34:K35)),COLUMNS('DBX Sprint'!$A$1:A7)),"")} | L35: {=IFERROR(INDEX('DBX Sprint'!$A$7:$K$62, SMALL(IF((INDEX('DBX Sprint'!$A$7:$K$62, ,16)<=(TODAY()+5))*(INDEX('DBX Sprint'!$A$7:$K$62, ,16)>(TODAY()+1)),MATCH(ROW('DBX Sprint'!$A$7:$K$62),ROW('DBX Sprint'!$A$7:$K$62)),""),ROWS($L$34:L35)),COLUMNS('DBX Sprint'!$A$1:A7)),"")} | M35: {=IFERROR(INDEX('DBX Sprint'!$A$7:$K$62, SMALL(IF((INDEX('DBX Sprint'!$A$7:$K$62, ,16)<=(TODAY()+10))*(INDEX('DBX Sprint'!$A$7:$K$62, ,16)>(TODAY()+5)),MATCH(ROW('DBX Sprint'!$A$7:$K$62),ROW('DBX Sprint'!$A$7:$K$62)),""),ROWS($M$34:M35)),COLUMNS('DBX Sprint'!$A$1:A7)),"")} | O35: {=IFERROR(INDEX('DBX Sprint'!$A$7:$K$62, SMALL(IF((INDEX('DBX Sprint'!$A$7:$K$62, ,19)=("Complete"))*(INDEX('DBX Sprint'!$A$7:$K$62, ,19)="Complete"),MATCH(ROW('DBX Sprint'!$A$7:$K$62),ROW('DBX Sprint'!$A$7:$K$62)),""),ROWS($O$34:O35)),COLUMNS('DBX Sprint'!$A$1:A7)),"")} | P35: {=IFERROR(INDEX('DBX Sprint'!$A$7:$K$62, SMALL(IF((INDEX('DBX Sprint'!$A$7:$K$62, ,19)<(TODAY()))*(INDEX('DBX Sprint'!$A$7:$K$62, ,19)<>"Complete"),MATCH(ROW('DBX Sprint'!$A$7:$K$62),ROW('DBX Sprint'!$A$7:$K$62)),""),ROWS($P$34:P35)),COLUMNS('DBX Sprint'!$A$1:A7)),"")} | Q35: {=IFERROR(INDEX('DBX Sprint'!$A$7:$K$62, SMALL(IF((INDEX('DBX Sprint'!$A$7:$K$62, ,19)<=(TODAY()+1))*(INDEX('DBX Sprint'!$A$7:$K$62, ,19)>=TODAY()),MATCH(ROW('DBX Sprint'!$A$7:$K$62),ROW('DBX Sprint'!$A$7:$K$62)),""),ROWS($Q$34:Q35)),COLUMNS('DBX Sprint'!$A$1:A7)),"")} | R35: {=IFERROR(INDEX('DBX Sprint'!$A$7:$K$62, SMALL(IF((INDEX('DBX Sprint'!$A$7:$K$62, ,19)<=(TODAY()+5))*(INDEX('DBX Sprint'!$A$7:$K$62, ,19)>(TODAY()+1)),MATCH(ROW('DBX Sprint'!$A$7:$K$62),ROW('DBX Sprint'!$A$7:$K$62)),""),ROWS($R$34:R35)),COLUMNS('DBX Sprint'!$A$1:A7)),"")} | S35: {=IFERROR(INDEX('DBX Sprint'!$A$7:$K$62, SMALL(IF((INDEX('DBX Sprint'!$A$7:$K$62, ,19)<=(TODAY()+10))*(INDEX('DBX Sprint'!$A$7:$K$62, ,19)>(TODAY()+5)),MATCH(ROW('DBX Sprint'!$A$7:$K$62),ROW('DBX Sprint'!$A$7:$K$62)),""),ROWS($S$34:S35)),COLUMNS('DBX Sprint'!$A$1:A7)),"")} | U35: {=IFERROR(INDEX('DBX Sprint'!$A$7:$K$62, SMALL(IF((INDEX('DBX Sprint'!$A$7:$K$62, ,22)=("Complete"))*(INDEX('DBX Sprint'!$A$7:$K$62, ,22)="Complete"),MATCH(ROW('DBX Sprint'!$A$7:$K$62),ROW('DBX Sprint'!$A$7:$K$62)),""),ROWS($U$34:U35)),COLUMNS('DBX Sprint'!$A$1:A7)),"")} | V35: {=IFERROR(INDEX('DBX Sprint'!$A$7:$K$62, SMALL(IF((INDEX('DBX Sprint'!$A$7:$K$62, ,22)<(TODAY()))*(INDEX('DBX Sprint'!$A$7:$K$62, ,22)<>"Complete"),MATCH(ROW('DBX Sprint'!$A$7:$K$62),ROW('DBX Sprint'!$A$7:$K$62)),""),ROWS($V$34:V35)),COLUMNS('DBX Sprint'!$A$1:A7)),"")} | W35: {=IFERROR(INDEX('DBX Sprint'!$A$7:$K$62, SMALL(IF((INDEX('DBX Sprint'!$A$7:$K$62, ,22)<=(TODAY()+1))*(INDEX('DBX Sprint'!$A$7:$K$62, ,22)>=TODAY()),MATCH(ROW('DBX Sprint'!$A$7:$K$62),ROW('DBX Sprint'!$A$7:$K$62)),""),ROWS($W$34:W35)),COLUMNS('DBX Sprint'!$A$1:A7)),"")} | X35: {=IFERROR(INDEX('DBX Sprint'!$A$7:$K$62, SMALL(IF((INDEX('DBX Sprint'!$A$7:$K$62, ,22)<=(TODAY()+5))*(INDEX('DBX Sprint'!$A$7:$K$62, ,22)>(TODAY()+1)),MATCH(ROW('DBX Sprint'!$A$7:$K$62),ROW('DBX Sprint'!$A$7:$K$62)),""),ROWS($X$34:X35)),COLUMNS('DBX Sprint'!$A$1:A7)),"")} | Y35: {=IFERROR(INDEX('DBX Sprint'!$A$7:$K$62, SMALL(IF((INDEX('DBX Sprint'!$A$7:$K$62, ,22)<=(TODAY()+10))*(INDEX('DBX Sprint'!$A$7:$K$62, ,22)>(TODAY()+5)),MATCH(ROW('DBX Sprint'!$A$7:$K$62),ROW('DBX Sprint'!$A$7:$K$62)),""),ROWS($Y$34:Y35)),COLUMNS('DBX Sprint'!$A$1:A7)),"")} | AA35: {=IFERROR(INDEX('DBX Sprint'!$A$7:$K$62, SMALL(IF((INDEX('DBX Sprint'!$A$7:$K$62, ,25)=("Complete"))*(INDEX('DBX Sprint'!$A$7:$K$62, ,25)="Complete"),MATCH(ROW('DBX Sprint'!$A$7:$K$62),ROW('DBX Sprint'!$A$7:$K$62)),""),ROWS($AA$34:AA35)),COLUMNS('DBX Sprint'!$A$1:A7)),"")} | AB35: {=IFERROR(INDEX('DBX Sprint'!$A$7:$K$62, SMALL(IF((INDEX('DBX Sprint'!$A$7:$K$62, ,25)<(TODAY()))*(INDEX('DBX Sprint'!$A$7:$K$62, ,25)<>"Complete"),MATCH(ROW('DBX Sprint'!$A$7:$K$62),ROW('DBX Sprint'!$A$7:$K$62)),""),ROWS($AB$34:AB35)),COLUMNS('DBX Sprint'!$A$1:A7)),"")} | AC35: {=IFERROR(INDEX('DBX Sprint'!$A$7:$K$62, SMALL(IF((INDEX('DBX Sprint'!$A$7:$K$62, ,25)<=(TODAY()+1))*(INDEX('DBX Sprint'!$A$7:$K$62, ,25)>=TODAY()),MATCH(ROW('DBX Sprint'!$A$7:$K$62),ROW('DBX Sprint'!$A$7:$K$62)),""),ROWS($AC$34:AC35)),COLUMNS('DBX Sprint'!$A$1:A7)),"")} | AD35: {=IFERROR(INDEX('DBX Sprint'!$A$7:$K$62, SMALL(IF((INDEX('DBX Sprint'!$A$7:$K$62, ,25)<=(TODAY()+5))*(INDEX('DBX Sprint'!$A$7:$K$62, ,25)>(TODAY()+1)),MATCH(ROW('DBX Sprint'!$A$7:$K$62),ROW('DBX Sprint'!$A$7:$K$62)),""),ROWS($AD$34:AD35)),COLUMNS('DBX Sprint'!$A$1:A7)),"")} | AE35: {=IFERROR(INDEX('DBX Sprint'!$A$7:$K$62, SMALL(IF((INDEX('DBX Sprint'!$A$7:$K$62, ,25)<=(TODAY()+10))*(INDEX('DBX Sprint'!$A$7:$K$62, ,25)>(TODAY()+5)),MATCH(ROW('DBX Sprint'!$A$7:$K$62),ROW('DBX Sprint'!$A$7:$K$62)),""),ROWS($AE$34:AE35)),COLUMNS('DBX Sprint'!$A$1:A7)),"")} | AG35: {=IFERROR(INDEX('DBX Sprint'!$A$7:$K$62, SMALL(IF((INDEX('DBX Sprint'!$A$7:$K$62, ,29)=("Complete"))*(INDEX('DBX Sprint'!$A$7:$K$62, ,29)="Complete"),MATCH(ROW('DBX Sprint'!$A$7:$K$62),ROW('DBX Sprint'!$A$7:$K$62)),""),ROWS($AG$34:AG35)),COLUMNS('DBX Sprint'!$A$1:A7)),"")} | AH35: {=IFERROR(INDEX('DBX Sprint'!$A$7:$K$62, SMALL(IF((INDEX('DBX Sprint'!$A$7:$K$62, ,29)<(TODAY()))*(INDEX('DBX Sprint'!$A$7:$K$62, ,29)<>"Complete"),MATCH(ROW('DBX Sprint'!$A$7:$K$62),ROW('DBX Sprint'!$A$7:$K$62)),""),ROWS($AH$34:AH35)),COLUMNS('DBX Sprint'!$A$1:A7)),"")} | AI35: {=IFERROR(INDEX('DBX Sprint'!$A$7:$K$62, SMALL(IF((INDEX('DBX Sprint'!$A$7:$K$62, ,29)<=(TODAY()+1))*(INDEX('DBX Sprint'!$A$7:$K$62, ,29)>=TODAY()),MATCH(ROW('DBX Sprint'!$A$7:$K$62),ROW('DBX Sprint'!$A$7:$K$62)),""),ROWS($AI$34:AI35)),COLUMNS('DBX Sprint'!$A$1:A7)),"")} | AJ35: {=IFERROR(INDEX('DBX Sprint'!$A$7:$K$62, SMALL(IF((INDEX('DBX Sprint'!$A$7:$K$62, ,29)<=(TODAY()+5))*(INDEX('DBX Sprint'!$A$7:$K$62, ,29)>(TODAY()+1)),MATCH(ROW('DBX Sprint'!$A$7:$K$62),ROW('DBX Sprint'!$A$7:$K$62)),""),ROWS($AJ$34:AJ35)),COLUMNS('DBX Sprint'!$A$1:A7)),"")} | AK35: {=IFERROR(INDEX('DBX Sprint'!$A$7:$K$62, SMALL(IF((INDEX('DBX Sprint'!$A$7:$K$62, ,29)<=(TODAY()+10))*(INDEX('DBX Sprint'!$A$7:$K$62, ,29)>(TODAY()+5)),MATCH(ROW('DBX Sprint'!$A$7:$K$62),ROW('DBX Sprint'!$A$7:$K$62)),""),ROWS($AK$34:AK35)),COLUMNS('DBX Sprint'!$A$1:A7)),"")} | AM35: {=IFERROR(INDEX('DBX Sprint'!$A$7:$K$62, SMALL(IF((INDEX('DBX Sprint'!$A$7:$K$62, ,32)=("Complete"))*(INDEX('DBX Sprint'!$A$7:$K$62, ,32)="Complete"),MATCH(ROW('DBX Sprint'!$A$7:$K$62),ROW('DBX Sprint'!$A$7:$K$62)),""),ROWS($AM$34:AM35)),COLUMNS('DBX Sprint'!$A$1:A7)),"")} | AN35: {=IFERROR(INDEX('DBX Sprint'!$A$7:$K$62, SMALL(IF((INDEX('DBX Sprint'!$A$7:$K$62, ,32)<(TODAY()))*(INDEX('DBX Sprint'!$A$7:$K$62, ,32)<>"Complete"),MATCH(ROW('DBX Sprint'!$A$7:$K$62),ROW('DBX Sprint'!$A$7:$K$62)),""),ROWS($AN$34:AN35)),COLUMNS('DBX Sprint'!$A$1:A7)),"")} | AO35: {=IFERROR(INDEX('DBX Sprint'!$A$7:$K$62, SMALL(IF((INDEX('DBX Sprint'!$A$7:$K$62, ,32)<=(TODAY()+1))*(INDEX('DBX Sprint'!$A$7:$K$62, ,32)>=TODAY()),MATCH(ROW('DBX Sprint'!$A$7:$K$62),ROW('DBX Sprint'!$A$7:$K$62)),""),ROWS($AO$34:AO35)),COLUMNS('DBX Sprint'!$A$1:A7)),"")} | AP35: {=IFERROR(INDEX('DBX Sprint'!$A$7:$K$62, SMALL(IF((INDEX('DBX Sprint'!$A$7:$K$62, ,32)<=(TODAY()+5))*(INDEX('DBX Sprint'!$A$7:$K$62, ,32)>(TODAY()+1)),MATCH(ROW('DBX Sprint'!$A$7:$K$62),ROW('DBX Sprint'!$A$7:$K$62)),""),ROWS($AP$34:AP35)),COLUMNS('DBX Sprint'!$A$1:A7)),"")} | AQ35: {=IFERROR(INDEX('DBX Sprint'!$A$7:$K$62, SMALL(IF((INDEX('DBX Sprint'!$A$7:$K$62, ,32)<=(TODAY()+10))*(INDEX('DBX Sprint'!$A$7:$K$62, ,32)>(TODAY()+5)),MATCH(ROW('DBX Sprint'!$A$7:$K$62),ROW('DBX Sprint'!$A$7:$K$62)),""),ROWS($AQ$34:AQ35)),COLUMNS('DBX Sprint'!$A$1:A7)),"")}
C36: {=IFERROR(INDEX('DBX Sprint'!$A$7:$K$62, SMALL(IF((INDEX('DBX Sprint'!$A$7:$K$62, ,13)=("Complete"))*(INDEX('DBX Sprint'!$A$7:$K$62, ,13)="Complete"),MATCH(ROW('DBX Sprint'!$A$7:$K$62),ROW('DBX Sprint'!$A$7:$K$62)),""),ROWS(C$34:$C36)),COLUMNS('DBX Sprint'!$A$1:A8)),"")} | D36: {=IFERROR(INDEX('DBX Sprint'!$A$7:$K$62, SMALL(IF((INDEX('DBX Sprint'!$A$7:$K$62, ,13)<(TODAY()))*(INDEX('DBX Sprint'!$A$7:$K$62, ,13)<>"Complete"),MATCH(ROW('DBX Sprint'!$A$7:$K$62),ROW('DBX Sprint'!$A$7:$K$62)),""),ROWS(D$34:$D36)),COLUMNS('DBX Sprint'!$A$1:A8)),"")} | E36: {=IFERROR(INDEX('DBX Sprint'!$A$7:$K$62, SMALL(IF((INDEX('DBX Sprint'!$A$7:$K$62, ,13)<=(TODAY()+1))*(INDEX('DBX Sprint'!$A$7:$K$62, ,13)>=TODAY()),MATCH(ROW('DBX Sprint'!$A$7:$K$62),ROW('DBX Sprint'!$A$7:$K$62)),""),ROWS(E$34:$E36)),COLUMNS('DBX Sprint'!$A$1:A8)),"")} | F36: {=IFERROR(INDEX('DBX Sprint'!$A$7:$K$62, SMALL(IF((INDEX('DBX Sprint'!$A$7:$K$62, ,13)<=(TODAY()+5))*(INDEX('DBX Sprint'!$A$7:$K$62, ,13)>(TODAY()+1)),MATCH(ROW('DBX Sprint'!$A$7:$K$62),ROW('DBX Sprint'!$A$7:$K$62)),""),ROWS($F$34:F36)),COLUMNS('DBX Sprint'!$A$1:A8)),"")} | G36: {=IFERROR(INDEX('DBX Sprint'!$A$7:$K$62, SMALL(IF((INDEX('DBX Sprint'!$A$7:$K$62, ,13)<=(TODAY()+10))*(INDEX('DBX Sprint'!$A$7:$K$62, ,13)>(TODAY()+5)),MATCH(ROW('DBX Sprint'!$A$7:$K$62),ROW('DBX Sprint'!$A$7:$K$62)),""),ROWS($G$34:G36)),COLUMNS('DBX Sprint'!$A$1:A8)),"")} | I36: {=IFERROR(INDEX('DBX Sprint'!$A$7:$K$62, SMALL(IF((INDEX('DBX Sprint'!$A$7:$K$62, ,16)=("Complete"))*(INDEX('DBX Sprint'!$A$7:$K$62, ,16)="Complete"),MATCH(ROW('DBX Sprint'!$A$7:$K$62),ROW('DBX Sprint'!$A$7:$K$62)),""),ROWS($I$34:I36)),COLUMNS('DBX Sprint'!$A$1:A8)),"")} | J36: {=IFERROR(INDEX('DBX Sprint'!$A$7:$K$62, SMALL(IF((INDEX('DBX Sprint'!$A$7:$K$62, ,16)<(TODAY()))*(INDEX('DBX Sprint'!$A$7:$K$62, ,16)<>"Complete"),MATCH(ROW('DBX Sprint'!$A$7:$K$62),ROW('DBX Sprint'!$A$7:$K$62)),""),ROWS($J$34:J36)),COLUMNS('DBX Sprint'!$A$1:A8)),"")} | K36: {=IFERROR(INDEX('DBX Sprint'!$A$7:$K$62, SMALL(IF((INDEX('DBX Sprint'!$A$7:$K$62, ,16)<=(TODAY()+1))*(INDEX('DBX Sprint'!$A$7:$K$62, ,16)>=TODAY()),MATCH(ROW('DBX Sprint'!$A$7:$K$62),ROW('DBX Sprint'!$A$7:$K$62)),""),ROWS($K$34:K36)),COLUMNS('DBX Sprint'!$A$1:A8)),"")} | L36: {=IFERROR(INDEX('DBX Sprint'!$A$7:$K$62, SMALL(IF((INDEX('DBX Sprint'!$A$7:$K$62, ,16)<=(TODAY()+5))*(INDEX('DBX Sprint'!$A$7:$K$62, ,16)>(TODAY()+1)),MATCH(ROW('DBX Sprint'!$A$7:$K$62),ROW('DBX Sprint'!$A$7:$K$62)),""),ROWS($L$34:L36)),COLUMNS('DBX Sprint'!$A$1:A8)),"")} | M36: {=IFERROR(INDEX('DBX Sprint'!$A$7:$K$62, SMALL(IF((INDEX('DBX Sprint'!$A$7:$K$62, ,16)<=(TODAY()+10))*(INDEX('DBX Sprint'!$A$7:$K$62, ,16)>(TODAY()+5)),MATCH(ROW('DBX Sprint'!$A$7:$K$62),ROW('DBX Sprint'!$A$7:$K$62)),""),ROWS($M$34:M36)),COLUMNS('DBX Sprint'!$A$1:A8)),"")} | O36: {=IFERROR(INDEX('DBX Sprint'!$A$7:$K$62, SMALL(IF((INDEX('DBX Sprint'!$A$7:$K$62, ,19)=("Complete"))*(INDEX('DBX Sprint'!$A$7:$K$62, ,19)="Complete"),MATCH(ROW('DBX Sprint'!$A$7:$K$62),ROW('DBX Sprint'!$A$7:$K$62)),""),ROWS($O$34:O36)),COLUMNS('DBX Sprint'!$A$1:A8)),"")} | P36: {=IFERROR(INDEX('DBX Sprint'!$A$7:$K$62, SMALL(IF((INDEX('DBX Sprint'!$A$7:$K$62, ,19)<(TODAY()))*(INDEX('DBX Sprint'!$A$7:$K$62, ,19)<>"Complete"),MATCH(ROW('DBX Sprint'!$A$7:$K$62),ROW('DBX Sprint'!$A$7:$K$62)),""),ROWS($P$34:P36)),COLUMNS('DBX Sprint'!$A$1:A8)),"")} | Q36: {=IFERROR(INDEX('DBX Sprint'!$A$7:$K$62, SMALL(IF((INDEX('DBX Sprint'!$A$7:$K$62, ,19)<=(TODAY()+1))*(INDEX('DBX Sprint'!$A$7:$K$62, ,19)>=TODAY()),MATCH(ROW('DBX Sprint'!$A$7:$K$62),ROW('DBX Sprint'!$A$7:$K$62)),""),ROWS($Q$34:Q36)),COLUMNS('DBX Sprint'!$A$1:A8)),"")} | R36: {=IFERROR(INDEX('DBX Sprint'!$A$7:$K$62, SMALL(IF((INDEX('DBX Sprint'!$A$7:$K$62, ,19)<=(TODAY()+5))*(INDEX('DBX Sprint'!$A$7:$K$62, ,19)>(TODAY()+1)),MATCH(ROW('DBX Sprint'!$A$7:$K$62),ROW('DBX Sprint'!$A$7:$K$62)),""),ROWS($R$34:R36)),COLUMNS('DBX Sprint'!$A$1:A8)),"")} | S36: {=IFERROR(INDEX('DBX Sprint'!$A$7:$K$62, SMALL(IF((INDEX('DBX Sprint'!$A$7:$K$62, ,19)<=(TODAY()+10))*(INDEX('DBX Sprint'!$A$7:$K$62, ,19)>(TODAY()+5)),MATCH(ROW('DBX Sprint'!$A$7:$K$62),ROW('DBX Sprint'!$A$7:$K$62)),""),ROWS($S$34:S36)),COLUMNS('DBX Sprint'!$A$1:A8)),"")} | U36: {=IFERROR(INDEX('DBX Sprint'!$A$7:$K$62, SMALL(IF((INDEX('DBX Sprint'!$A$7:$K$62, ,22)=("Complete"))*(INDEX('DBX Sprint'!$A$7:$K$62, ,22)="Complete"),MATCH(ROW('DBX Sprint'!$A$7:$K$62),ROW('DBX Sprint'!$A$7:$K$62)),""),ROWS($U$34:U36)),COLUMNS('DBX Sprint'!$A$1:A8)),"")} | V36: {=IFERROR(INDEX('DBX Sprint'!$A$7:$K$62, SMALL(IF((INDEX('DBX Sprint'!$A$7:$K$62, ,22)<(TODAY()))*(INDEX('DBX Sprint'!$A$7:$K$62, ,22)<>"Complete"),MATCH(ROW('DBX Sprint'!$A$7:$K$62),ROW('DBX Sprint'!$A$7:$K$62)),""),ROWS($V$34:V36)),COLUMNS('DBX Sprint'!$A$1:A8)),"")} | W36: {=IFERROR(INDEX('DBX Sprint'!$A$7:$K$62, SMALL(IF((INDEX('DBX Sprint'!$A$7:$K$62, ,22)<=(TODAY()+1))*(INDEX('DBX Sprint'!$A$7:$K$62, ,22)>=TODAY()),MATCH(ROW('DBX Sprint'!$A$7:$K$62),ROW('DBX Sprint'!$A$7:$K$62)),""),ROWS($W$34:W36)),COLUMNS('DBX Sprint'!$A$1:A8)),"")} | X36: {=IFERROR(INDEX('DBX Sprint'!$A$7:$K$62, SMALL(IF((INDEX('DBX Sprint'!$A$7:$K$62, ,22)<=(TODAY()+5))*(INDEX('DBX Sprint'!$A$7:$K$62, ,22)>(TODAY()+1)),MATCH(ROW('DBX Sprint'!$A$7:$K$62),ROW('DBX Sprint'!$A$7:$K$62)),""),ROWS($X$34:X36)),COLUMNS('DBX Sprint'!$A$1:A8)),"")} | Y36: {=IFERROR(INDEX('DBX Sprint'!$A$7:$K$62, SMALL(IF((INDEX('DBX Sprint'!$A$7:$K$62, ,22)<=(TODAY()+10))*(INDEX('DBX Sprint'!$A$7:$K$62, ,22)>(TODAY()+5)),MATCH(ROW('DBX Sprint'!$A$7:$K$62),ROW('DBX Sprint'!$A$7:$K$62)),""),ROWS($Y$34:Y36)),COLUMNS('DBX Sprint'!$A$1:A8)),"")} | AA36: {=IFERROR(INDEX('DBX Sprint'!$A$7:$K$62, SMALL(IF((INDEX('DBX Sprint'!$A$7:$K$62, ,25)=("Complete"))*(INDEX('DBX Sprint'!$A$7:$K$62, ,25)="Complete"),MATCH(ROW('DBX Sprint'!$A$7:$K$62),ROW('DBX Sprint'!$A$7:$K$62)),""),ROWS($AA$34:AA36)),COLUMNS('DBX Sprint'!$A$1:A8)),"")} | AB36: {=IFERROR(INDEX('DBX Sprint'!$A$7:$K$62, SMALL(IF((INDEX('DBX Sprint'!$A$7:$K$62, ,25)<(TODAY()))*(INDEX('DBX Sprint'!$A$7:$K$62, ,25)<>"Complete"),MATCH(ROW('DBX Sprint'!$A$7:$K$62),ROW('DBX Sprint'!$A$7:$K$62)),""),ROWS($AB$34:AB36)),COLUMNS('DBX Sprint'!$A$1:A8)),"")} | AC36: {=IFERROR(INDEX('DBX Sprint'!$A$7:$K$62, SMALL(IF((INDEX('DBX Sprint'!$A$7:$K$62, ,25)<=(TODAY()+1))*(INDEX('DBX Sprint'!$A$7:$K$62, ,25)>=TODAY()),MATCH(ROW('DBX Sprint'!$A$7:$K$62),ROW('DBX Sprint'!$A$7:$K$62)),""),ROWS($AC$34:AC36)),COLUMNS('DBX Sprint'!$A$1:A8)),"")} | AD36: {=IFERROR(INDEX('DBX Sprint'!$A$7:$K$62, SMALL(IF((INDEX('DBX Sprint'!$A$7:$K$62, ,25)<=(TODAY()+5))*(INDEX('DBX Sprint'!$A$7:$K$62, ,25)>(TODAY()+1)),MATCH(ROW('DBX Sprint'!$A$7:$K$62),ROW('DBX Sprint'!$A$7:$K$62)),""),ROWS($AD$34:AD36)),COLUMNS('DBX Sprint'!$A$1:A8)),"")} | AE36: {=IFERROR(INDEX('DBX Sprint'!$A$7:$K$62, SMALL(IF((INDEX('DBX Sprint'!$A$7:$K$62, ,25)<=(TODAY()+10))*(INDEX('DBX Sprint'!$A$7:$K$62, ,25)>(TODAY()+5)),MATCH(ROW('DBX Sprint'!$A$7:$K$62),ROW('DBX Sprint'!$A$7:$K$62)),""),ROWS($AE$34:AE36)),COLUMNS('DBX Sprint'!$A$1:A8)),"")} | AG36: {=IFERROR(INDEX('DBX Sprint'!$A$7:$K$62, SMALL(IF((INDEX('DBX Sprint'!$A$7:$K$62, ,29)=("Complete"))*(INDEX('DBX Sprint'!$A$7:$K$62, ,29)="Complete"),MATCH(ROW('DBX Sprint'!$A$7:$K$62),ROW('DBX Sprint'!$A$7:$K$62)),""),ROWS($AG$34:AG36)),COLUMNS('DBX Sprint'!$A$1:A8)),"")} | AH36: {=IFERROR(INDEX('DBX Sprint'!$A$7:$K$62, SMALL(IF((INDEX('DBX Sprint'!$A$7:$K$62, ,29)<(TODAY()))*(INDEX('DBX Sprint'!$A$7:$K$62, ,29)<>"Complete"),MATCH(ROW('DBX Sprint'!$A$7:$K$62),ROW('DBX Sprint'!$A$7:$K$62)),""),ROWS($AH$34:AH36)),COLUMNS('DBX Sprint'!$A$1:A8)),"")} | AI36: {=IFERROR(INDEX('DBX Sprint'!$A$7:$K$62, SMALL(IF((INDEX('DBX Sprint'!$A$7:$K$62, ,29)<=(TODAY()+1))*(INDEX('DBX Sprint'!$A$7:$K$62, ,29)>=TODAY()),MATCH(ROW('DBX Sprint'!$A$7:$K$62),ROW('DBX Sprint'!$A$7:$K$62)),""),ROWS($AI$34:AI36)),COLUMNS('DBX Sprint'!$A$1:A8)),"")} | AJ36: {=IFERROR(INDEX('DBX Sprint'!$A$7:$K$62, SMALL(IF((INDEX('DBX Sprint'!$A$7:$K$62, ,29)<=(TODAY()+5))*(INDEX('DBX Sprint'!$A$7:$K$62, ,29)>(TODAY()+1)),MATCH(ROW('DBX Sprint'!$A$7:$K$62),ROW('DBX Sprint'!$A$7:$K$62)),""),ROWS($AJ$34:AJ36)),COLUMNS('DBX Sprint'!$A$1:A8)),"")} | AK36: {=IFERROR(INDEX('DBX Sprint'!$A$7:$K$62, SMALL(IF((INDEX('DBX Sprint'!$A$7:$K$62, ,29)<=(TODAY()+10))*(INDEX('DBX Sprint'!$A$7:$K$62, ,29)>(TODAY()+5)),MATCH(ROW('DBX Sprint'!$A$7:$K$62),ROW('DBX Sprint'!$A$7:$K$62)),""),ROWS($AK$34:AK36)),COLUMNS('DBX Sprint'!$A$1:A8)),"")} | AM36: {=IFERROR(INDEX('DBX Sprint'!$A$7:$K$62, SMALL(IF((INDEX('DBX Sprint'!$A$7:$K$62, ,32)=("Complete"))*(INDEX('DBX Sprint'!$A$7:$K$62, ,32)="Complete"),MATCH(ROW('DBX Sprint'!$A$7:$K$62),ROW('DBX Sprint'!$A$7:$K$62)),""),ROWS($AM$34:AM36)),COLUMNS('DBX Sprint'!$A$1:A8)),"")} | AN36: {=IFERROR(INDEX('DBX Sprint'!$A$7:$K$62, SMALL(IF((INDEX('DBX Sprint'!$A$7:$K$62, ,32)<(TODAY()))*(INDEX('DBX Sprint'!$A$7:$K$62, ,32)<>"Complete"),MATCH(ROW('DBX Sprint'!$A$7:$K$62),ROW('DBX Sprint'!$A$7:$K$62)),""),ROWS($AN$34:AN36)),COLUMNS('DBX Sprint'!$A$1:A8)),"")} | AO36: {=IFERROR(INDEX('DBX Sprint'!$A$7:$K$62, SMALL(IF((INDEX('DBX Sprint'!$A$7:$K$62, ,32)<=(TODAY()+1))*(INDEX('DBX Sprint'!$A$7:$K$62, ,32)>=TODAY()),MATCH(ROW('DBX Sprint'!$A$7:$K$62),ROW('DBX Sprint'!$A$7:$K$62)),""),ROWS($AO$34:AO36)),COLUMNS('DBX Sprint'!$A$1:A8)),"")} | AP36: {=IFERROR(INDEX('DBX Sprint'!$A$7:$K$62, SMALL(IF((INDEX('DBX Sprint'!$A$7:$K$62, ,32)<=(TODAY()+5))*(INDEX('DBX Sprint'!$A$7:$K$62, ,32)>(TODAY()+1)),MATCH(ROW('DBX Sprint'!$A$7:$K$62),ROW('DBX Sprint'!$A$7:$K$62)),""),ROWS($AP$34:AP36)),COLUMNS('DBX Sprint'!$A$1:A8)),"")} | AQ36: {=IFERROR(INDEX('DBX Sprint'!$A$7:$K$62, SMALL(IF((INDEX('DBX Sprint'!$A$7:$K$62, ,32)<=(TODAY()+10))*(INDEX('DBX Sprint'!$A$7:$K$62, ,32)>(TODAY()+5)),MATCH(ROW('DBX Sprint'!$A$7:$K$62),ROW('DBX Sprint'!$A$7:$K$62)),""),ROWS($AQ$34:AQ36)),COLUMNS('DBX Sprint'!$A$1:A8)),"")}
C37: {=IFERROR(INDEX('DBX Sprint'!$A$7:$K$62, SMALL(IF((INDEX('DBX Sprint'!$A$7:$K$62, ,13)=("Complete"))*(INDEX('DBX Sprint'!$A$7:$K$62, ,13)="Complete"),MATCH(ROW('DBX Sprint'!$A$7:$K$62),ROW('DBX Sprint'!$A$7:$K$62)),""),ROWS(C$34:$C37)),COLUMNS('DBX Sprint'!$A$1:A9)),"")} | D37: {=IFERROR(INDEX('DBX Sprint'!$A$7:$K$62, SMALL(IF((INDEX('DBX Sprint'!$A$7:$K$62, ,13)<(TODAY()))*(INDEX('DBX Sprint'!$A$7:$K$62, ,13)<>"Complete"),MATCH(ROW('DBX Sprint'!$A$7:$K$62),ROW('DBX Sprint'!$A$7:$K$62)),""),ROWS(D$34:$D37)),COLUMNS('DBX Sprint'!$A$1:A9)),"")} | E37: {=IFERROR(INDEX('DBX Sprint'!$A$7:$K$62, SMALL(IF((INDEX('DBX Sprint'!$A$7:$K$62, ,13)<=(TODAY()+1))*(INDEX('DBX Sprint'!$A$7:$K$62, ,13)>=TODAY()),MATCH(ROW('DBX Sprint'!$A$7:$K$62),ROW('DBX Sprint'!$A$7:$K$62)),""),ROWS(E$34:$E37)),COLUMNS('DBX Sprint'!$A$1:A9)),"")} | F37: {=IFERROR(INDEX('DBX Sprint'!$A$7:$K$62, SMALL(IF((INDEX('DBX Sprint'!$A$7:$K$62, ,13)<=(TODAY()+5))*(INDEX('DBX Sprint'!$A$7:$K$62, ,13)>(TODAY()+1)),MATCH(ROW('DBX Sprint'!$A$7:$K$62),ROW('DBX Sprint'!$A$7:$K$62)),""),ROWS($F$34:F37)),COLUMNS('DBX Sprint'!$A$1:A9)),"")} | G37: {=IFERROR(INDEX('DBX Sprint'!$A$7:$K$62, SMALL(IF((INDEX('DBX Sprint'!$A$7:$K$62, ,13)<=(TODAY()+10))*(INDEX('DBX Sprint'!$A$7:$K$62, ,13)>(TODAY()+5)),MATCH(ROW('DBX Sprint'!$A$7:$K$62),ROW('DBX Sprint'!$A$7:$K$62)),""),ROWS($G$34:G37)),COLUMNS('DBX Sprint'!$A$1:A9)),"")} | I37: {=IFERROR(INDEX('DBX Sprint'!$A$7:$K$62, SMALL(IF((INDEX('DBX Sprint'!$A$7:$K$62, ,16)=("Complete"))*(INDEX('DBX Sprint'!$A$7:$K$62, ,16)="Complete"),MATCH(ROW('DBX Sprint'!$A$7:$K$62),ROW('DBX Sprint'!$A$7:$K$62)),""),ROWS($I$34:I37)),COLUMNS('DBX Sprint'!$A$1:A9)),"")} | J37: {=IFERROR(INDEX('DBX Sprint'!$A$7:$K$62, SMALL(IF((INDEX('DBX Sprint'!$A$7:$K$62, ,16)<(TODAY()))*(INDEX('DBX Sprint'!$A$7:$K$62, ,16)<>"Complete"),MATCH(ROW('DBX Sprint'!$A$7:$K$62),ROW('DBX Sprint'!$A$7:$K$62)),""),ROWS($J$34:J37)),COLUMNS('DBX Sprint'!$A$1:A9)),"")} | K37: {=IFERROR(INDEX('DBX Sprint'!$A$7:$K$62, SMALL(IF((INDEX('DBX Sprint'!$A$7:$K$62, ,16)<=(TODAY()+1))*(INDEX('DBX Sprint'!$A$7:$K$62, ,16)>=TODAY()),MATCH(ROW('DBX Sprint'!$A$7:$K$62),ROW('DBX Sprint'!$A$7:$K$62)),""),ROWS($K$34:K37)),COLUMNS('DBX Sprint'!$A$1:A9)),"")} | L37: {=IFERROR(INDEX('DBX Sprint'!$A$7:$K$62, SMALL(IF((INDEX('DBX Sprint'!$A$7:$K$62, ,16)<=(TODAY()+5))*(INDEX('DBX Sprint'!$A$7:$K$62, ,16)>(TODAY()+1)),MATCH(ROW('DBX Sprint'!$A$7:$K$62),ROW('DBX Sprint'!$A$7:$K$62)),""),ROWS($L$34:L37)),COLUMNS('DBX Sprint'!$A$1:A9)),"")} | M37: {=IFERROR(INDEX('DBX Sprint'!$A$7:$K$62, SMALL(IF((INDEX('DBX Sprint'!$A$7:$K$62, ,16)<=(TODAY()+10))*(INDEX('DBX Sprint'!$A$7:$K$62, ,16)>(TODAY()+5)),MATCH(ROW('DBX Sprint'!$A$7:$K$62),ROW('DBX Sprint'!$A$7:$K$62)),""),ROWS($M$34:M37)),COLUMNS('DBX Sprint'!$A$1:A9)),"")} | O37: {=IFERROR(INDEX('DBX Sprint'!$A$7:$K$62, SMALL(IF((INDEX('DBX Sprint'!$A$7:$K$62, ,19)=("Complete"))*(INDEX('DBX Sprint'!$A$7:$K$62, ,19)="Complete"),MATCH(ROW('DBX Sprint'!$A$7:$K$62),ROW('DBX Sprint'!$A$7:$K$62)),""),ROWS($O$34:O37)),COLUMNS('DBX Sprint'!$A$1:A9)),"")} | P37: {=IFERROR(INDEX('DBX Sprint'!$A$7:$K$62, SMALL(IF((INDEX('DBX Sprint'!$A$7:$K$62, ,19)<(TODAY()))*(INDEX('DBX Sprint'!$A$7:$K$62, ,19)<>"Complete"),MATCH(ROW('DBX Sprint'!$A$7:$K$62),ROW('DBX Sprint'!$A$7:$K$62)),""),ROWS($P$34:P37)),COLUMNS('DBX Sprint'!$A$1:A9)),"")} | Q37: {=IFERROR(INDEX('DBX Sprint'!$A$7:$K$62, SMALL(IF((INDEX('DBX Sprint'!$A$7:$K$62, ,19)<=(TODAY()+1))*(INDEX('DBX Sprint'!$A$7:$K$62, ,19)>=TODAY()),MATCH(ROW('DBX Sprint'!$A$7:$K$62),ROW('DBX Sprint'!$A$7:$K$62)),""),ROWS($Q$34:Q37)),COLUMNS('DBX Sprint'!$A$1:A9)),"")} | R37: {=IFERROR(INDEX('DBX Sprint'!$A$7:$K$62, SMALL(IF((INDEX('DBX Sprint'!$A$7:$K$62, ,19)<=(TODAY()+5))*(INDEX('DBX Sprint'!$A$7:$K$62, ,19)>(TODAY()+1)),MATCH(ROW('DBX Sprint'!$A$7:$K$62),ROW('DBX Sprint'!$A$7:$K$62)),""),ROWS($R$34:R37)),COLUMNS('DBX Sprint'!$A$1:A9)),"")} | S37: {=IFERROR(INDEX('DBX Sprint'!$A$7:$K$62, SMALL(IF((INDEX('DBX Sprint'!$A$7:$K$62, ,19)<=(TODAY()+10))*(INDEX('DBX Sprint'!$A$7:$K$62, ,19)>(TODAY()+5)),MATCH(ROW('DBX Sprint'!$A$7:$K$62),ROW('DBX Sprint'!$A$7:$K$62)),""),ROWS($S$34:S37)),COLUMNS('DBX Sprint'!$A$1:A9)),"")} | U37: {=IFERROR(INDEX('DBX Sprint'!$A$7:$K$62, SMALL(IF((INDEX('DBX Sprint'!$A$7:$K$62, ,22)=("Complete"))*(INDEX('DBX Sprint'!$A$7:$K$62, ,22)="Complete"),MATCH(ROW('DBX Sprint'!$A$7:$K$62),ROW('DBX Sprint'!$A$7:$K$62)),""),ROWS($U$34:U37)),COLUMNS('DBX Sprint'!$A$1:A9)),"")} | V37: {=IFERROR(INDEX('DBX Sprint'!$A$7:$K$62, SMALL(IF((INDEX('DBX Sprint'!$A$7:$K$62, ,22)<(TODAY()))*(INDEX('DBX Sprint'!$A$7:$K$62, ,22)<>"Complete"),MATCH(ROW('DBX Sprint'!$A$7:$K$62),ROW('DBX Sprint'!$A$7:$K$62)),""),ROWS($V$34:V37)),COLUMNS('DBX Sprint'!$A$1:A9)),"")} | W37: {=IFERROR(INDEX('DBX Sprint'!$A$7:$K$62, SMALL(IF((INDEX('DBX Sprint'!$A$7:$K$62, ,22)<=(TODAY()+1))*(INDEX('DBX Sprint'!$A$7:$K$62, ,22)>=TODAY()),MATCH(ROW('DBX Sprint'!$A$7:$K$62),ROW('DBX Sprint'!$A$7:$K$62)),""),ROWS($W$34:W37)),COLUMNS('DBX Sprint'!$A$1:A9)),"")} | X37: {=IFERROR(INDEX('DBX Sprint'!$A$7:$K$62, SMALL(IF((INDEX('DBX Sprint'!$A$7:$K$62, ,22)<=(TODAY()+5))*(INDEX('DBX Sprint'!$A$7:$K$62, ,22)>(TODAY()+1)),MATCH(ROW('DBX Sprint'!$A$7:$K$62),ROW('DBX Sprint'!$A$7:$K$62)),""),ROWS($X$34:X37)),COLUMNS('DBX Sprint'!$A$1:A9)),"")} | Y37: {=IFERROR(INDEX('DBX Sprint'!$A$7:$K$62, SMALL(IF((INDEX('DBX Sprint'!$A$7:$K$62, ,22)<=(TODAY()+10))*(INDEX('DBX Sprint'!$A$7:$K$62, ,22)>(TODAY()+5)),MATCH(ROW('DBX Sprint'!$A$7:$K$62),ROW('DBX Sprint'!$A$7:$K$62)),""),ROWS($Y$34:Y37)),COLUMNS('DBX Sprint'!$A$1:A9)),"")} | AA37: {=IFERROR(INDEX('DBX Sprint'!$A$7:$K$62, SMALL(IF((INDEX('DBX Sprint'!$A$7:$K$62, ,25)=("Complete"))*(INDEX('DBX Sprint'!$A$7:$K$62, ,25)="Complete"),MATCH(ROW('DBX Sprint'!$A$7:$K$62),ROW('DBX Sprint'!$A$7:$K$62)),""),ROWS($AA$34:AA37)),COLUMNS('DBX Sprint'!$A$1:A9)),"")} | AB37: {=IFERROR(INDEX('DBX Sprint'!$A$7:$K$62, SMALL(IF((INDEX('DBX Sprint'!$A$7:$K$62, ,25)<(TODAY()))*(INDEX('DBX Sprint'!$A$7:$K$62, ,25)<>"Complete"),MATCH(ROW('DBX Sprint'!$A$7:$K$62),ROW('DBX Sprint'!$A$7:$K$62)),""),ROWS($AB$34:AB37)),COLUMNS('DBX Sprint'!$A$1:A9)),"")} | AC37: {=IFERROR(INDEX('DBX Sprint'!$A$7:$K$62, SMALL(IF((INDEX('DBX Sprint'!$A$7:$K$62, ,25)<=(TODAY()+1))*(INDEX('DBX Sprint'!$A$7:$K$62, ,25)>=TODAY()),MATCH(ROW('DBX Sprint'!$A$7:$K$62),ROW('DBX Sprint'!$A$7:$K$62)),""),ROWS($AC$34:AC37)),COLUMNS('DBX Sprint'!$A$1:A9)),"")} | AD37: {=IFERROR(INDEX('DBX Sprint'!$A$7:$K$62, SMALL(IF((INDEX('DBX Sprint'!$A$7:$K$62, ,25)<=(TODAY()+5))*(INDEX('DBX Sprint'!$A$7:$K$62, ,25)>(TODAY()+1)),MATCH(ROW('DBX Sprint'!$A$7:$K$62),ROW('DBX Sprint'!$A$7:$K$62)),""),ROWS($AD$34:AD37)),COLUMNS('DBX Sprint'!$A$1:A9)),"")} | AE37: {=IFERROR(INDEX('DBX Sprint'!$A$7:$K$62, SMALL(IF((INDEX('DBX Sprint'!$A$7:$K$62, ,25)<=(TODAY()+10))*(INDEX('DBX Sprint'!$A$7:$K$62, ,25)>(TODAY()+5)),MATCH(ROW('DBX Sprint'!$A$7:$K$62),ROW('DBX Sprint'!$A$7:$K$62)),""),ROWS($AE$34:AE37)),COLUMNS('DBX Sprint'!$A$1:A9)),"")} | AG37: {=IFERROR(INDEX('DBX Sprint'!$A$7:$K$62, SMALL(IF((INDEX('DBX Sprint'!$A$7:$K$62, ,29)=("Complete"))*(INDEX('DBX Sprint'!$A$7:$K$62, ,29)="Complete"),MATCH(ROW('DBX Sprint'!$A$7:$K$62),ROW('DBX Sprint'!$A$7:$K$62)),""),ROWS($AG$34:AG37)),COLUMNS('DBX Sprint'!$A$1:A9)),"")} | AH37: {=IFERROR(INDEX('DBX Sprint'!$A$7:$K$62, SMALL(IF((INDEX('DBX Sprint'!$A$7:$K$62, ,29)<(TODAY()))*(INDEX('DBX Sprint'!$A$7:$K$62, ,29)<>"Complete"),MATCH(ROW('DBX Sprint'!$A$7:$K$62),ROW('DBX Sprint'!$A$7:$K$62)),""),ROWS($AH$34:AH37)),COLUMNS('DBX Sprint'!$A$1:A9)),"")} | AI37: {=IFERROR(INDEX('DBX Sprint'!$A$7:$K$62, SMALL(IF((INDEX('DBX Sprint'!$A$7:$K$62, ,29)<=(TODAY()+1))*(INDEX('DBX Sprint'!$A$7:$K$62, ,29)>=TODAY()),MATCH(ROW('DBX Sprint'!$A$7:$K$62),ROW('DBX Sprint'!$A$7:$K$62)),""),ROWS($AI$34:AI37)),COLUMNS('DBX Sprint'!$A$1:A9)),"")} | AJ37: {=IFERROR(INDEX('DBX Sprint'!$A$7:$K$62, SMALL(IF((INDEX('DBX Sprint'!$A$7:$K$62, ,29)<=(TODAY()+5))*(INDEX('DBX Sprint'!$A$7:$K$62, ,29)>(TODAY()+1)),MATCH(ROW('DBX Sprint'!$A$7:$K$62),ROW('DBX Sprint'!$A$7:$K$62)),""),ROWS($AJ$34:AJ37)),COLUMNS('DBX Sprint'!$A$1:A9)),"")} | AK37: {=IFERROR(INDEX('DBX Sprint'!$A$7:$K$62, SMALL(IF((INDEX('DBX Sprint'!$A$7:$K$62, ,29)<=(TODAY()+10))*(INDEX('DBX Sprint'!$A$7:$K$62, ,29)>(TODAY()+5)),MATCH(ROW('DBX Sprint'!$A$7:$K$62),ROW('DBX Sprint'!$A$7:$K$62)),""),ROWS($AK$34:AK37)),COLUMNS('DBX Sprint'!$A$1:A9)),"")} | AM37: {=IFERROR(INDEX('DBX Sprint'!$A$7:$K$62, SMALL(IF((INDEX('DBX Sprint'!$A$7:$K$62, ,32)=("Complete"))*(INDEX('DBX Sprint'!$A$7:$K$62, ,32)="Complete"),MATCH(ROW('DBX Sprint'!$A$7:$K$62),ROW('DBX Sprint'!$A$7:$K$62)),""),ROWS($AM$34:AM37)),COLUMNS('DBX Sprint'!$A$1:A9)),"")} | AN37: {=IFERROR(INDEX('DBX Sprint'!$A$7:$K$62, SMALL(IF((INDEX('DBX Sprint'!$A$7:$K$62, ,32)<(TODAY()))*(INDEX('DBX Sprint'!$A$7:$K$62, ,32)<>"Complete"),MATCH(ROW('DBX Sprint'!$A$7:$K$62),ROW('DBX Sprint'!$A$7:$K$62)),""),ROWS($AN$34:AN37)),COLUMNS('DBX Sprint'!$A$1:A9)),"")} | AO37: {=IFERROR(INDEX('DBX Sprint'!$A$7:$K$62, SMALL(IF((INDEX('DBX Sprint'!$A$7:$K$62, ,32)<=(TODAY()+1))*(INDEX('DBX Sprint'!$A$7:$K$62, ,32)>=TODAY()),MATCH(ROW('DBX Sprint'!$A$7:$K$62),ROW('DBX Sprint'!$A$7:$K$62)),""),ROWS($AO$34:AO37)),COLUMNS('DBX Sprint'!$A$1:A9)),"")} | AP37: {=IFERROR(INDEX('DBX Sprint'!$A$7:$K$62, SMALL(IF((INDEX('DBX Sprint'!$A$7:$K$62, ,32)<=(TODAY()+5))*(INDEX('DBX Sprint'!$A$7:$K$62, ,32)>(TODAY()+1)),MATCH(ROW('DBX Sprint'!$A$7:$K$62),ROW('DBX Sprint'!$A$7:$K$62)),""),ROWS($AP$34:AP37)),COLUMNS('DBX Sprint'!$A$1:A9)),"")} | AQ37: {=IFERROR(INDEX('DBX Sprint'!$A$7:$K$62, SMALL(IF((INDEX('DBX Sprint'!$A$7:$K$62, ,32)<=(TODAY()+10))*(INDEX('DBX Sprint'!$A$7:$K$62, ,32)>(TODAY()+5)),MATCH(ROW('DBX Sprint'!$A$7:$K$62),ROW('DBX Sprint'!$A$7:$K$62)),""),ROWS($AQ$34:AQ37)),COLUMNS('DBX Sprint'!$A$1:A9)),"")}
