Workbook
Name Assignee_Main: 'Indicative Timeline'!#REF!
Name ColumnTitle1: Contacts[[#Headers],[Organization]]
Name Display_Week: 'CWB Deployment Plan'!$G$1
Name Display_Week: 'CWB Deployment Plan VCOO'!$I$1
Name Display_Week: 'Infinity OLB & Mob App'!$H$1
Name Display_Week: 'Project Readiness'!$F$1
Name Display_Week: '[1]OLB & Mob App (OLD)'!$H$4
Name Display_Week: 'OLB & Mob App (OLD)'!$H$4
Name Project_Start: 'CWB Deployment Plan'!$C$1
Name Project_Start: 'CWB Deployment Plan VCOO'!$F$1
Name Project_Start: 'Infinity OLB & Mob App'!$D$1
Name Project_Start: 'Project Readiness'!$C$1
Name Project_Start: '[1]OLB & Mob App (OLD)'!$H$3
Name Project_Start: 'OLB & Mob App (OLD)'!$H$3
Name RowTitleRegion1..I1: 'Contact list'!#REF!
Name task_end: 'CWB Deployment Plan'!$H1
Name task_end: 'CWB Deployment Plan VCOO'!$J1
Name task_end: 'Infinity OLB & Mob App'!$I1
Name task_end: 'OLB & Mob App (OLD)'!$I1
Name task_end: 'Project Readiness'!$H1
Name Task_End_Main: 'Indicative Timeline'!$G:$G
Name task_progress: 'CWB Deployment Plan'!$E1
Name task_progress: 'CWB Deployment Plan VCOO'!$G1
Name task_progress: 'Infinity OLB & Mob App'!$F1
Name task_progress: 'OLB & Mob App (OLD)'!$G1
Name task_progress: 'Project Readiness'!$E1
Name task_start: 'CWB Deployment Plan'!$G1
Name task_start: 'CWB Deployment Plan VCOO'!$I1
Name task_start: 'Infinity OLB & Mob App'!$H1
Name task_start: 'OLB & Mob App (OLD)'!$H1
Name task_start: 'Project Readiness'!$G1
Name Task_Start_Main: 'Indicative Timeline'!$F:$F
Name today: TODAY()
Name today: TODAY()
Name today: TODAY()
Name today: TODAY()
Name today: TODAY()

Sheet CWB Deployment Plan VCOO
H1: Display Week: | I1: 1 | O1: =O2 -> -5 | V1: =V2 -> 2 | AC1: =AC2 -> 9 | AJ1: =AJ2 -> 16 | AQ1: =AQ2 -> 23 | AX1: =AX2 -> 30 | BE1: =BE2 -> 37 | BL1: =BL2 -> 44 | BS1: =BS2 -> 51 | BZ1: =BZ2 -> 58 | CG1: =CG2 -> 65 | CN1: =CN2 -> 72 | CU1: =CU2 -> 79
O2: =Project_Start-WEEKDAY(Project_Start,1)+2+7*(Display_Week-1) -> -5 | P2: =O2+1 -> -4 | Q2: =P2+1 -> -3 | R2: =Q2+1 -> -2 | S2: =R2+1 -> -1 | T2: =S2+1 -> 0 | U2: =T2+1 -> 1 | V2: =U2+1 -> 2 | W2: =V2+1 -> 3 | ... DA2: =CZ2+1 -> 85
A3: Task ID | B3: TASK | C3: Scheduled START | D3: Scheduled END | E3: Status | F3: ASSIGNED/CONFIRMATION GROUP | G3: PROGRESS (%) | H3: Duration (H or M) | I3: Scheduled START | J3: Scheduled END | K3: Estimated/Actual START | L3: Estimated/Actual END | N3: DAYS | O3: =LEFT(TEXT(O2,"ddd"),1) -> #VALUE! | P3: =LEFT(TEXT(P2,"ddd"),1) -> #VALUE! | Q3: =LEFT(TEXT(Q2,"ddd"),1) -> #VALUE! | R3: =LEFT(TEXT(R2,"ddd"),1) -> #VALUE! | S3: =LEFT(TEXT(S2,"ddd"),1) -> #VALUE! | T3: =LEFT(TEXT(T2,"ddd"),1) -> S | U3: =LEFT(TEXT(U2,"ddd"),1) -> S | V3: =LEFT(TEXT(V2,"ddd"),1) -> M | ... DA3: =LEFT(TEXT(DA2,"ddd"),1) -> S
A4: CWB | N4: =IF(OR(ISBLANK(task_start),ISBLANK(task_end)),"",task_end-task_start+1)
B5: SMTP Services
A6: SMTP.1 | B6: Confirm exception to allow SMTP traffic outside of CWB network - currently limited to cwbank.com emails. | C6: 44764 | D6: 44764 | E6: Completed | F6: Adam / Stacy
A7: SMTP.2 | B7: Confirm email address proxy for all outgoing emails from Infinity. E.g. no-reply.cwb.digital@cwbank.com | C7: 44764 | D7: 44764 | E7: Completed | F7: Adam / Stacy
A8: SMTP.3 | B8: Send email address proxy to Temenos for inclusion in the runbook | C8: 44764 | D8: 44764 | E8: Completed | F8: Andrew / Alvin
A9: SMTP.4 | B9: Provide confirmation to CWB Infrastructure (Ryan Mah) to update the SMTP traffic rule in production | C9: 44764 | D9: 44764 | E9: Completed | F9: Andrew / Alvin
A10: SMTP.5 | B10: Implement SMTP rule change in production (update email to approved value) | C10: 44770 | D10: 44770 | E10: Pending | F10: Ryan Mah/Vijay
A11: SMTP.6 | B11: Smoketest SMTP Services | C11: 44770 | D11: 44770 | E11: Pending | F11: Temenos | DB11: send test email
B12: T24
A13: T24.1 | B13: Identify R1.1 T24 code dependencies prior to launch | C13: 44742 | D13: 44742 | E13: Completed | F13: Charlotte
A14: T24.2 | B14: Deploy R1.0 to OPSIT2 for Pre-Production Regression Testing | C14: 44753 | D14: 44753 | E14: Completed | F14: Sundhar
A15: T24.3 | B15: Deploy T24 code to OPSIT2 for Pre-Production Regression Testing (R1.1) | C15: 44745 | D15: 44745 | E15: Completed | F15: Charlotte
A16: T24.4 | B16: Pre-Production Regression Testing | C16: 44754 | D16: 44755 | E16: Completed | F16: Operational QA (Trisha)
A17: T24.5 | B17: Pre-Production Regression Defect Fixes and Re-test (if applicable) | C17: 44756 | D17: 44757 | E17: Completed | F17: Charlotte/Trisha
A18: T24.6 | B18: T24 Production Deployment | C18: 44759 | D18: 44759 | E18: Completed | F18: RM (Release Management)
A19: T24.7 | B19: 2 defects remaining for T24 only | C19: 44770 | D19: 44770 | E19: Pending | F19: RM (Release Management)
B20: Data Migration
A21: DM.1 | B21: Confirm signoff for C1 CR - submittance. (Profile E impact - early November) - may need to include in VCOO/FF release | E21: In Progress | F21: Dapo / Braydon | H21: 0
A22: DM.1 | B22: Deploy final DM process code to production - updating ETL code in PROD | C22: 44761 | D22: 44761 | E22: Completed | F22: Dapo / Henry | H22: 0
A23: DM.2 | B23: [Not required] Reset password hook on dedicated C1 production test account to specifically test password hook APIs | C23: 44762 | D23: 44762 | E23: Pending | F23: Tony
A24: DM.3 | B24: Test Password hook API | C24: 44765 | D24: 44765 | E24: Pending | F24: Adam
A25: DM.4 | B25: [Not required until after go-live] Infinity to validate connection to DM load tables | C25: 44765 | D25: 44765 | E25: Pending | F25: Vijaya/Satish
B26: Third-Party Applications
B27: Celero
A28: CEL.1 | B28: No deployments required for R1.1 | E28: Completed | F28: Mark D | H28: 0
B29: Central1 - CRA Deployment
A30: C1.1 | B30: QA signoff of CRA API | C30: 44757 | D30: 44757 | E30: Completed | F30: Adrian
A31: C1.2 | B31: Notify C1 to stand-up API from non-prod env to prod | C31: 44757 | D31: 44757 | E31: Completed | F31: Mark D
A32: C1.3 | B32: Stand-up Mule API into Prod - requires CR approval | C32: 44761 | D32: 44761 | E32: Completed | F32: Mark D / Alex / CAB
A33: C1.4 | B33: Confirm CRA API connectivity CWB & C1 | C33: 44764 | D33: 44764 | E33: Completed | F33: CWB and C1
B34: OKTA
A35: OK.1 | B35: Confirm tasks with Tony regarding outstanding actions for pre-prod/prod | F35: Tony Fang / Andrew | G35: 1 | H35: 0 | I35: 44501 | J35: 44501
A36: OK.2 | B36: Provide change details to the CWB IAM Team (IAM = Identity Access Management) | F36: Tony Fang | H36: 0.5 | I36: 44502 | J36: 44502
A37: OK.3 | B37: Create and submit Change Requests for Okta production | F37: CWB IAM Team | H37: 0.5 | I37: 44503 | J37: 44503
A38: OK.4 | B38: Approve CRs for change | F38: Thomas Matthew | H38: 0.5 | I38: 44504 | J38: 44504
A39: OK.5 | B39: Complete production deployment for Okta (Date to align once new go-live has been established) | F39: Tony Fang/Rajiv Sharma | H39: 0.5
A40: OK.6 | B40: CR#1: Update Sign In Page to 5.latest SIW Version, Configure Headings/Labels/Customized Help Links | E40: Completed | F40: Tony Fang/Rajiv Sharma
...

Sheet RollBackActivities
A1: Task ID | B1: TASK | C1: Scheduled START | D1: Scheduled END | E1: Status | F1: ASSIGNED/CONFIRMATION GROUP | G1: PROGRESS (%) | H1: Duration (Days)
B2: Rollback Activities
A3: TEM.1 | B3: Export the Fabric Apps((DBPLocalServices, KonyBankingAdminConsole, EventsManager and AlertsEngine ) from the backup. | C3: 44769 | D3: 44769 | E3: Pending | F3: Pavani/Gowthami | H3: 2H
A4: TEM.2 | B4: Import the Fabric apps into Target environment. | C4: 44769 | D4: 44769 | E4: Pending | F4: Pavani/Gowthami | H4: 2H
A5: TEM.3 | B5: Update the Identity Service (DbxUserLogin) URL to map with target environment. | C5: 44769 | D5: 44769 | E5: Pending | F5: Pavani/Gowthami | H5: 15M
A6: TEM.4 | B6: Update the Identity Service (OktaOAuthIdentityProvider) - OktaOAuthIdentityProvider - Authorize Endpoint, Token Endpoint, Callback URL, Logout Url, Client ID, Client Secret | C6: 44769 | D6: 44769 | E6: Pending | F6: Pavani/Gowthami | H6: 0.5H
A7: TEM.5 | B7: Update DB configuration with the backup instance database credentials in the Integration Services,Object services and in configuration parameters (dbpRbLocalServicesdb & CRUDLayer) for all the applicable apps(DBPLocalservices,KonyBankingAdminConsole,DBPEventManager) | C7: 44769 | D7: 44769 | E7: Pending | F7: Pavani/Gowthami | H7: 1H
A8: TEM.6 | B8: Update MuleSoft endpoints with the correct environment URL & credentials. | C8: 44769 | D8: 44769 | E8: Pending | F8: Pavani/Gowthami | H8: 0.5H
A9: TEM.7 | B9: Compare & merge Server Properties with source environment and, update the values which are target env specific. | C9: 44769 | D9: 44769 | E9: Pending | F9: Pavani/Gowthami | H9: 1H
A10: TEM.8 | B10: Compare & merge Client Properties with source environment and, update the values which are target env specific. | C10: 44769 | D10: 44769 | E10: Pending | F10: Pavani/Gowthami | H10: 1H
A11: TEM.9 | B11: Upload the custom code jars (cwbservices, eventdispatcher, migration ) for pre or post processor changes from the backup | C11: 44769 | D11: 44769 | E11: Pending | F11: Pavani/Gowthami | H11: 0.5H
A12: TEM.10 | B12: Configure Campaign MS - Campaign Engine, KonyBankingAdminConsole, ODataCampaign | C12: 44769 | D12: 44769 | E12: Pending | F12: Pavani/Gowthami | H12: 1H
A13: TEM.11 | B13: Publish Fabric apps (KonyBankingAdminConsole) | C13: 44769 | D13: 44769 | E13: Pending | F13: Pavani/Gowthami | H13: 1H
A14: TEM.12 | B14: Publish Fabric apps (DBPLocalServices, event manager,odatacampaign,limitsengine and campaign engine). | C14: 44769 | D14: 44769 | E14: Pending | F14: Pavani/Gowthami | H14: 2H
... A20: TEM.18 | B20: Upload the Spotlight.zip to KonBankingAdminConsole Fabric app and publish. | C20: 44769 | D20: 44769 | E20: Pending | F20: Pavani/Gowthami | H20: 1H

Sheet Apps list
A1: Systesm / 3rd Party Deploys | C1: Update/deployment Required? Yes/No
B2: T24 | C2: YES | D2: Charlotte has provided R1.1 code dependencies. T24 currently set as pre-production release.
B3: Data Migration | C3: TBD | D3: Follow-up with Dapo and Henry to see if there is anything specific to R1.1 DM the requires promotion
B4: Celero | C4: NO
B5: Central1 | C5: YES | D5: CRA Deployment
B6: Okta | C6: YES | D6: OLB R1.1 will require some updates to the Okta-hosted Sign In Widget (for mobile) to enable Forgot PW/Unlock.
B7: MuleSoft | C7: YES
B8: CloudFlare | C8: YES | D8: Latest outage pages, planned and unplanned, to be deployed. Can be done in advance of R1.1 go-live.
B9: Navaera | C9: NO
B10: CRA Direct Deposit | C10: YES
B11: Helix | C11: NO
B12: Mobile App | C12: YES
B13: BRIM | C13: YES
B14: XAI / TDL / TDH | C14: YES | D14: Confirm with Temenos
B15: Dashboard | C15: YES
B16: Spotlight | C16: YES
B17: Forgot password | C17: YES | D17: CR#2
B18: Encryption Keys | C18: YES
B19: Codat | C19: YES

Sheet Contact list
A1: Contact List
A2: Organization | B2: Name | C2: Phone | D2: Home phone | E2: Email | F2: Role | G2: Notes
A3: BRIM | B3: Fayez Alameddine | C3: 4168268160 | E3: fayez.alameddine@brimfinancial.com | F3: BRIM Lead
A4: BRIM | B4: Kevin Kim | C4: 9053203031 | E4: kevin.kim@brimfinancial.com | F4: BRIM Lead
A5: BRIM | B5: Mo Zubby | E5: mo.zubby@brimfinancial.com | F5: Technical Support
A6: BRIM | B6: Thomas Patterson | C6: 6473381468 | E6: thomas.patterson@brimfinancial.com | F6: BRIM Lead
A7: CWB | B7: Adam Skoreyko | C7: 7809748010 | E7: Adam.skoreyko@cwbank.com | F7: DBX Business Lead
A8: CWB | B8: Alex Yakovenko | C8: 2368335251 | E8: alex.yakovenko@cwbank.com | F8: Mulesoft/DTS Lead
A9: CWB | B9: Alvin Quach | C9: 7809347087 | E9: Alvin.quach@cwbank.com | F9: Project Manager
A10: CWB | B10: Andrew Petesky | C10: 7807204226 | E10: andrew.petesky@cwbank.com | F10: Project Manager
A11: CWB | B11: Carmela Pucci | C11: 7809835216 | E11: Carmela.pucci@cwbank.com | F11: QA Lead
A12: CWB | B12: Carmen Girardin | C12: 2045584669 | E12: carmen.girardin@cwbank.com | F12: IAM Lead
A13: CWB | B13: Christina Mullin | E13: christina.mullin@cwbank.com | F13: Digital Program Owner
A14: CWB | B14: Dilshad Bhatti | E14: dilshad.bhatti@cwbank.com | F14: Program Manager
A15: CWB | B15: Dino Noce | C15: 7806863285 | E15: dino.noce@cwbank.com | F15: Project Manager
A16: CWB | B16: Edmund Chua | C16: 7809194664 | E16: Edmund.chua@cwbank.com | F16: VCOO Business Lead
A17: CWB | B17: Gerry Weber | C17: 2369912757 | E17: gerry.weber@cwbank.com | F17: Technical lead
A18: CWB | B18: Jason Bond | E18: Jason.bond@cwbank.com | F18: Digital Program Owner
A19: CWB | B19: Kris Aloisio | C19: 7809646957 | E19: kris.aloisio@cwbank.com | F19: BAS Support
A20: CWB | B20: Mark Doubinin | C20: 5879879460 | E20: mark.doubinin@cwbank.com | F20: DTS Lead
A21: CWB | B21: Mohammed Yahya | C21: 7806193224 | E21: mohammed.yahya@cwbank.com | F21: IAM Technical Support
A22: CWB | B22: Tony Fang | E22: tony.fang@techjutsu.com | F22: IAM Consultant
A23: Temenos | B23: Ahmed Tawfik | C23: 6478938908 | E23: atawfik@temenos.com | F23: Digital Program Owner
A24: Temenos | B24: Niel Colinares | C24: 4167990798 | E24: Niel.colinares@cwbank.com | F24: Program Manager
A25: Temenos | B25: Sundhar Sangaranarayanan | C25: 6472126477 | E25: s.sundhar@temenos.com | F25: Project Manager
A26: Temenos | B26: Hemantha kallathi | E26: hemantha.kallati@temenos.com | F26: Senior Solution Architect
A27: Temenos | B27: Vijay Parella | C27: 2054276587 | E27: p.vijayalakshmi@temenos.com | F27: Architect/Tech Lead
A28: Temenos | B28: Satish Kolkunda | C28: 6475760345 | E28: satish.kolkunda@contractor.temenos.com | F28: TL
A29: Temenos | B29: Kalin Todorov | E29: ktodorov@temenos.com | F29: VCOO Tech Lead
A30: Temenos | B30: Karthikeyan Koothan | E30: karthikeyank@temenos.com | F30: Infinity
A31: Temenos | B31: Goutham Sahu | C31: 9989475327 | E31: goutam.sahu@temenos.com | F31: Product Development
A32: Temenos | B32: Krupal Chennuri | C32: 8978306909 | E32: krupal.chennuri@temenos.com | F32: Visualizer
A33: Temenos | B33: Lakshmankumar | C33: 7893149141 | E33: Lakshmankumar Kothagundla | F33: Visualizer
A34: Temenos | B34: Veera Nagireddy | C34: 9886054926 | E34: veeravsn@temenos.com | F34: Cloud Operations / Hosting
A35: Temenos | B35: Vani Tiruveedhula | C35: 9490793420 | E35: vani.tiruveedhula@temenos.com | F35: PACS
A36: Temenos | B36: Kanuru Lokesh | C36: 9948053807 | E36: kanuru.lokesh@temenos.com | F36: IT
A37: Temenos | B37: Satya Tammana | C37: 9885052849 | E37: satya.tammana@temenos.com | F37: Delivery Manager
A38: Temenos | B38: Vamsi Chilukuri | C38: 9866273937 | E38: vamsikrishna.c@temenos.com | F38: Delivery Manager
A39: Temenos | B39: Srikanth Sriramoji | C39: 9908225443 | E39: srikanth.sriramoji@temenos.com | F39: Architect
A40: Temenos | B40: Pavani Challa | C40: 9059282576 | E40: pavani.challa@temenos.com | F40: Tech Lead
...

Sheet Indicative Timeline
H2: 44197 | BH2: 44562
H3: January | L3: February | P3: March | U3: April | Y3: May | AD3: June | AH3: July | AL3: August | AQ3: September | AU3: October | AY3: November | BD3: December | BH3: =BH4 -> 44564 | BM3: =BM4 -> 44599 | BQ3: =BQ4 -> 44627 | BU3: =BU4 -> 44655 | BY3: =BY4 -> 44683 | CD3: =CD4 -> 44718 | CH3: =CH4 -> 44746 | CL3: =CL4 -> 44774 | CQ3: =CQ4 -> 44809 | CU3: =CU4 -> 44837 | CZ3: =CZ4 -> 44872 | DD3: =DD4 -> 44900
D4: Assignee | E4: Progress | F4: Task Start | G4: Task End | H4: 44200 | I4: =H4+7 -> 44207 | J4: =I4+7 -> 44214 | K4: =J4+7 -> 44221 | L4: =K4+7 -> 44228 | M4: =L4+7 -> 44235 | N4: =M4+7 -> 44242 | O4: =N4+7 -> 44249 | P4: =O4+7 -> 44256 | ... DG4: =DF4+7 -> 44921
B5: Public Website (PWS) | C5: Readiness
C6: Project Plan & Governance | E6: =VLOOKUP($C6,'Project Readiness'!$B:$K,4,0) -> 0 | F6: =VLOOKUP($C6,'Project Readiness'!$B:$K,6,0) -> 44200 | G6: =VLOOKUP($C6,'Project Readiness'!$B:$K,7,0) -> 44245
C7: Training | E7: =VLOOKUP($C7,'Project Readiness'!$B:$K,4,0) -> 0 | F7: =VLOOKUP($C7,'Project Readiness'!$B:$K,6,0) -> 44200 | G7: =VLOOKUP($C7,'Project Readiness'!$B:$K,7,0) -> 44214
B8: Mobile App & Online Banking (OLB) | C8: OLB and Mobile App1
C9: Initial Config & ISO/API Test | E9: =VLOOKUP($C9,'Infinity OLB & Mob App'!$C:$L,4,0) -> 0 | F9: =VLOOKUP($C9,'Infinity OLB & Mob App'!$C:$L,6,0) -> 0 | G9: =VLOOKUP($C9,'Infinity OLB & Mob App'!$C:$L,7,0) -> 0
C10: Data Seeding | E10: =VLOOKUP($C10,'Infinity OLB & Mob App'!$C:$L,4,0) -> 0 | F10: =VLOOKUP($C10,'Infinity OLB & Mob App'!$C:$L,6,0) -> 0 | G10: =VLOOKUP($C10,'Infinity OLB & Mob App'!$C:$L,7,0) -> 0
C11: Mobile App Only
C12: TEST Config & Test (Mobile) | E12: =VLOOKUP($C12,'Infinity OLB & Mob App'!$C:$L,4,0) -> #N/A | F12: =VLOOKUP($C12,'Infinity OLB & Mob App'!$C:$L,6,0) -> #N/A | G12: =VLOOKUP($C12,'Infinity OLB & Mob App'!$C:$L,7,0) -> #N/A
C13: UAT Config & Test (Mobile) | E13: =VLOOKUP($C13,'Infinity OLB & Mob App'!$C:$L,4,0) -> #N/A | F13: =VLOOKUP($C13,'Infinity OLB & Mob App'!$C:$L,6,0) -> #N/A | G13: =VLOOKUP($C13,'Infinity OLB & Mob App'!$C:$L,7,0) -> #N/A
C14: Client UAT (Mobile) | E14: =VLOOKUP($C14,'Infinity OLB & Mob App'!$C:$L,4,0) -> #N/A | F14: =VLOOKUP($C14,'Infinity OLB & Mob App'!$C:$L,6,0) -> #N/A | G14: =VLOOKUP($C14,'Infinity OLB & Mob App'!$C:$L,7,0) -> #N/A
C15: Client BETA F&F/Pilot (Mobile) | E15: =VLOOKUP($C15,'Infinity OLB & Mob App'!$C:$L,4,0) -> #N/A | F15: =VLOOKUP($C15,'Infinity OLB & Mob App'!$C:$L,6,0) -> #N/A | G15: =VLOOKUP($C15,'Infinity OLB & Mob App'!$C:$L,7,0) -> #N/A
C16: PROD App Release | E16: =VLOOKUP($C16,'Infinity OLB & Mob App'!$C:$L,4,0) -> 0 | F16: =VLOOKUP($C16,'Infinity OLB & Mob App'!$C:$L,6,0) -> 44653 | G16: =VLOOKUP($C16,'Infinity OLB & Mob App'!$C:$L,7,0) -> 44653
C17: OLB Only
C18: TEST Config & Test (OLB) | E18: =VLOOKUP($C18,'Infinity OLB & Mob App'!$C:$L,4,0) -> #N/A | F18: =VLOOKUP($C18,'Infinity OLB & Mob App'!$C:$L,6,0) -> #N/A | G18: =VLOOKUP($C18,'Infinity OLB & Mob App'!$C:$L,7,0) -> #N/A
C19: UAT Config & Test (OLB) | E19: =VLOOKUP($C19,'Infinity OLB & Mob App'!$C:$L,4,0) -> #N/A | F19: =VLOOKUP($C19,'Infinity OLB & Mob App'!$C:$L,6,0) -> #N/A | G19: =VLOOKUP($C19,'Infinity OLB & Mob App'!$C:$L,7,0) -> #N/A
C20: Client UAT (OLB) | E20: =VLOOKUP($C20,'Infinity OLB & Mob App'!$C:$L,4,0) -> #N/A | F20: =VLOOKUP($C20,'Infinity OLB & Mob App'!$C:$L,6,0) -> #N/A | G20: =VLOOKUP($C20,'Infinity OLB & Mob App'!$C:$L,7,0) -> #N/A
C21: Client BETA F&F/Pilot (OLB) | E21: =VLOOKUP($C21,'Infinity OLB & Mob App'!$C:$L,4,0) -> #N/A | F21: =VLOOKUP($C21,'Infinity OLB & Mob App'!$C:$L,6,0) -> #N/A | G21: =VLOOKUP($C21,'Infinity OLB & Mob App'!$C:$L,7,0) -> #N/A
C22: PROD OLB Launch | E22: =VLOOKUP($C22,'Infinity OLB & Mob App'!$C:$L,4,0) -> 0 | F22: =VLOOKUP($C22,'Infinity OLB & Mob App'!$C:$L,6,0) -> 44646 | G22: =VLOOKUP($C22,'Infinity OLB & Mob App'!$C:$L,7,0) -> 44646
C24: Notes

Sheet Project Readiness
A1: The Display Week in cell E4 represents the starting week to display in the project schedule in cell I4. The project start date is considered Week 1. To change the display week, simply enter a new week number in cell E4. The starting date for each week, starting with the display week from cell E4, starts in cell I4 and is auto calculated. There are 8 weeks represented in this view from cell I4 through cell BF4. You should not modify these cells. Display Week: label is in cell C4. | B1: Kick-off Date: | C1: 44200 | E1: Display Week: | F1: 1 | M1: =M2 -> 44200 | T1: =T2 -> 44207 | AA1: =AA2 -> 44214 | AH1: =AH2 -> 44221 | AO1: =AO2 -> 44228 | AV1: =AV2 -> 44235 | BC1: =BC2 -> 44242 | BJ1: =BJ2 -> 44249
A2: Cells I5 through BL5 contain the day number for the week represented in the cell block above each date cell and are auto calculated. You should not modify these cells. Today's date is outlined in Red (hex #AD3815) from today's date in row 5 through the entire date column to the end of the project schedule. | M2: =Project_Start-WEEKDAY(Project_Start,1)+2+7*(Display_Week-1) -> 44200 | N2: =M2+1 -> 44201 | O2: =N2+1 -> 44202 | P2: =O2+1 -> 44203 | Q2: =P2+1 -> 44204 | R2: =Q2+1 -> 44205 | S2: =R2+1 -> 44206 | T2: =S2+1 -> 44207 | U2: =T2+1 -> 44208 | ... BP2: =BO2+1 -> 44255
A3: JIRA # | B3: TASK | C3: Description | D3: ASSIGNED GROUP | E3: PROGRESS (%) | F3: Duration (Days) | G3: Scheduled START | H3: Scheduled END | I3: Estimated/Actual START | J3: Estimated/Actual END | L3: DAYS | M3: =LEFT(TEXT(M2,"ddd"),1) -> M | N3: =LEFT(TEXT(N2,"ddd"),1) -> T | O3: =LEFT(TEXT(O2,"ddd"),1) -> W | P3: =LEFT(TEXT(P2,"ddd"),1) -> T | Q3: =LEFT(TEXT(Q2,"ddd"),1) -> F | R3: =LEFT(TEXT(R2,"ddd"),1) -> S | S3: =LEFT(TEXT(S2,"ddd"),1) -> S | T3: =LEFT(TEXT(T2,"ddd"),1) -> M | ... BP3: =LEFT(TEXT(BP2,"ddd"),1) -> S
A4: Do not delete this row. This row is hidden to preserve a formula that is used to highlight the curren day within the project schedule. | L4: =IF(OR(ISBLANK(task_start),ISBLANK(task_end)),"",task_end-task_start+1)
A5: Readiness | L5: =IF(OR(ISBLANK(task_start),ISBLANK(task_end)),"",task_end-task_start+1)
B6: Project Plan & Governance | D6: C1/Client | E6: =AVERAGE(E7:E16) -> 0 | F6: =NETWORKDAYS(G6,H6) -> 34 | G6: =MIN(G7:G16) -> 44200 | H6: =MAX(H7:H16) -> 44245
B7: Executive Onboarding - Senior Level | C7: CU onboarding by RM | D7: C1/Client | E7: 0 | F7: 0 | G7: =Project_Start -> 44200 | H7: =WORKDAY(G7,F7) -> 44200 | L7: =IF(OR(ISBLANK(task_start),ISBLANK(task_end)),"",task_end-task_start+1) -> 1
B8: Project Kick Off with Credit Union Project Team | C8: First touchpoint with FIT Team | D8: C1 | E8: 0 | F8: 0 | G8: =Project_Start -> 44200 | H8: =WORKDAY(G8,F8) -> 44200 | L8: =IF(OR(ISBLANK(task_start),ISBLANK(task_end)),"",task_end-task_start+1) -> 1
B9: Follow-up Touchpoint and Setup Weekly Cadence | C9: Second touchpoinit with FIT Team | D9: C1 | E9: 0 | F9: 5 | G9: =H8 -> 44200 | H9: =WORKDAY(G9,F9) -> 44207 | L9: =IF(OR(ISBLANK(task_start),ISBLANK(task_end)),"",task_end-task_start+1) -> 8
B10: Create Gap Analysis | C10: Identify feature gap analysis between MD and Forge | D10: C1 | E10: 0 | F10: 10 | G10: =WORKDAY(H9,1) -> 44208 | H10: =WORKDAY(G10,F10) -> 44222
B11: Gap Analysis: Sign-off | C11: Client signs off on gap analysis | D11: Client | E11: 0 | F11: 0 | G11: =H10 -> 44222 | H11: =WORKDAY(G11,F11) -> 44222
B12: Determine channel strategy (PWS, Mobile and OLB) | C12: Determine the launch order for the channels | D12: C1/Client | E12: 0 | F12: 10 | G12: =WORKDAY(H9,1) -> 44208 | H12: =WORKDAY(G12,F12) -> 44222 | L12: =IF(OR(ISBLANK(task_start),ISBLANK(task_end)),"",task_end-task_start+1) -> 15
B13: Determine Launch Strategies for each Channel | C13: Determine the launch dates for each channel's Beta and Market Launch | D13: C1/Client | E13: 0 | F13: 10 | G13: =WORKDAY(H9,1) -> 44208 | H13: =WORKDAY(G13,F13) -> 44222 | L13: =IF(OR(ISBLANK(task_start),ISBLANK(task_end)),"",task_end-task_start+1) -> 15
B14: Develop Project Plan with Schedule Estimates | C14: Add estimates for duration and dates for all actvities | D14: C1/Client | E14: 0 | F14: 10 | G14: =WORKDAY(H9,1) -> 44208 | H14: =WORKDAY(G14,F14) -> 44222
B15: Project SoW: Draft Development | C15: Develop the draft copy of SoW for review | D15: C1 | E15: 0 | F15: 5 | G15: =MAX(WORKDAY(H13,1),WORKDAY(H12,1),WORKDAY(H11,1),WORKDAY(H14,1)) -> 44223 | H15: =WORKDAY(G15,F15) -> 44230
B16: Project SoW: Sign-off | C16: Client and C1 sign off on SoW | D16: C1/Client | E16: 0 | F16: 10 | G16: =WORKDAY(H15,1) -> 44231 | H16: =WORKDAY(G16,F16) -> 44245
B17: Training | D17: Client | E17: =AVERAGE(E18:E19) -> 0 | F17: =NETWORKDAYS(G17,H17) -> 11 | G17: =MIN(G18:G19) -> 44200 | H17: =MAX(H18:H19) -> 44214
B18: Spark Learning | C18: Complete Training on https://sparklearning.central1.com/ | D18: Client | E18: 0 | F18: 10 | G18: =Project_Start -> 44200 | H18: =WORKDAY(G18,F18) -> 44214
B19: Webinar | C19: Complete viewing the Webinar on https://www.youtube.com/watch?v=X7E96Zkmnxo&feature=youtu.be | D19: C1/Client | E19: 0 | F19: 10 | G19: =Project_Start -> 44200 | H19: =WORKDAY(G19,F19) -> 44214
L20: =IF(OR(ISBLANK(task_start),ISBLANK(task_end)),"",task_end-task_start+1)
B21: Insert new rows ABOVE this one | L21: =IF(OR(ISBLANK(task_start),ISBLANK(task_end)),"",task_end-task_start+1)

Sheet Infinity OLB & Mob App
A1: OLB & Mobile Start Date: | G1: Display Week: | H1: 1 | N1: =N2 -> -5 | U1: =U2 -> 2 | AB1: =AB2 -> 9 | AI1: =AI2 -> 16 | AP1: =AP2 -> 23 | AW1: =AW2 -> 30 | BD1: =BD2 -> 37 | BK1: =BK2 -> 44
N2: =Project_Start-WEEKDAY(Project_Start,1)+2+7*(Display_Week-1) -> -5 | O2: =N2+1 -> -4 | P2: =O2+1 -> -3 | Q2: =P2+1 -> -2 | R2: =Q2+1 -> -1 | S2: =R2+1 -> 0 | T2: =S2+1 -> 1 | U2: =T2+1 -> 2 | V2: =U2+1 -> 3 | ... BQ2: =BP2+1 -> 50
A3: JIRA# | B3: Required/Not Required | C3: TASK | D3: Description | E3: ASSIGNED GROUP | F3: PROGRESS (%) | G3: Duration (Days) | H3: Scheduled START | I3: Scheduled END | J3: Estimated/Actual START | K3: Estimated/Actual END | M3: DAYS | N3: =LEFT(TEXT(N2,"ddd"),1) -> #VALUE! | O3: =LEFT(TEXT(O2,"ddd"),1) -> #VALUE! | P3: =LEFT(TEXT(P2,"ddd"),1) -> #VALUE! | Q3: =LEFT(TEXT(Q2,"ddd"),1) -> #VALUE! | R3: =LEFT(TEXT(R2,"ddd"),1) -> #VALUE! | S3: =LEFT(TEXT(S2,"ddd"),1) -> S | T3: =LEFT(TEXT(T2,"ddd"),1) -> S | U3: =LEFT(TEXT(U2,"ddd"),1) -> M | ... BQ3: =LEFT(TEXT(BQ2,"ddd"),1) -> S
A4: Mobile + OLB | M4: =IF(OR(ISBLANK(task_start),ISBLANK(task_end)),"",task_end-task_start+1)
C5: CU Engaged | M5: =IF(OR(ISBLANK(task_start),ISBLANK(task_end)),"",task_end-task_start+1)
C6: Obtain Implementation Requirement Document | M6: =IF(OR(ISBLANK(task_start),ISBLANK(task_end)),"",task_end-task_start+1)
C7: Initial Config & ISO/API Test
B8: Not Required | C8: Raise request with AzureCloud Hosting for Fabric environment with base Infinity 2020.07 Apps & Campaign MS | D8: Pre-req to start | E8: Temenos
B9: Not Required | C9: Procure Environment with credentials | E9: Temenos
B10: Not Required | C10: Cloud Flare (prod) - provided initial cert info - secure domain (completed) - cert to follow | E10: CWB
B11: Not Required | C11: Production Site URL, app names and version numbers (iOS & Android) - Production Checklist | E11: CWB (Mark)
B12: Not Required | C12: Whitelist Temenos public IP Address to CWB environment - MuleSoft, SMTP, Migration Database | E12: CWB
B13: Not Required | C13: Twilio Credentials from CWB for SMS alerts | E13: CWB(Mark/DTS)
B14: Not Required | C14: SMTP credentials for Email messaging | E14: CWB (Braydon)
B15: Not Required | C15: SSL Certificate for Production domain | E15: CWB
B16: Not Required | C16: Base URL and credentials for Mule endpoints | E16: CWB (Brad)
B17: Not Required | C17: Okta credentials for authentication | E17: Okta (Tony, Rajiv)
B18: Not Required | C18: Provide Redirect URIs for OLB and MB | E18: Temenos
B19: Not Required | C19: Configure the Redirect URIs in Okta | E19: CWB & Okta (Tony)
B20: Not Required | C20: Public keys for the Password Encryption | E20: CWB (Brad)
... B38: Not Required | C38: Configure Fabric server and client properties | E38: Temenos
B39: Required | C39: Dashboard - Connection MicroService deployment | E39: Temenos | H39: 44496 | I39: 44616
B40: Required | C40: Dashboard - Fabric configuration for the Consent API URL and auth details | E40: Temenos | H40: 44496 | I40: 44616
B41: Required | C41: Dashboard - Fabric XAI URLs and auth details | E41: Temenos | H41: 44496 | I41: 44616
B42: Required | C42: Dashboard - Fabric Codat URLs and auth details | E42: Temenos | H42: 44496 | I42: 44616
B43: Required | C43: Dashboard - Consent Timeout environment variable in Fabric | E43: Temenos | H43: 44496 | I43: 44616
B44: Required | C44: OLB & MB - Okta Config update to enable Additional Options like forgot pwd , unlock account in OKTA hosted site | E44: Okta (Tony, Rajiv) | F44: 1 | I44: 44512
B45: Required | C45: Spotlight - Provide authorise URL, signout URL, issuer ID, scope, clientID & secretKey | E45: Okta (Tony, Rajiv) | F45: 1 | I45: 44512
B46: Required | C46: Spotlight - Provide call back URL | E46: Temenos | H46: 44496 | I46: 44512
B47: Required | C47: Spotlight - Configure OKTA SSO - authorise URL, signout URL, issuer ID, scope, callback URL, Client-ID & SecretKey | E47: Okta (Tony, Rajiv) | F47: 1 | I47: 44512
B48: Required | C48: Spotlight - Add admin/default user in Okta | E48: Okta (Tony, Rajiv) | F48: 1 | I48: 44512
B49: Required | C49: Upload cwbServices.jar before doing integration changes(includes processor changes) | E49: Temenos
B50: Required | C50: CONSENT_MICROSERVICE_URL, CONSENT_CODAT_URL, CONSENT_ANALYTICS_URL | E50: Temenos
B51: Required | C51: BRIM - ENCRYPTION PRIVATEKEY for Card linking | E51: CWB (Roney) | F51: 1 | I51: 44512
B52: Required | C52: Temenos - ENCRYPTION PUBLICKEY for Card linking | E52: CWB (Roney) | F52: 1 | I52: 44512
B53: Required | C53: BRIM - External URL to apply for new CWB Master Card | E53: BRIM (Fayez) | I53: 44512
B54: Required | C54: BRIM - SSO LINK | E54: BRIM (Fayez) | I54: 44512
B55: Required | C55: BRIM - Test Cards | E55: BRIM (Fayez) | I55: 44512
B56: Required | C56: Mule Deployment in Production for R1.1 | E56: CWB | I56: 44512
B57: Required | C57: Backend API Testing and Smoke Test in the Prod environment | E57: Temenos | I57: 44646
...

Sheet CWB Deployment Plan
A1: CWB Start Date: | C1: 44362 | F1: Display Week: | G1: 1 | M1: =M2 -> 44361 | T1: =T2 -> 44368 | AA1: =AA2 -> 44375 | AH1: =AH2 -> 44382 | AO1: =AO2 -> 44389 | AV1: =AV2 -> 44396 | BC1: =BC2 -> 44403 | BJ1: =BJ2 -> 44410 | BQ1: =BQ2 -> 44417 | BX1: =BX2 -> 44424 | CE1: =CE2 -> 44431 | CL1: =CL2 -> 44438 | CS1: =CS2 -> 44445
M2: =Project_Start-WEEKDAY(Project_Start,1)+2+7*(Display_Week-1) -> 44361 | N2: =M2+1 -> 44362 | O2: =N2+1 -> 44363 | P2: =O2+1 -> 44364 | Q2: =P2+1 -> 44365 | R2: =Q2+1 -> 44366 | S2: =R2+1 -> 44367 | T2: =S2+1 -> 44368 | U2: =T2+1 -> 44369 | ... CY2: =CX2+1 -> 44451
A3: JIRA# | B3: TASK | C3: Description | D3: ASSIGNED GROUP | E3: PROGRESS (%) | F3: Duration (Days) | G3: Scheduled START | H3: Scheduled END | I3: Estimated/Actual START | J3: Estimated/Actual END | L3: DAYS | M3: =LEFT(TEXT(M2,"ddd"),1) -> M | N3: =LEFT(TEXT(N2,"ddd"),1) -> T | O3: =LEFT(TEXT(O2,"ddd"),1) -> W | P3: =LEFT(TEXT(P2,"ddd"),1) -> T | Q3: =LEFT(TEXT(Q2,"ddd"),1) -> F | R3: =LEFT(TEXT(R2,"ddd"),1) -> S | S3: =LEFT(TEXT(S2,"ddd"),1) -> S | T3: =LEFT(TEXT(T2,"ddd"),1) -> M | ... CY3: =LEFT(TEXT(CY2,"ddd"),1) -> S
A4: Pre-Production - All tasks that can be completed prior to go-live weekend | L4: =IF(OR(ISBLANK(task_start),ISBLANK(task_end)),"",task_end-task_start+1)
B5: T24 | E5: =AVERAGE(E6:E94) -> 0.93103448
B6: T24 R1 deployment analysis and package deployment list | D6: Charlotte | E6: 1 | F6: 0 | G6: 44362 | H6: =WORKDAY(G6,F6) -> 44362
B7: Analyze required changes and time estimate for T24 Infinity container for web services | D7: Braydon | E7: 1 | F7: 0 | G7: 44364 | H7: =WORKDAY(G7,F7) -> 44364
B8: Complete release management analysis | D8: Charlotte | E8: 1 | F8: 0 | G8: 44364 | H8: =WORKDAY(G8,F8) -> 44364
B9: Deploy R1 to operational SIT1 env | D9: RM Team | E9: 1 | F9: 0 | G9: 44364 | H9: =WORKDAY(G9,F9) -> 44364
B10: Test Digital T24 changes in SIT1 | D10: QA Team | E10: 1 | F10: 12 | G10: 44364 | H10: =WORKDAY(G10,F10) -> 44382
B11: Config / complete T24 Infinity container in SIT1 | D11: Braydon | E11: 1 | F11: 0 | G11: 44364 | H11: =WORKDAY(G11,F11) -> 44364
B12: Config / complete T24 Infinity container in SIT2 | D12: Braydon | E12: 1 | F12: 0 | G12: 44389 | H12: =WORKDAY(G12,F12) -> 44389
B13: Deploy R1 to operational SIT2 env | D13: RM Team | E13: 1 | F13: 0 | G13: 44389 | H13: =WORKDAY(G13,F13) -> 44389
B14: Regression test T24 in SIT2 | D14: QA Team | E14: 1 | F14: 3 | G14: 44389 | H14: =WORKDAY(G14,F14) -> 44392
B15: Determine go/no-go for T24 R1 into production | D15: CAS Team, QA Team | E15: 1 | F15: 0 | G15: 44391 | H15: =WORKDAY(G15,F15) -> 44391
B16: Determine go/no-go for T24 Infinity container as a part of the release | D16: RM Team / Braydon | E16: 1 | F16: 0 | G16: 44391 | H16: =WORKDAY(G16,F16) -> 44391
B17: Deploy T24 R1 into production | D17: RM Team / Braydon | E17: 1 | F17: 0 | G17: 44395 | H17: =WORKDAY(G17,F17) -> 44395
B18: Deploy T24 Infinity container | D18: Braydon | E18: 1 | F18: 0 | G18: 44395 | H18: =WORKDAY(G18,F18) -> 44395
B19: Data Migration
B20: Confirm signoff for CR submittance. | D20: Dapo / Braydon | E20: 1 | F20: 0 | G20: 44390 | H20: =WORKDAY(G20,F20) -> 44390
B21: Submit CR for production change Includes: all config required for SFTP, the production DM database, as well as the private VPN between Temenos and CWB to provide read access to the required tables in the DB database | D21: Dapo | E21: 1 | F21: 0 | G21: 44399 | H21: =WORKDAY(G21,F21) -> 44399
B22: Perform smoke test of setup | D22: Dapo | E22: 1 | F22: 0 | G22: 44400 | H22: =WORKDAY(G22,F22) -> 44400
B23: Perform smoke test of VPN setup Dependency: This will require Temenos Infinity to be up and running. | D23: Temenos | E23: 0 | F23: 2 | G23: 44426 | H23: =WORKDAY(G23,F23) -> 44428
B24: Deploy final DM process code to production | D24: Dapo / Braydon | E24: 0 | F24: 0 | G24: 44426 | H24: =WORKDAY(G24,F24) -> 44426
B25: Celero
B26: VPN Setup | D26: Mark D / Brad | E26: 1 | F26: 0 | G26: 44390 | H26: =WORKDAY(G26,F26) -> 44390
B27: Confirm build by Celero for prod | D27: Mark D | E27: 1 | F27: 0 | G27: 44393 | H27: =WORKDAY(G27,F27) -> 44393
B28: Mark to review with Brad regarding Celero and testing pre-prod using PostMan | D28: Mark D / Brad | F28: 1 | G28: 44413 | H28: =WORKDAY(G28,F28) -> 44414
B29: Config update for estatements and cheque images | D29: Mark D | F29: 0 | G29: 44413 | H29: =WORKDAY(G29,F29) -> 44413
B30: Central1
B31: Meeting with C1 on timing of sign-off and go-ahead plan | D31: Mark D | E31: 1 | F31: 0 | G31: 44392 | H31: =WORKDAY(G31,F31) -> 44392
B32: Confirm build by Celero for prod | D32: Mark D | E32: 1 | F32: 0 | G32: 44393 | H32: =WORKDAY(G32,F32) -> 44393
B33: Mark to review with Brad regarding Celero and testing pre-prod using PostMan | D33: Mark D / Brad | F33: 1 | G33: 44413 | H33: =WORKDAY(G33,F33) -> 44414
B34: Config update for estatements and cheque images | D34: Mark D | F34: 0 | G34: 44413 | H34: =WORKDAY(G34,F34) -> 44413
B35: Submit CR for production change - Latest this can be submitted is 26-Aug. | D35: Mark D | F35: 0 | G35: 44434 | H35: =WORKDAY(G35,F35) -> 44434
B36: Config update for estatements and cheque images - Smoke test C1 connectivity. | D36: Mark D | F36: 0 | G36: 44435 | H36: =WORKDAY(G36,F36) -> 44435
B37: Okta
B38: Confirm tasks with Tony regarding outstanding actions for pre-prod/prod | D38: CWB | F38: 0 | G38: 44413 | H38: =WORKDAY(G38,F38) -> 44413
B39: [Okta task] - flush out with Tony Fang | F39: 0 | G39: 44413 | H39: =WORKDAY(G39,F39) -> 44413
B40: Add groups (Infinity Users, Infinity Users - Suspended) | D40: Tony | E40: 1
...

Sheet Sheet2
A1: 1 | B1: CU Engaged | D1: OPEN | E1: Unassigned | F1: Actions | I1: https://jira.central1.com/browse/FIT-1001 | J1: FIT-1001
A2: 2 | B2: Obtain Implementation Requirement Document | D2: OPEN | E2: Unassigned | F2: Actions | I2: https://jira.central1.com/browse/FIT-1835 | J2: FIT-1835
A3: 3 | B3: =======ONBOARDING FOR MOBILE OR OLB======= | D3: OPEN | E3: Unassigned | F3: Actions | I3: https://jira.central1.com/browse/FIT-10262 | J3: IT-10262
A4: 4 | B4: CU making BH changes (Mobile and OLB) | D4: OPEN | E4: Unassigned | F4: Actions | I4: https://jira.central1.com/browse/FIT-1003 | J4: FIT-1003
A5: 5 | B5: Setup BH Connectivity (Mobile and OLB) | D5: OPEN | E5: Unassigned | F5: Actions | I5: https://jira.central1.com/browse/FIT-1005 | J5: FIT-1005
A6: 6 | B6: Import latest MD properties (Mobile and OLB) | D6: OPEN | E6: Unassigned | F6: Actions | I6: https://jira.central1.com/browse/FIT-1800 | J6: FIT-1800
A7: 7 | B7: ISO testing in local Dev (Mobile and OLB) | D7: OPEN | E7: Unassigned | F7: Actions | I7: https://jira.central1.com/browse/FIT-1164 | J7: FIT-1164
A8: 8 | B8: Setup Client JIRA Project and Access (Mobile and OLB) | D8: OPEN | E8: Unassigned | F8: Actions | I8: https://jira.central1.com/browse/FIT-1320 | J8: FIT-1320
A9: 9 | B9: Obtain SSL Certificate for auth and forge subdomains (Mobile and OLB) | D9: OPEN | E9: Unassigned | F9: Actions | I9: https://jira.central1.com/browse/FIT-7939 | J9: FIT-7939
A10: 10 | B10: Add ID Mapper | D10: OPEN | E10: Christina Chan | F10: Actions | I10: https://jira.central1.com/browse/FIT-14954 | J10: IT-14954
A11: 11 | B11: Create DB & Tenant for DTAP (Mobile and OLB) | D11: OPEN | E11: Unassigned | F11: Actions | I11: https://jira.central1.com/browse/FIT-1010 | J11: FIT-1010
A12: 12 | B12: Create AWS Role for CU (Mobile and OLB) | D12: OPEN | E12: Unassigned | F12: Actions | I12: https://jira.central1.com/browse/FIT-1801 | J12: FIT-1801
... A103: 103 | B103: FULL LAUNCH - Day before Full Launch Preparation (PWS) | D103: OPEN | E103: Unassigned | F103: Actions | I103: https://jira.central1.com/browse/FIT-10367 | J103: FIT-10367
A104: 104 | B104: Member Full Launch!! (PWS) | D104: OPEN | E104: Unassigned | I104: https://jira.central1.com/browse/FIT-10368 | J104: FIT-10368

Sheet OLB & Mob App (OLD)
A1: Create a Project Schedule in this worksheet. Enter title of this project in cell B1. Information about how to use this worksheet, including instructions for screen readers and the author of this workbook is in the About worksheet. Continue navigating down column A to hear further instructions. | B1: Conexus Forge Implementation | E1: All Products | G1: PWS | H1: OLB | I1: Mobile
A2: Enter Company Name in cell B2. | B2: Conexus
A3: Enter the name of the Project Lead in cell B3. Enter the Project Start date in cell E3. Pooject Start: label is in cell C3. | E3: Project Start: | H3: 43831
A4: The Display Week in cell E4 represents the starting week to display in the project schedule in cell I4. The project start date is considered Week 1. To change the display week, simply enter a new week number in cell E4. The starting date for each week, starting with the display week from cell E4, starts in cell I4 and is auto calculated. There are 8 weeks represented in this view from cell I4 through cell BF4. You should not modify these cells. Display Week: label is in cell C4. | E4: Display Week: | H4: 1 | N4: =N5 -> 43829 | U4: =U5 -> 43836 | AB4: =AB5 -> 43843 | AI4: =AI5 -> 43850 | AP4: =AP5 -> 43857 | AW4: =AW5 -> 43864 | BD4: =BD5 -> 43871 | BK4: =BK5 -> 43878
A5: Cells I5 through BL5 contain the day number for the week represented in the cell block above each date cell and are auto calculated. You should not modify these cells. Today's date is outlined in Red (hex #AD3815) from today's date in row 5 through the entire date column to the end of the project schedule. | N5: =Project_Start-WEEKDAY(Project_Start,1)+2+7*(Display_Week-1) -> 43829 | O5: =N5+1 -> 43830 | P5: =O5+1 -> 43831 | Q5: =P5+1 -> 43832 | R5: =Q5+1 -> 43833 | S5: =R5+1 -> 43834 | T5: =S5+1 -> 43835 | U5: =T5+1 -> 43836 | V5: =U5+1 -> 43837 | ... BQ5: =BP5+1 -> 43884
A6: Task ID | B6: TASK | C6: Description | D6: Product | E6: ASSIGNED GROUP | F6: Duration (Days) | G6: PROGRESS | H6: Scheduled START | I6: Scheduled END | J6: Estimated/Actual START | K6: Estimated/Actual END | M6: DAYS | N6: =LEFT(TEXT(N5,"ddd"),1) -> M | O6: =LEFT(TEXT(O5,"ddd"),1) -> T | P6: =LEFT(TEXT(P5,"ddd"),1) -> W | Q6: =LEFT(TEXT(Q5,"ddd"),1) -> T | R6: =LEFT(TEXT(R5,"ddd"),1) -> F | S6: =LEFT(TEXT(S5,"ddd"),1) -> S | T6: =LEFT(TEXT(T5,"ddd"),1) -> S | U6: =LEFT(TEXT(U5,"ddd"),1) -> M | ... BQ6: =LEFT(TEXT(BQ5,"ddd"),1) -> S
A7: Do not delete this row. This row is hidden to preserve a formula that is used to highlight the curren day within the project schedule. | M7: =IF(OR(ISBLANK(task_start),ISBLANK(task_end)),"",task_end-task_start+1)
B8: Readiness | M8: =IF(OR(ISBLANK(task_start),ISBLANK(task_end)),"",task_end-task_start+1)
A9: R01 | B9: Executive Onboarding - Senior Level | C9: CU onboarding by RM | D9: All | E9: C1/Client | F9: 1 | M9: =IF(OR(ISBLANK(task_start),ISBLANK(task_end)),"",task_end-task_start+1)
A10: R02 | B10: Project Kick Off with Credit Union Project Team | C10: First touchpoint with FIT Team | D10: All | E10: C1 | F10: 1 | M10: =IF(OR(ISBLANK(task_start),ISBLANK(task_end)),"",task_end-task_start+1)
A11: R03 | B11: Follow-up Touchpoint and Setup Weekly Cadence | C11: Second touchpoinit with FIT Team | D11: All | E11: C1 | F11: 1 | M11: =IF(OR(ISBLANK(task_start),ISBLANK(task_end)),"",task_end-task_start+1)
A12: R04 | B12: Determine channel strategy (PWS, Mobile and OLB) and MD sunset timelines | C12: Determine the launch order for the channels and timeline to retire MD | D12: All | E12: C1/Client | F12: 5 | M12: =IF(OR(ISBLANK(task_start),ISBLANK(task_end)),"",task_end-task_start+1)
A13: R05 | B13: Determine Launch Strategies for each Channel | C13: Determine the launch dates for each channel's Beta and Market Launch | D13: All | E13: C1/Client | F13: 5 | M13: =IF(OR(ISBLANK(task_start),ISBLANK(task_end)),"",task_end-task_start+1)
A14: R06 | B14: Project SoW: Draft Development | C14: Develop the draft copy of SoW for review | D14: All | E14: C1 | F14: 5
A15: R07 | B15: Project SoW: Sign-off | C15: Client and C1 sign off on SoW | D15: All | E15: Client/C1 | F15: 60
A16: R08 | B16: Banking Host & Data Seeding Discovery Session | C16: Q & A for Pre-seeding Tests and Data Seeding | D16: All | E16: C1/Client | F16: 1
A17: R09 | B17: Develop Project Plan with Schedule Estimates | C17: Add estimates for duration and dates for all actvities | D17: All | E17: C1/Client | F17: 5
A18: R10 | B18: Provide Credit Union branding and style guide by C1 | C18: Provide all design documents | D18: All | E18: Client | F18: 10
B19: Training
A20: T01 | B20: Spark Learning | C20: Complete Training on https://sparklearning.central1.com/ | D20: All | E20: Client | F20: 10
A21: T02 | B21: Backbase | C21: Complete Trainng on https://central1.learnupon.com/users/sign_in | D21: All | E21: Client | F21: 5
A22: T03 | B22: Webinar | C22: Complete viewing the Webinar (link) to be added | D22: All | E22: C1/Client | F22: 1
B23: Applepay Pre-Requisites
A24: AP01 | B24: Implement Strong PAC | C24: Implement Strong PAC for Forge | D24: Mobile | E24: C1
A25: AP02 | B25: Implement 2SV | C25: Implement 2SV (2 factor authentication) for Forge | D25: Mobile | E25: C1
A26: AP03 | B26: Implement Increased Auth (RSA) | C26: Implement Increased Auth for Forge | D26: Mobile | E26: C1 | F26: 0.2
A27: AP04 | B27: Implement Oauth | C27: Implement Oauth for Forge | D27: Mobile | E27: C1 | F27: 0.2 to 10
A28: AP05 | B28: Whitelist on C1's Firewall | C28: Client to be whitelisted on C1's Firewall for access to Interac's Customer Service Portal | D28: Mobile | E28: C1 | F28: 5
A29: AP06 | B29: Provide SOW and Signoff | C29: Applepay specific SOW for Forge | D29: Mobile | E29: C1 | F29: 10
A30: AP07 | B30: Provide Mobile Pay Addendum and Signoff | C30: Applepay specific Mobile Pay Addendum for Forge | D30: Mobile | E30: C1 | F30: 5
A31: AP08 | B31: FI onboarding Requirements with CCUA | C31: FI to engage with CCUA; 2 tickets to be created to C1 (1 from CCUA, 1 from FI) | D31: Mobile | E31: Client/CCUA
B32: Applepay Info Collection
A33: AP09 | B33: Check CCUA Ticket for Required Info | C33: Launch schedule; FI BIN range | D33: Mobile | E33: C1 | F33: 0.1
A34: AP10 | B34: Create Dev Ops Ticket for Key / Meta-Data | C34: Provide Team ID, Adam ID, TeamID.Bundle ID, URL for app launch | D34: Mobile | E34: C1 | F34: 0.1
A35: AP11 | B35: Notify CCUA Key Exchange in Progress | C35: Email CCUA of key exchange is in progress | D35: Mobile | E35: C1 | F35: 0.1
A36: AP12 | B36: Provide CCUA with Key / Meta-Data | C36: Provide CCUA with the Team ID, Adam ID, TeamID.Bundle, and the URL for the Mobile application launch | D36: Mobile | E36: C1 | F36: 0.1
A37: AP13 | B37: Interac Confirms Key Successfully Uploaded to TSP | C37: Email Interac for confirmation they are in receipt of key and uploaded to their internal system TSP | D37: Mobile | E37: Interac | F37: 2
A38: AP14 | B38: Apple confirms Entitlement Config is done | C38: This step is a must, prior to building the app | D38: Mobile | E38: Apple | F38: 10
A39: AP15 | B39: Update Dev Ops Ticket | C39: Give go-ahead to Dev Ops to enable Applepay | D39: Mobile | E39: C1 | F39: 0.1
B40: Configuration & Testing
...
