Workbook
Name Custom: Table6[Custom]
Name Development: Table4[Development Category]
Name Effort: Table6[Custom]
Name NoDev: Table7[Product]
Name Product: Table7[Product]

Sheet Summary
A1: <Client> | B1: Readiness: | C1: =IFERROR((D1/SUM(D1:F1))*100,-1) -> -1 | D1: =SUM(D4:D11) -> #REF! | E1: =SUM(E4:E11) -> #REF! | F1: =SUM(F4:F11) -> #REF! | G1: =SUM(G4:G11) -> #REF!
A3: # | B3: Module | C3: Status | D3: 3 | E3: 2 | F3: 1 | G3: 0
A4: 1 | B4: RB User Management | C4: =IFERROR((D4/SUM(D4:F4))*100,-1) -> -1 | D4: =COUNTIFS('Retail Banking'!#REF!,"=" & $A4,'Retail Banking'!#REF!,">2") -> #REF! | E4: =COUNTIFS('Retail Banking'!#REF!,"=" & $A4,'Retail Banking'!#REF!,"=2") -> #REF! | F4: =COUNTIFS('Retail Banking'!#REF!,"=" & $A4,'Retail Banking'!#REF!,"=1") -> #REF! | G4: =COUNTIFS('Retail Banking'!#REF!,"=" & $A4,'Retail Banking'!#REF!,"=0") -> #REF!
A5: 2 | B5: RB Account Management | C5: =IFERROR((D5/SUM(D5:F5))*100,-1) -> -1 | D5: =COUNTIFS('Retail Banking'!#REF!,"=" & $A5,'Retail Banking'!#REF!,">2") -> #REF! | E5: =COUNTIFS('Retail Banking'!#REF!,"=" & $A5,'Retail Banking'!#REF!,"=2") -> #REF! | F5: =COUNTIFS('Retail Banking'!#REF!,"=" & $A5,'Retail Banking'!#REF!,"=1") -> #REF! | G5: =COUNTIFS('Retail Banking'!#REF!,"=" & $A5,'Retail Banking'!#REF!,"=0") -> #REF!
A6: 3 | B6: RB Money Management | C6: =IFERROR((D6/SUM(D6:F6))*100,-1) -> -1 | D6: =COUNTIFS('Retail Banking'!#REF!,"=" & $A6,'Retail Banking'!#REF!,">2") -> #REF! | E6: =COUNTIFS('Retail Banking'!#REF!,"=" & $A6,'Retail Banking'!#REF!,"=2") -> #REF! | F6: =COUNTIFS('Retail Banking'!#REF!,"=" & $A6,'Retail Banking'!#REF!,"=1") -> #REF! | G6: =COUNTIFS('Retail Banking'!#REF!,"=" & $A6,'Retail Banking'!#REF!,"=0") -> #REF!
A7: 4 | B7: RB New User Onboarding | C7: =IFERROR((D7/SUM(D7:F7))*100,-1) -> -1 | D7: =COUNTIFS('Retail Banking'!#REF!,"=" & $A7,'Retail Banking'!#REF!,">2") -> #REF! | E7: =COUNTIFS('Retail Banking'!#REF!,"=" & $A7,'Retail Banking'!#REF!,"=2") -> #REF! | F7: =COUNTIFS('Retail Banking'!#REF!,"=" & $A7,'Retail Banking'!#REF!,"=1") -> #REF! | G7: =COUNTIFS('Retail Banking'!#REF!,"=" & $A7,'Retail Banking'!#REF!,"=0") -> #REF!
A8: 5 | B8: RB Administration | C8: =IFERROR((D8/SUM(D8:F8))*100,-1) -> -1 | D8: =COUNTIFS('Retail Banking'!#REF!,"=" & $A8,'Retail Banking'!#REF!,">2") -> #REF! | E8: =COUNTIFS('Retail Banking'!#REF!,"=" & $A8,'Retail Banking'!#REF!,"=2") -> #REF! | F8: =COUNTIFS('Retail Banking'!#REF!,"=" & $A8,'Retail Banking'!#REF!,"=1") -> #REF! | G8: =COUNTIFS('Retail Banking'!#REF!,"=" & $A8,'Retail Banking'!#REF!,"=0") -> #REF!
A9: 9 | B9: RB Custom | C9: =IFERROR((D9/SUM(D9:F9))*100,-1) -> -1 | D9: =COUNTIFS('Retail Banking'!#REF!,"=" & $A9,'Retail Banking'!#REF!,">2") -> #REF! | E9: =COUNTIFS('Retail Banking'!#REF!,"=" & $A9,'Retail Banking'!#REF!,"=2") -> #REF! | F9: =COUNTIFS('Retail Banking'!#REF!,"=" & $A9,'Retail Banking'!#REF!,"=1") -> #REF! | G9: =COUNTIFS('Retail Banking'!#REF!,"=" & $A9,'Retail Banking'!#REF!,"=0") -> #REF!
A11: 21 | B11: BB User Management | C11: =IFERROR((D11/SUM(D11:F11))*100,-1) -> -1 | D11: =COUNTIFS('Business Banking'!$A$2:$A$200,"=" & $A11,'Business Banking'!#REF!,">2") -> #REF! | E11: =COUNTIFS('Business Banking'!$A$2:$A$200,"=" & $A11,'Business Banking'!#REF!,"=2") -> #REF! | F11: =COUNTIFS('Business Banking'!$A$2:$A$200,"=" & $A11,'Business Banking'!#REF!,"=1") -> #REF! | G11: =COUNTIFS('Business Banking'!$A$2:$A$200,"=" & $A11,'Business Banking'!#REF!,"=0") -> #REF!
A12: 22 | B12: BB Account Management | C12: =IFERROR((D12/SUM(D12:F12))*100,-1) -> -1 | D12: =COUNTIFS('Business Banking'!$A$2:$A$200,"=" & $A12,'Business Banking'!#REF!,">2") -> #REF! | E12: =COUNTIFS('Business Banking'!$A$2:$A$200,"=" & $A12,'Business Banking'!#REF!,"=2") -> #REF! | F12: =COUNTIFS('Business Banking'!$A$2:$A$200,"=" & $A12,'Business Banking'!#REF!,"=1") -> #REF! | G12: =COUNTIFS('Business Banking'!$A$2:$A$200,"=" & $A12,'Business Banking'!#REF!,"=0") -> #REF!
A13: 23 | B13: BB Money Management | C13: =IFERROR((D13/SUM(D13:F13))*100,-1) -> -1 | D13: =COUNTIFS('Business Banking'!$A$2:$A$200,"=" & $A13,'Business Banking'!#REF!,">2") -> #REF! | E13: =COUNTIFS('Business Banking'!$A$2:$A$200,"=" & $A13,'Business Banking'!#REF!,"=2") -> #REF! | F13: =COUNTIFS('Business Banking'!$A$2:$A$200,"=" & $A13,'Business Banking'!#REF!,"=1") -> #REF! | G13: =COUNTIFS('Business Banking'!$A$2:$A$200,"=" & $A13,'Business Banking'!#REF!,"=0") -> #REF!
A14: 24 | B14: BB New Organization Onboarding | C14: =IFERROR((D14/SUM(D14:F14))*100,-1) -> -1 | D14: =COUNTIFS('Business Banking'!$A$2:$A$200,"=" & $A14,'Business Banking'!#REF!,">2") -> #REF! | E14: =COUNTIFS('Business Banking'!$A$2:$A$200,"=" & $A14,'Business Banking'!#REF!,"=2") -> #REF! | F14: =COUNTIFS('Business Banking'!$A$2:$A$200,"=" & $A14,'Business Banking'!#REF!,"=1") -> #REF! | G14: =COUNTIFS('Business Banking'!$A$2:$A$200,"=" & $A14,'Business Banking'!#REF!,"=0") -> #REF!
A15: 25 | B15: BB User Management | C15: =IFERROR((D15/SUM(D15:F15))*100,-1) -> -1 | D15: =COUNTIFS('Business Banking'!$A$2:$A$200,"=" & $A15,'Business Banking'!#REF!,">2") -> #REF! | E15: =COUNTIFS('Business Banking'!$A$2:$A$200,"=" & $A15,'Business Banking'!#REF!,"=2") -> #REF! | F15: =COUNTIFS('Business Banking'!$A$2:$A$200,"=" & $A15,'Business Banking'!#REF!,"=1") -> #REF! | G15: =COUNTIFS('Business Banking'!$A$2:$A$200,"=" & $A15,'Business Banking'!#REF!,"=0") -> #REF!
A16: 29 | B16: BB Custom | C16: =IFERROR((D16/SUM(D16:F16))*100,-1) -> -1 | D16: =COUNTIFS('Business Banking'!$A$2:$A$216,"=" & $A16,'Business Banking'!#REF!,">2") -> #REF! | E16: =COUNTIFS('Business Banking'!$A$2:$A$216,"=" & $A16,'Business Banking'!#REF!,"=2") -> #REF! | F16: =COUNTIFS('Business Banking'!$A$2:$A$216,"=" & $A16,'Business Banking'!#REF!,"=1") -> #REF! | G16: =COUNTIFS('Business Banking'!$A$2:$A$216,"=" & $A16,'Business Banking'!#REF!,"=0") -> #REF!
A18: 31 | B18: C360 User Management | C18: =IFERROR((D18/SUM(D18:F18))*100,-1) -> -1 | D18: =COUNTIFS('Customer 360'!$A$2:$A$230,"=" & $A18,'Customer 360'!$G$2:$G$230,">2") -> 0 | E18: =COUNTIFS('Customer 360'!$A$2:$A$230,"=" & $A18,'Customer 360'!$G$2:$G$230,"=2") -> 0 | F18: =COUNTIFS('Customer 360'!$A$2:$A$230,"=" & $A18,'Customer 360'!$G$2:$G$230,"=1") -> 0 | G18: =COUNTIFS('Customer 360'!$A$2:$A$230,"=" & $A18,'Customer 360'!$G$2:$G$230,"=0") -> 21
A19: 32 | B19: C360 Account Management | C19: =IFERROR((D19/SUM(D19:F19))*100,-1) -> -1 | D19: =COUNTIFS('Customer 360'!$A$2:$A$230,"=" & $A19,'Customer 360'!$G$2:$G$230,">2") -> 0 | E19: =COUNTIFS('Customer 360'!$A$2:$A$230,"=" & $A19,'Customer 360'!$G$2:$G$230,"=2") -> 0 | F19: =COUNTIFS('Customer 360'!$A$2:$A$230,"=" & $A19,'Customer 360'!$G$2:$G$230,"=1") -> 0 | G19: =COUNTIFS('Customer 360'!$A$2:$A$230,"=" & $A19,'Customer 360'!$G$2:$G$230,"=0") -> 6
A20: 35 | B20: C360 User Management | C20: =IFERROR((D20/SUM(D20:F20))*100,-1) -> -1 | D20: =COUNTIFS('Customer 360'!$A$2:$A$230,"=" & $A20,'Customer 360'!$G$2:$G$230,">2") -> 0 | E20: =COUNTIFS('Customer 360'!$A$2:$A$230,"=" & $A20,'Customer 360'!$G$2:$G$230,"=2") -> 0 | F20: =COUNTIFS('Customer 360'!$A$2:$A$230,"=" & $A20,'Customer 360'!$G$2:$G$230,"=1") -> 0 | G20: =COUNTIFS('Customer 360'!$A$2:$A$230,"=" & $A20,'Customer 360'!$G$2:$G$230,"=0") -> 28
A21: 39 | B21: C360 Custom | C21: =IFERROR((D21/SUM(D21:F21))*100,-1) -> -1 | D21: =COUNTIFS('Customer 360'!$A$2:$A$230,"=" & $A21,'Customer 360'!$G$2:$G$230,">2") -> 0 | E21: =COUNTIFS('Customer 360'!$A$2:$A$230,"=" & $A21,'Customer 360'!$G$2:$G$230,"=2") -> 0 | F21: =COUNTIFS('Customer 360'!$A$2:$A$230,"=" & $A21,'Customer 360'!$G$2:$G$230,"=1") -> 0 | G21: =COUNTIFS('Customer 360'!$A$2:$A$230,"=" & $A21,'Customer 360'!$G$2:$G$230,"=0") -> 1

Sheet Kony RB - Services Detail
B2: Kony RB + Custom Enhancements Integration Services Parameters:
B3: Requirement Category | C3: Integration Service | D3: Input / Output | E3: Parameter | F3: Description
B4: Product | C4: getAccountCashFlowDetails | D4: Inputs | E4: - | F4: -
B5: Product | C5: getAccountCashFlowDetails | D5: Outputs | E5: AccountCashFlow | F5: Cash flow array with one or more record
B6: Product | C6: getAccountCashFlowDetails | D6: Outputs | E6: month | F6: Month. For example, Jan, Feb, Mar
B7: Product | C7: getAccountCashFlowDetails | D7: Outputs | E7: monthCash | F7: Amount spent for that month
B8: Product | C8: getAccountCashFlowDetails | D8: Outputs | E8: monthCredit | F8: Credit amount for that month
B9: Product | C9: getAccountCashFlowDetails | D9: Outputs | E9: totalCash | F9: Total cash
B10: Product | C10: getAccountCashFlowDetails | D10: Outputs | E10: totalCreditDebt | F10: Total credit debt
B11: Product | C11: getAccounts | D11: Inputs | E11: accountID | F11: It is an optional URL input parameter. If it is not added, then service should return all the accounts of the user
B12: Product | C12: getAccounts | D12: Inputs | E12: deviceID | F12: Device ID
B13: Product | C13: getAccounts | D13: Inputs | E13: User name | F13: User name
B14: Product | C14: getAccounts | D14: Outputs | E14: ccounts | F14: Array of accounts related to the logged in user
... B369: Product | C369: getCheckOrders | D369: Outputs | E369: zipcode | F369: Delivery address – Zip code
B370: Product | C370: getCheckOrders | D370: Outputs | E370: name
B371: Product | C371: createCheckOrder | D371: Inputs | E371: accountID | F371: ID of the account
B372: Product | C372: createCheckOrder | D372: Inputs | E372: leafCount | F372: Leaf count of the Check Book.
B373: Product | C373: createCheckOrder | D373: Inputs | E373: country | F373: Reason that is entered by the customer while performing the action
B374: Product | C374: createCheckOrder | D374: Inputs | E374: name | F374: Name of the delivery address
B375: Product | C375: createCheckOrder | D375: Inputs | E375: postboxNumber | F375: Post box number of the delivery address
B376: Product | C376: createCheckOrder | D376: Inputs | E376: state | F376: State name of the delivery address
B377: Product | C377: createCheckOrder | D377: Inputs | E377: zipcode | F377: Zip code of the delivery address
B378: Product | C378: createCheckOrder | D378: Outputs | E378: checkOrderID
B379: Product | C379: createCheckOrder | D379: Outputs | E379: Check order ID
B380: Product | C380: registerDevice | D380: Inputs | E380: deviceId | F380: Device ID
B381: Product | C381: registerDevice | D381: Outputs | E381: deviceId | F381: Device ID
B382: Product | C382: deviceRegistrationStatus | D382: Inputs | E382: deviceId | F382: Device ID
B383: Product | C383: deviceRegistrationStatus | D383: Outputs | E383: deviceId | F383: Device ID
B384: Product | C384: deRegisterDevice | D384: Inputs | E384: deviceId | F384: Device ID
B385: Product | C385: deRegisterDevice | D385: Outputs | E385: - | F385: -
B386: Product | C386: createUser | D386: Inputs | E386: accountNumber | F386: Account number that is entered by the user on the screen
B387: Product | C387: createUser | D387: Inputs | E387: accountType | F387: Type of account selected by the user. For example, Savings, Checking, Credit Card etc.
B388: Product | C388: createUser | D388: Inputs | E388: dateOfBirth | F388: Date of the birth entered by the user
B389: Product | C389: createUser | D389: Inputs | E389: email | F389: Email address entered by the user
B390: Product | C390: createUser | D390: Inputs | E390: password | F390: Password entered by the user
B391: Product | C391: createUser | D391: Inputs | E391: phone | F391: Phone number entered by the user
... B495: Product | C495: getUserDetails | D495: Inputs | E495: password | F495: New password selected by the user
B496: Product | C496: getUserDetails | D496: Outputs | E496: User
B497: Product | C497: getUserDetails | D497: Outputs | E497: dateOfBirth | F497: Date of birth of the user
B498: Product | C498: getUserDetails | D498: Outputs | E498: ssn | F498: SSN of the user
...

Sheet Retail Banking
A1: Category # | B1: Module | C1: Sub-Module | D1: API | E1: Documentation Link * | F1: Description | G1: System of Record | H1: Readiness | I1: NOTES | J1: Standard/Add-on | K1: Mobile | L1: Tablet
A2: 1 | B2: User Management | C2: Login | D2: checkUserEnrolled | E2: https://konydocs.atlassian.net/wiki/spaces/ARBD425/pages/1080820602/checkUserEnrolled+Java+Integration+Service | F2: The API checks whether the user is enrolled or not. | G2: DBX | H2: 0 | J2: Standard
A3: 1 | B3: User Management | C3: Login | D3: createDBXCustomer | E3: https://konydocs.atlassian.net/wiki/spaces/ARBD424/pages/1031440205/createDbxCustomer+Java+Integration+Service | F3: The API enrolls a new user to mobile banking. | G3: DBX | H3: 4 | J3: Add-on
A4: 1 | B4: User Management | C4: Login | D4: createUserSecurityQuestions | E4: https://konydocs.atlassian.net/wiki/spaces/ARBD424/pages/1031439228/createUserSecurityQuestions+Java+Integration+Service | F4: Sets up security questions for the users while enrolling to mobile/online banking. | G4: N/A | H4: 0 | J4: Standard
A5: 1 | B5: User Management | C5: Login | D5: deletePin | E5: https://konydocs.atlassian.net/wiki/spaces/ARBD424/pages/1031439317/deletePin+Java+Integration+Service | F5: The API deletes the PIN defined in case of PIN-based login. | G5: N/A | J5: Standard
A6: 1 | B6: User Management | C6: Login | D6: deRegisterDevice | E6: https://konydocs.atlassian.net/wiki/spaces/ARBD425/pages/1080820137/deRegisterDevice+Java+Integration+Service | F6: The API de-registers a device for a user. | G6: DBX | H6: 3 | J6: Standard
A7: 1 | B7: User Management | C7: Login | D7: deviceRegistrationStatus | E7: https://konydocs.atlassian.net/wiki/spaces/ARBD425/pages/1080820190/deviceRegistrationStatus+Java+Integration+Service | F7: The API identifies the registration status of the device for a user. | G7: DBX | H7: 0 | J7: Standard
A8: 1 | B8: User Management | C8: Login | D8: fetchUserName | E8: https://konydocs.atlassian.net/wiki/spaces/ARBD425/pages/1080821454/fetchUserName+Java+Integration+Service | F8: The API fetches the username. | G8: DBX | H8: 0 | J8: Standard
A9: 1 | B9: User Management | C9: Login | D9: getApplicationProp | E9: https://konydocs.atlassian.net/wiki/spaces/ARBD425/pages/1080821095/getApplicationProp+Java+Integration+Service | F9: The API retrieves the default application parameters, such as currency code, banner URL and more.(System Config params C360) | G9: DBX | H9: 3 | J9: Standard
A10: 1 | B10: User Management | C10: Login | D10: getCustomerContact | E10: https://konydocs.atlassian.net/wiki/spaces/ARBD425/pages/1080820546/getCustomerContact+Java+Integration+Service | F10: The API retrieves user email, and contact numbers. | G10: DBX | H10: 3 | J10: Standard
A11: 1 | B11: User Management | C11: Login | D11: getPasswordPolicies | E11: https://konydocs.atlassian.net/wiki/spaces/ARBD425/pages/1080820544/getPasswordPolicies+Java+Integration+Service | F11: The API gets the username and password policies. | G11: DBX | H11: 0 | J11: Standard
A12: 1 | B12: User Management | C12: Login | D12: getSecurityQuestions | E12: https://konydocs.atlassian.net/wiki/spaces/ARBD424/pages/1031440182/getSecurityQuestions+Java+Integration+Service | F12: The API retrieves the list of security questions after the user logs in. | G12: N/A | H12: 0 | J12: Standard
A13: 1 | B13: User Management | C13: Login | D13: getUserSecurityQuestions | E13: https://konydocs.atlassian.net/wiki/spaces/ARBD425/pages/1080821089/getUserSecurityQuestions+Java+Integration+Service | F13: Retrieves the list of security questions before the user logs in. | G13: N/A | H13: 0 | J13: Standard
A14: 1 | B14: User Management | C14: Login | D14: logout | E14: https://konydocs.atlassian.net/wiki/spaces/ARBD425/pages/1080821536/logout+Java+Integration+Service | F14: The API is called to logout from the application. | G14: DBX | H14: 0 | J14: Standard
A15: 1 | B15: User Management | C15: Login | D15: registerDevice | E15: https://konydocs.atlassian.net/wiki/spaces/ARBD425/pages/1080820130/registerDevice+Java+Integration+Service | F15: The API registers a device for a user. | G15: DBX | H15: 3 | J15: Standard
A16: 1 | B16: User Management | C16: Login | D16: resetUserPassword | E16: https://konydocs.atlassian.net/wiki/spaces/ARBD425/pages/1080820596/resetUserPassword+Java+Integration+Service | F16: The API resets the password of a user. | G16: DBX | H16: 0 | J16: Standard
A17: 1 | B17: User Management | C17: Login | D17: verifyCVV | E17: https://konydocs.atlassian.net/wiki/spaces/ARBD425/pages/1080820843/verifyCVV+Java+Integration+Service | F17: The API verifies the CVV. | G17: DBX | H17: 0 | J17: Standard
A18: 1 | B18: User Management | C18: Login | D18: verifyOTP | E18: https://konydocs.atlassian.net/wiki/spaces/ARBD425/pages/1080821494/verifyOTP+Java+Integration+Service | F18: The API verifies the OTP used during enrollment(with SSN, DOB, LastName and OTP) | H18: 0 | J18: Standard
A19: 1 | B19: User Management | C19: Login | D19: verifyPin | E19: https://konydocs.atlassian.net/wiki/spaces/ARBD424/pages/1031438375/verifyPin+Java+Integration+Service | F19: The API verifies the PIN provided by the user. | G19: N/A | H19: 0 | J19: Standard
A20: 1 | B20: User Management | C20: Login | D20: verifyUserSecurityQuestions | E20: https://konydocs.atlassian.net/wiki/spaces/ARBD425/pages/1080821093/verifyUserSecurityQuestions+Java+Integration+Service | F20: Validates the security questions answered by a user. | G20: N/A | H20: 0 | J20: Standard
A21: 1 | B21: User Management | C21: Login | D21: dbxUserLogin | E21: https://konydocs.atlassian.net/wiki/spaces/ARBD425/pages/1080821850/dbxUserLogin+Orchestration+Service | F21: The API logs in the user. | G21: DBX | H21: 0 | J21: Standard
A22: 1 | B22: User Management | C22: Login | D22: dbxVerifyOTP | E22: https://konydocs.atlassian.net/wiki/spaces/ARBD425/pages/1080821951/dbxVerifyOTP+Java+Integration+Service | F22: The API verifies the OTP used during login and Security checks inside the app | H22: 3 | J22: Standard
A23: 1 | B23: User Management | C23: Login | D23: resetDbxUserPassword | E23: https://konydocs.atlassian.net/wiki/spaces/ARBD425/pages/1080820799/resetDbxUserPassword+Java+Integration+Service | F23: The API resets the password. | G23: DBX | H23: 0 | J23: Standard
A24: 1 | B24: User Management | C24: Login | D24: sendDbxResetPasswordEmail | E24: https://konydocs.atlassian.net/wiki/spaces/ARBD425/pages/1080820562/updateDbxUserStatus+Java+Integration+Service | F24: Sends an email with a link to reset the password | G24: DBX | H24: 0 | J24: Standard
A25: 1 | B25: User Management | C25: Login | D25: updateDbxUserStatus | E25: https://konydocs.atlassian.net/wiki/spaces/ARBD425/pages/1080820562/updateDbxUserStatus+Java+Integration+Service | F25: Toggles the status of a user between 'Active' and 'Suspended' | G25: DBX | J25: Standard
A26: 1 | B26: User Management | C26: Login | D26: getDbxUserStatus | E26: https://konydocs.atlassian.net/wiki/spaces/ARBD425/pages/1080821932/getDbxUserStatus+Java+Integration+Service | F26: Retrieves the status of the user in DBX | G26: DBX | H26: 0 | J26: Standard
A27: 1 | B27: User Management | C27: Login | D27: smsOTP | E27: https://konydocs.atlassian.net/wiki/spaces/ARBD425/pages/1080821953/smsOTP+Java+Integration+Service | F27: Generates an OTP and sends an SMS to the provided phone number. An optional e-Mail can also be provided if the user wants to receive the OTP through this channel. | H27: 2 | J27: Standard
A28: 1 | B28: User Management | C28: Login | D28: dbxRequestOTP | E28: https://konydocs.atlassian.net/wiki/spaces/ARBD425/pages/1080820835/dbxRequestOTP+Java+Integration+Service | F28: The API requests an OTP. | H28: 2
A29: 1 | B29: User Management | C29: Login | D29: getCustomerCommunication | E29: https://konydocs.atlassian.net/wiki/spaces/ARBD425/pages/1080821006/getCustomerCommunication+Java+Integration+Service | F29: Retrieves the communication details for the specified user | G29: DBX | H29: 3 | J29: Standard
A30: 1 | B30: User Management | C30: Login | D30: getUserNameRulesAndPolicy | E30: https://konydocs.atlassian.net/wiki/spaces/ARBD425/pages/1080821036/getUserNameRulesAndPolicy+Java+Integration+Service | F30: Retrieves the policies for user name in DBX | G30: DBX | H30: 0 | J30: Standard
A31: 1 | B31: User Management | C31: Login | D31: getPasswordRulesAndPolicy | E31: https://konydocs.atlassian.net/wiki/spaces/ARBD425/pages/1080820305/getPasswordRulesAndPolicy+Java+Integration+Service | F31: Retrieves the policies for user name in DBXRetrieves the policies for maintaining a password in DBX | G31: DBX | H31: 0 | J31: Standard
A32: 1 | B32: User Management | C32: Login | D32: getUserNameAndPasswordRulesAndPolicies | E32: https://konydocs.atlassian.net/wiki/spaces/ARBD425/pages/1080821007/getUserNameAndPasswordRulesAndPolicies+Java+Integration+Service | F32: Retrieves the policies for maintaining a username and password in DBX | G32: DBX | H32: 0 | J32: Standard
A33: 1 | B33: User Management | C33: Login | D33: getAPIPasswordLockoutSettings | E33: https://konydocs.atlassian.net/wiki/spaces/ARBD425/pages/1080821009/getAPIPasswordLockoutSettings+Java+Integration+Service | F33: Retrieves the password lockout settings maintained in the DBX identity management system | G33: DBX | H33: 0 | J33: Standard
A34: 1 | B34: User Management | C34: Login | D34: getPasswordLockoutSettings | E34: https://konydocs.atlassian.net/wiki/spaces/ARBD425/pages/1080821015/getPasswordLockoutSettings+Java+Integration+Service | F34: Retrieves the password lockout settings maintained in the DBX identity management system | G34: DBX | H34: 0 | J34: Standard
A35: 1 | B35: User Management | C35: Login | D35: updateDbxUserPassword | E35: https://konydocs.atlassian.net/wiki/spaces/ARBD425/pages/1080820207/updateDbxUserPassword+Java+Integration+Service | F35: Updates the password of a user The password provided needs to satisfy the password policies configured in the Customer360 application. | G35: DBX | H35: 0 | J35: Standard
A36: 1 | B36: User Management | C36: Login | D36: requestEnrollOTP | E36: https://konydocs.atlassian.net/wiki/spaces/ARBD425/pages/1080821713/requestEnrollOTP+Java+Integration+Service | F36: The API initiates the MFA process or alernately fetches additional parameters required to initiate the MFA process. This service is invoked in pre-login flows like password reset and user enrollment. | H36: 0 | J36: Standard
A37: 1 | B37: User Management | C37: Login | D37: verifyOTPPreLogin | E37: https://konydocs.atlassian.net/wiki/spaces/ARBD425/pages/1080820317/verifyOTPPreLogin+Java+Integration+Service | F37: The API validates and verifies the OTP passed in from the application for the given pre-login scenario like reset password or user enrollment | H37: 2 | J37: standard
A38: 1 | B38: User Management | C38: Login | D38: requestLoginMFAOTP | E38: https://konydocs.atlassian.net/wiki/spaces/ARBD425/pages/1080821722/requestLoginMFAOTP+Java+Integration+Service | F38: The API initiates the MFA OTP process for the Login flow. | G38: DBX | H38: 2 | J38: standard
A39: 1 | B39: User Management | C39: Login | D39: verifyLoginMFAOTP | E39: https://konydocs.atlassian.net/wiki/spaces/ARBD425/pages/1080821725/verifyLoginMFAOTP+Java+Integration+Service | F39: The API initiates the MFA OTP process for the Login flow. The API validates and verifies the OTP passed in from the application for the given Login scenario. | G39: DBX | H39: 2 | J39: standard
A40: 1 | B40: User Management | C40: Login | D40: verifyLoginMFASecurityQuestions | E40: https://konydocs.atlassian.net/wiki/spaces/ARBD425/pages/1080820386/verifyLoginMFASecurityQuestions+Java+Integration+Service | F40: The API validates and verifies the user's answers to the specified security questions for the given Login scenario. | G40: DBX | H40: 3 | J40: standard
...

Sheet Business Banking
K1: Channel
A2: Category # | B2: Module | C2: Sub-Module | D2: API | E2: Documentation Link | F2: Description | G2: System of Record | H2: Readiness | I2: Integration Notes | J2: Standard/Add-on | K2: Mobile | L2: Tablet | M2: Web | N2: NUO
A3: 21 | B3: User Management | C3: Business Users | D3: CreateOrganizationEmployee | E3: https://konydocs.atlassian.net/wiki/spaces/ARBD425/pages/1080821236/CreateOrganizationEmployee | F3: This API creates a new organization user. | G3: DBX | H3: 0
A4: 21 | B4: User Management | C4: Business Users | D4: getGroupEntitlements | E4: https://docs.kony.com/apps/integration/AdminConsoleServicesDocs/#/Groups_GetGroupEntitlements | F4: This API gets a list of transaction limit and daily limit for the organization. | G4: DBX | H4: 0
A5: 21 | B5: User Management | C5: Business Users | D5: getMembershipAccounts | E5: https://konydocs.atlassian.net/wiki/spaces/ARBD425/pages/1080821956/getMembershipAccounts+Java+Integration+Service | F5: Retrieves the list of accounts associated with an Org Id | G5: DBX | H5: 0
A6: 21 | B6: User Management | C6: Business Users | D6: getGroups | E6: https://docs.kony.com/apps/integration/AdminConsoleServicesDocs/#/Groups_GetGroupRecords | F6: This API gets a list of groups for the organization. | G6: DBX | H6: 0
A7: 21 | B7: User Management | C7: Business Users | D7: getDBXOrganizationDetails | E7: https://konydocs.atlassian.net/wiki/spaces/ARBD422/pages/1015743045/getDbxOrganizationDetails+Java+Integration+Service | F7: This API gets the organization details of the logged in user. | G7: DBX | H7: 0
A8: 21 | B8: User Management | C8: Business Users | D8: CreateOrganizationEmployee | E8: https://konydocs.atlassian.net/wiki/spaces/ARBD425/pages/1080821236/CreateOrganizationEmployee | F8: This API gets the list of all users under the organization. | G8: DBX | H8: 0
A9: 21 | B9: User Management | C9: Business Users | D9: getOrganizationAccounts | E9: https://konydocs.atlassian.net/wiki/spaces/ARBD425/pages/1080820789/getOrganizationAccounts+Java+Integration+Service | F9: This API gets a list of organization Accounts. | G9: DBX | H9: 0
A10: 21 | B10: User Management | C10: Business Users | D10: getOrgEmployeeDetails | E10: https://konydocs.atlassian.net/wiki/spaces/ARBD425/pages/1080820925/getOrgEmployeeDetails+Java+Integration+Service | F10: This API gets the user details. | G10: DBX | H10: 0
A11: 21 | B11: User Management | C11: Business Users | D11: getOrganizationName | E11: https://konydocs.atlassian.net/wiki/spaces/ARBD425/pages/1080821955/getOrganizationName | F11: This API returns the organization Name of the logged in user. | G11: DBX | H11: 0
A12: 21 | B12: User Management | C12: Business Users | D12: setOrgEmployeePassword | E12: https://konydocs.atlassian.net/wiki/spaces/ARBD425/pages/1080821865/SetOrgEmployeePassword | F12: This API helps the User set his / her password when he / she is created by the Business Owner. | G12: DBX | H12: 0
A13: 21 | B13: User Management | C13: Business Users | D13: OFACAndCIPChecks | E13: https://konydocs.atlassian.net/wiki/spaces/ARBD425/pages/1080820917/OFACAndCIPChecks+Java+Integration+Service | F13: This API checks OFAC and CIP for the SSN and DOB. | H13: 0
A14: 21 | B14: User Management | C14: Business Users | D14: ResendActivationLink | E14: https://konydocs.atlassian.net/wiki/spaces/ARBD425/pages/1080821274/ResendActivationLink+Java+Integration+Service | F14: This API resends the activation link. | G14: DBX | H14: 0
A15: 21 | B15: User Management | C15: Business Users | D15: updateDBXUserStatus | E15: https://konydocs.atlassian.net/wiki/spaces/ARBD425/pages/1080820562/updateDbxUserStatus+Java+Integration+Service | F15: This API activates/deactivates the user. | G15: DBX | H15: 0
A16: 21 | B16: User Management | C16: Business Users | D16: resendOrgEmployeeActivationLink | E16: https://konydocs.atlassian.net/wiki/spaces/ARBD425/pages/1080821224/ResendOrgEmployeeActivationLink | F16: This API will help the Business Owner / Admin to resend the activation email. | G16: DBX
A17: 21 | B17: User Management | C17: Business Users | D17: checkIfOrgMemberExists | E17: https://konydocs.atlassian.net/wiki/spaces/ARBD425/pages/1080822039/checkIfOrgMemberExists+Java+Integration+Service | F17: Verifies if a Membership Id exists in core banking system and whether it can be associated with a given user and organization. | G17: DBX | H17: 0
A18: 21 | B18: User Management | C18: Business Users | D18: unlinkOrgAccounts | E18: https://konydocs.atlassian.net/wiki/spaces/ARBD425/pages/1080822001/unLinkOrgAccounts+Java+Integration+Service | F18: Un-links the specified account(s) from an organization | G18: DBX | H18: 0
A19: 21 | B19: User Management | C19: Business Users | D19: validateTIN | E19: https://konydocs.atlassian.net/wiki/spaces/ARBD425/pages/1080822037/validateTin+Java+Integration+Service | F19: Verifies the existence of the Tax Id in DBX | G19: DBX | H19: 0
A20: 21 | B20: User Management | C20: Business Users | D20: verifyDbxUserName | E20: https://konydocs.atlassian.net/wiki/spaces/ARBD425/pages/1080820823/verifyDbxUserName+Java+Integration+Service | F20: This API checks the username availability. | G20: DBX | H20: 0
A21: 1 | B21: User Management | C21: Login | D21: checkUserEnrolled | E21: https://konydocs.atlassian.net/wiki/spaces/ARBD425/pages/1080820602/checkUserEnrolled+Java+Integration+Service | F21: The API checks whether the user is enrolled or not. | G21: DBX | H21: 0 | J21: Standard
A22: 1 | B22: User Management | C22: Login | D22: createDBXCustomer | E22: https://konydocs.atlassian.net/wiki/spaces/ARBD424/pages/1031440205/createDbxCustomer+Java+Integration+Service | F22: The API enrolls a new user to mobile banking. | G22: DBX | H22: 4 | J22: Add-on
A23: 1 | B23: User Management | C23: Login | D23: createUserSecurityQuestions | E23: https://konydocs.atlassian.net/wiki/spaces/ARBD424/pages/1031439228/createUserSecurityQuestions+Java+Integration+Service | F23: Sets up security questions for the users while enrolling to mobile/online banking. | G23: N/A | H23: 0 | J23: Standard
A24: 1 | B24: User Management | C24: Login | D24: deletePin | E24: https://konydocs.atlassian.net/wiki/spaces/ARBD424/pages/1031439317/deletePin+Java+Integration+Service | F24: The API deletes the PIN defined in case of PIN-based login. | G24: N/A | J24: Standard
A25: 1 | B25: User Management | C25: Login | D25: deRegisterDevice | E25: https://konydocs.atlassian.net/wiki/spaces/ARBD425/pages/1080820137/deRegisterDevice+Java+Integration+Service | F25: The API de-registers a device for a user. | G25: DBX | H25: 3 | J25: Standard
A26: 1 | B26: User Management | C26: Login | D26: deviceRegistrationStatus | E26: https://konydocs.atlassian.net/wiki/spaces/ARBD425/pages/1080820190/deviceRegistrationStatus+Java+Integration+Service | F26: The API identifies the registration status of the device for a user. | G26: DBX | H26: 0 | J26: Standard
A27: 1 | B27: User Management | C27: Login | D27: fetchUserName | E27: https://konydocs.atlassian.net/wiki/spaces/ARBD425/pages/1080821454/fetchUserName+Java+Integration+Service | F27: The API fetches the username. | G27: DBX | H27: 0 | J27: Standard
A28: 1 | B28: User Management | C28: Login | D28: getApplicationProp | E28: https://konydocs.atlassian.net/wiki/spaces/ARBD425/pages/1080821095/getApplicationProp+Java+Integration+Service | F28: The API retrieves the default application parameters, such as currency code, banner URL and more.(System Config params C360) | G28: DBX | H28: 3 | J28: Standard
A29: 1 | B29: User Management | C29: Login | D29: getCustomerContact | E29: https://konydocs.atlassian.net/wiki/spaces/ARBD425/pages/1080820546/getCustomerContact+Java+Integration+Service | F29: The API retrieves user email, and contact numbers. | G29: DBX | H29: 3 | J29: Standard
A30: 1 | B30: User Management | C30: Login | D30: getPasswordPolicies | E30: https://konydocs.atlassian.net/wiki/spaces/ARBD425/pages/1080820544/getPasswordPolicies+Java+Integration+Service | F30: The API gets the username and password policies. | G30: DBX | H30: 0 | J30: Standard
A31: 1 | B31: User Management | C31: Login | D31: getSecurityQuestions | E31: https://konydocs.atlassian.net/wiki/spaces/ARBD424/pages/1031440182/getSecurityQuestions+Java+Integration+Service | F31: The API retrieves the list of security questions after the user logs in. | G31: N/A | H31: 0 | J31: Standard
A32: 1 | B32: User Management | C32: Login | D32: getUserSecurityQuestions | E32: https://konydocs.atlassian.net/wiki/spaces/ARBD425/pages/1080821089/getUserSecurityQuestions+Java+Integration+Service | F32: Retrieves the list of security questions before the user logs in. | G32: N/A | H32: 0 | J32: Standard
A33: 1 | B33: User Management | C33: Login | D33: logout | E33: https://konydocs.atlassian.net/wiki/spaces/ARBD425/pages/1080821536/logout+Java+Integration+Service | F33: The API is called to logout from the application. | G33: DBX | H33: 0 | J33: Standard
A34: 1 | B34: User Management | C34: Login | D34: registerDevice | E34: https://konydocs.atlassian.net/wiki/spaces/ARBD425/pages/1080820130/registerDevice+Java+Integration+Service | F34: The API registers a device for a user. | G34: DBX | H34: 3 | J34: Standard
A35: 1 | B35: User Management | C35: Login | D35: resetUserPassword | E35: https://konydocs.atlassian.net/wiki/spaces/ARBD425/pages/1080820596/resetUserPassword+Java+Integration+Service | F35: The API resets the password of a user. | G35: DBX | H35: 0 | J35: Standard
A36: 1 | B36: User Management | C36: Login | D36: verifyCVV | E36: https://konydocs.atlassian.net/wiki/spaces/ARBD425/pages/1080820843/verifyCVV+Java+Integration+Service | F36: The API verifies the CVV. | G36: DBX | H36: 0 | J36: Standard
A37: 1 | B37: User Management | C37: Login | D37: verifyOTP | E37: https://konydocs.atlassian.net/wiki/spaces/ARBD425/pages/1080821494/verifyOTP+Java+Integration+Service | F37: The API verifies the OTP used during enrollment(with SSN, DOB, LastName and OTP) | H37: 0 | J37: Standard
A38: 1 | B38: User Management | C38: Login | D38: verifyPin | E38: https://konydocs.atlassian.net/wiki/spaces/ARBD424/pages/1031438375/verifyPin+Java+Integration+Service | F38: The API verifies the PIN provided by the user. | G38: N/A | H38: 0 | J38: Standard
A39: 1 | B39: User Management | C39: Login | D39: verifyUserSecurityQuestions | E39: https://konydocs.atlassian.net/wiki/spaces/ARBD425/pages/1080821093/verifyUserSecurityQuestions+Java+Integration+Service | F39: Validates the security questions answered by a user. | G39: N/A | H39: 0 | J39: Standard
A40: 1 | B40: User Management | C40: Login | D40: dbxUserLogin | E40: https://konydocs.atlassian.net/wiki/spaces/ARBD425/pages/1080821850/dbxUserLogin+Orchestration+Service | F40: The API logs in the user. | G40: DBX | H40: 0 | J40: Standard
...

Sheet Customer 360
J1: Channel
A2: Category # | B2: Module | C2: Sub-Module | D2: API | E2: Description | F2: System of Record | G2: Readiness | H2: Integration Notes | I2: Standard/Add-on | J2: Mobile | K2: Tablet | L2: Web | M2: NUO
A3: 31 | B3: User Management | C3: Login | D3: getAllEntitlements | E3: The API retrieves the list of all entitlements for a user | F3: DBX | G3: 0
A4: 31 | B4: User Management | C4: Login | D4: RegisterCustomerDevice | E4: The API registers a device for a given user in DBX. | F4: DBX | G4: 0
A5: 31 | B5: User Management | C5: Login | D5: trackRegisterCustomerDevice | E5: The API registers a device for a customer | F5: DBX | G5: 0
A6: 31 | B6: User Management | C6: Login | D6: UpdateCustomerDeviceInformation | E6: The API updates the information of a registered device for a given user. | F6: DBX | G6: 0
A7: 31 | B7: User Management | C7: Login | D7: DBX_verifyCustomerSecurityQuestions | E7: The API verifies the answers provided by the customer for their security questions. | F7: DBX | G7: 0
A8: 31 | B8: User Management | C8: Login | D8: createCustomerSecurityQuestions | E8: The API sets up security questions for a customer in DBX. | F8: DBX | G8: 0
A9: 31 | B9: User Management | C9: Login | D9: getRandomCustomerSecurityQuestions | E9: The API retrieves all the security questions of a given customer. | F9: DBX | G9: 0
A10: 31 | B10: User Management | C10: Login | D10: getSecurityQuestions | E10: The API retrieves the list of security questions maintained in DBX | F10: DBX | G10: 0
A11: 31 | B11: User Management | C11: Login | D11: verifyCustomerSecurityQuestions | E11: The API verifies the answers of security questions provided by a customer | F11: DBX | G11: 0
A12: 31 | B12: User Management | C12: Profile Management | D12: getAllAlerts | E12: The API retrieves the list of alerts and alert preferences of a user | F12: DBX | G12: 0
A13: 31 | B13: User Management | C13: Profile Management | D13: updateAlerts | E13: The API updates the details of an alert | F13: DBX | G13: 0
A14: 31 | B14: User Management | C14: Profile Management | D14: fetchCustomerDetailsForOlb | E14: The API retrieves basic customer profile information | F14: DBX | G14: 0
... A57: 35 | B57: Administration | C57: Outage Message | D57: updateOutageMessage | E57: The API updates the content of an outage message | F57: DBX | G57: 0
A59: 39 | B59: Custom | G59: 0

Sheet Vendor List
A2: Backend Requirement for | B2: CWB Current | C2: CWB Future
A3: Core Banking
A4: Remote Deposit Capture System (RDC)
A5: Reporting & Analytics
A6: Check Images
A7: Document Management Database
A8: Bill Pay System
A9: Card Control
A10: PFM / Data Enrichment
A11: Card Processor
A12: P2P / Real Time Payments System (RTP)
A13: Risk Profile System
A14: SMS Aggregator System
... A32: Product

Sheet Lists
B2: Development Category | D2: Product | F2: Custom | J2: Product-Custom
B3: Product | D3: - | F3: 1 - Low | J3: 1 - Low
B4: Custom | F4: 2 - Med | J4: 2 - Med
B5: Product+Custom | F5: 3 - High | J5: 3 - High
B10: Platform Support | D10: Backend | E10: Customer | I10: Product
D11: =IF(#REF!=0,"",#REF!) -> #REF! | E11: =IF(#REF!=0,"",#REF!) -> #REF! | I11: Custom
B12: Y | D12: =IF(#REF!=0,"",#REF!) -> #REF! | E12: =IF(#REF!=0,"",#REF!) -> #REF!
B13: N | D13: =IF(#REF!=0,"",#REF!) -> #REF! | E13: =IF(#REF!=0,"",#REF!) -> #REF!
B14: N/A | D14: =IF(#REF!=0,"",#REF!) -> #REF! | E14: =IF(#REF!=0,"",#REF!) -> #REF!
D15: =IF(#REF!=0,"",#REF!) -> #REF! | E15: =IF(#REF!=0,"",#REF!) -> #REF!
D16: =IF(#REF!=0,"",#REF!) -> #REF! | E16: =IF(#REF!=0,"",#REF!) -> #REF!
D17: =IF(#REF!=0,"",#REF!) -> #REF! | E17: =IF(#REF!=0,"",#REF!) -> #REF!
D18: =IF(#REF!=0,"",#REF!) -> #REF! | E18: =IF(#REF!=0,"",#REF!) -> #REF!
D19: =IF(#REF!=0,"",#REF!) -> #REF! | E19: =IF(#REF!=0,"",#REF!) -> #REF!
D20: =IF(#REF!=0,"",#REF!) -> #REF! | E20: =IF(#REF!=0,"",#REF!) -> #REF!
D21: =IF(#REF!=0,"",#REF!) -> #REF! | E21: =IF(#REF!=0,"",#REF!) -> #REF!
D22: =IF(#REF!=0,"",#REF!) -> #REF! | E22: =IF(#REF!=0,"",#REF!) -> #REF!
D23: =IF(#REF!=0,"",#REF!) -> #REF! | E23: =IF(#REF!=0,"",#REF!) -> #REF!
D24: =IF(#REF!=0,"",#REF!) -> #REF! | E24: =IF(#REF!=0,"",#REF!) -> #REF!
D25: =IF(#REF!=0,"",#REF!) -> #REF! | E25: =IF(#REF!=0,"",#REF!) -> #REF!
D26: =IF(#REF!=0,"",#REF!) -> #REF! | E26: =IF(#REF!=0,"",#REF!) -> #REF!
... D70: =IF(#REF!=0,"",#REF!) -> #REF! | E70: =IF(#REF!=0,"",#REF!) -> #REF!
D71: =IF(#REF!=0,"",#REF!) -> #REF!
